Workbook

Sheet ReadMe
A1: About the Document
B2: This is a summary of the Inbred HIPS field at Missouri Valley, IA
B4: The field posseses 752 plots (376 plots per rep)
B6: 2 row plots
B8: As of 8/24/22, the plots are unlabeled
A10: Sheet | B10: Description
A12: Index
B13: Columns A-R are a copy/paste from the following document:
C14: Missouri Valley Inbred HIPS 2022 - Index.xlsx
D15: This is a copy of the following file from Lisa Coffey
E16: LC-CF2221.10ft.xlsx
B18: Columns S and T are the range/row numbers for each of the plots based upon the document:
C19: Missouri Valley Inbred HIPS 2022 - Layout.pdf
D20: This is a copy of the following file from Lisa Coffey:
E21: LC-MOValley-CF2221-Inbreds.pdf
B23: Column U contains indeces used for the production of the "Layout" sheet
B25: The remaining columns are simply copies of columns M and N
A31: Layout
B32: Using the row/range numbers in the sheet, "Index", the maps here are the layouts of the
B33: Missouri Valley inbred HIPS field
B35: The maps represent the same plots but different ID terms are used in each of the maps

Sheet Index
A1: Location | B1: BookName | C1: CRO | D1: ST | E1: City | F1: Client1 | G1: Type | H1: Exp | I1: Entry | J1: Hybrid | K1: Pedigree | L1: User Rep | M1: Plot # | N1: UR_Plot | O1: Source Order | P1: Check | Q1: Check# | R1: Group# | S1: Range | T1: Row | U1: Index | V1: Plot # | W1: UR_Plot
A2: ISU.IA.MOValley | B2: CF2221.10ft | C2: ISU | D2: IA | E2: MOValley | F2: LC | G2: 2-row | H2: LC_2211 | I2: 18 | J2: L127 | K2: PI 601726 | L2: 1 | M2: 1 | N2: 101 | O2: 240 | R2: 1 | S2: 3 | T2: 53 | U2: =S2&"_"&T2 -> 3_53 | V2: 1 | W2: 101
A3: ISU.IA.MOValley | B3: CF2221.10ft | C3: ISU | D3: IA | E3: MOValley | F3: LC | G3: 2-row | H3: LC_2211 | I3: 29 | J3: Yu796_NS | K3: Ames 27196 | L3: 1 | M3: 2 | N3: 102 | O3: 303 | R3: 1 | S3: 3 | T3: 54 | U3: =S3&"_"&T3 -> 3_54 | V3: 2 | W3: 102
A4: ISU.IA.MOValley | B4: CF2221.10ft | C4: ISU | D4: IA | E4: MOValley | F4: LC | G4: 2-row | H4: LC_2211 | I4: 50 | J4: AK-57 | K4: AK-57 | L4: 1 | M4: 3 | N4: 103 | O4: 373 | R4: 1 | S4: 3 | T4: 55 | U4: =S4&"_"&T4 -> 3_55 | V4: 3 | W4: 103
A5: ISU.IA.MOValley | B5: CF2221.10ft | C5: ISU | D5: IA | E5: MOValley | F5: LC | G5: 2-row | H5: LC_2211 | I5: 45 | J5: AK-29 | K5: AK-29 | L5: 1 | M5: 4 | N5: 104 | O5: 366 | R5: 1 | S5: 3 | T5: 56 | U5: =S5&"_"&T5 -> 3_56 | V5: 4 | W5: 104
A6: ISU.IA.MOValley | B6: CF2221.10ft | C6: ISU | D6: IA | E6: MOValley | F6: LC | G6: 2-row | H6: LC_2211 | I6: 32 | J6: F7 | K6: PI 257507 | L6: 1 | M6: 5 | N6: 105 | O6: 311 | R6: 1 | S6: 3 | T6: 57 | U6: =S6&"_"&T6 -> 3_57 | V6: 5 | W6: 105
A7: ISU.IA.MOValley | B7: CF2221.10ft | C7: ISU | D7: IA | E7: MOValley | F7: LC | G7: 2-row | H7: LC_2211 | I7: 5 | J7: A188 | K7: Ames 22443 | L7: 1 | M7: 6 | N7: 106 | O7: 140 | R7: 1 | S7: 3 | T7: 58 | U7: =S7&"_"&T7 -> 3_58 | V7: 6 | W7: 106
A8: ISU.IA.MOValley | B8: CF2221.10ft | C8: ISU | D8: IA | E8: MOValley | F8: LC | G8: 2-row | H8: LC_2211 | I8: 2 | J8: F42 | K8: PI 601026 | L8: 1 | M8: 7 | N8: 107 | O8: 103 | R8: 1 | S8: 3 | T8: 59 | U8: =S8&"_"&T8 -> 3_59 | V8: 7 | W8: 107
A9: ISU.IA.MOValley | B9: CF2221.10ft | C9: ISU | D9: IA | E9: MOValley | F9: LC | G9: 2-row | H9: LC_2211 | I9: 7 | J9: NC290A | K9: Ames 27141 | L9: 1 | M9: 8 | N9: 108 | O9: 161 | R9: 1 | S9: 3 | T9: 60 | U9: =S9&"_"&T9 -> 3_60 | V9: 8 | W9: 108
A10: ISU.IA.MOValley | B10: CF2221.10ft | C10: ISU | D10: IA | E10: MOValley | F10: LC | G10: 2-row | H10: LC_2211 | I10: 25 | J10: EP1 | K10: Ames 27111 | L10: 1 | M10: 9 | N10: 109 | O10: 289 | R10: 1 | S10: 3 | T10: 61 | U10: =S10&"_"&T10 -> 3_61 | V10: 9 | W10: 109
A11: ISU.IA.MOValley | B11: CF2221.10ft | C11: ISU | D11: IA | E11: MOValley | F11: LC | G11: 2-row | H11: LC_2211 | I11: 1 | J11: 29MIBZ2 | K11: PI 548830 | L11: 1 | M11: 10 | N11: 110 | O11: 66 | R11: 1 | S11: 4 | T11: 61 | U11: =S11&"_"&T11 -> 4_61 | V11: 10 | W11: 110
A12: ISU.IA.MOValley | B12: CF2221.10ft | C12: ISU | D12: IA | E12: MOValley | F12: LC | G12: 2-row | H12: LC_2211 | I12: 40 | J12: B73 | K12: B73, check | L12: 1 | M12: 11 | N12: 111 | O12: 328 | P12: Y | R12: 1 | S12: 4 | T12: 60 | U12: =S12&"_"&T12 -> 4_60 | V12: 11 | W12: 111
A13: ISU.IA.MOValley | B13: CF2221.10ft | C13: ISU | D13: IA | E13: MOValley | F13: LC | G13: 2-row | H13: LC_2211 | I13: 11 | J13: RS 710 | K13: PI 539930 | L13: 1 | M13: 12 | N13: 112 | O13: 186 | R13: 1 | S13: 4 | T13: 59 | U13: =S13&"_"&T13 -> 4_59 | V13: 12 | W13: 112
A14: ISU.IA.MOValley | B14: CF2221.10ft | C14: ISU | D14: IA | E14: MOValley | F14: LC | G14: 2-row | H14: LC_2211 | I14: 6 | J14: CI187-2 | K14: Ames 26138 | L14: 1 | M14: 13 | N14: 113 | O14: 143 | R14: 1 | S14: 4 | T14: 58 | U14: =S14&"_"&T14 -> 4_58 | V14: 13 | W14: 113
A15: ISU.IA.MOValley | B15: CF2221.10ft | C15: ISU | D15: IA | E15: MOValley | F15: LC | G15: 2-row | H15: LC_2211 | I15: 24 | J15: CML220 | K15: Ames 27087 | L15: 1 | M15: 14 | N15: 114 | O15: 286 | R15: 1 | S15: 4 | T15: 57 | U15: =S15&"_"&T15 -> 4_57 | V15: 14 | W15: 114
A16: ISU.IA.MOValley | B16: CF2221.10ft | C16: ISU | D16: IA | E16: MOValley | F16: LC | G16: 2-row | H16: LC_2211 | I16: 28 | J16: NC346 | K16: Ames 27169 | L16: 1 | M16: 15 | N16: 115 | O16: 298 | R16: 1 | S16: 4 | T16: 56 | U16: =S16&"_"&T16 -> 4_56 | V16: 15 | W16: 115
A17: ISU.IA.MOValley | B17: CF2221.10ft | C17: ISU | D17: IA | E17: MOValley | F17: LC | G17: 2-row | H17: LC_2211 | I17: 48 | J17: AK-51 | K17: AK-51 | L17: 1 | M17: 16 | N17: 116 | O17: 370 | R17: 1 | S17: 4 | T17: 55 | U17: =S17&"_"&T17 -> 4_55 | V17: 16 | W17: 116
A18: ISU.IA.MOValley | B18: CF2221.10ft | C18: ISU | D18: IA | E18: MOValley | F18: LC | G18: 2-row | H18: LC_2211 | I18: 52 | J18: AK-61 | K18: AK-61 | L18: 1 | M18: 17 | N18: 117 | O18: 375 | R18: 1 | S18: 4 | T18: 54 | U18: =S18&"_"&T18 -> 4_54 | V18: 17 | W18: 117
A19: ISU.IA.MOValley | B19: CF2221.10ft | C19: ISU | D19: IA | E19: MOValley | F19: LC | G19: 2-row | H19: LC_2211 | I19: 9 | J19: W22 | K19: NSL 30053 | L19: 1 | M19: 18 | N19: 118 | O19: 179 | R19: 1 | S19: 4 | T19: 53 | U19: =S19&"_"&T19 -> 4_53 | V19: 18 | W19: 118
A20: ISU.IA.MOValley | B20: CF2221.10ft | C20: ISU | D20: IA | E20: MOValley | F20: LC | G20: 2-row | H20: LC_2211 | I20: 3 | J20: LH54 | K20: PI 601316 | L20: 1 | M20: 19 | N20: 119 | O20: 111 | R20: 1 | S20: 5 | T20: 53 | U20: =S20&"_"&T20 -> 5_53 | V20: 19 | W20: 119
A21: ISU.IA.MOValley | B21: CF2221.10ft | C21: ISU | D21: IA | E21: MOValley | F21: LC | G21: 2-row | H21: LC_2211 | I21: 42 | J21: B73 | K21: B73, check | L21: 1 | M21: 20 | N21: 120 | O21: 328 | P21: Y | R21: 1 | S21: 5 | T21: 54 | U21: =S21&"_"&T21 -> 5_54 | V21: 20 | W21: 120
A22: ISU.IA.MOValley | B22: CF2221.10ft | C22: ISU | D22: IA | E22: MOValley | F22: LC | G22: 2-row | H22: LC_2211 | I22: 49 | J22: AK-52 | K22: AK-52 | L22: 1 | M22: 21 | N22: 121 | O22: 371 | R22: 1 | S22: 5 | T22: 55 | U22: =S22&"_"&T22 -> 5_55 | V22: 21 | W22: 121
A23: ISU.IA.MOValley | B23: CF2221.10ft | C23: ISU | D23: IA | E23: MOValley | F23: LC | G23: 2-row | H23: LC_2211 | I23: 13 | J23: 78010 | K23: PI 601211 | L23: 1 | M23: 22 | N23: 122 | O23: 216 | R23: 1 | S23: 5 | T23: 56 | U23: =S23&"_"&T23 -> 5_56 | V23: 22 | W23: 122
A24: ISU.IA.MOValley | B24: CF2221.10ft | C24: ISU | D24: IA | E24: MOValley | F24: LC | G24: 2-row | H24: LC_2211 | I24: 31 | J24: IA2132 | K24: Ames 28364 | L24: 1 | M24: 23 | N24: 123 | O24: 306 | R24: 1 | S24: 5 | T24: 57 | U24: =S24&"_"&T24 -> 5_57 | V24: 23 | W24: 123
A25: ISU.IA.MOValley | B25: CF2221.10ft | C25: ISU | D25: IA | E25: MOValley | F25: LC | G25: 2-row | H25: LC_2211 | I25: 37 | J25: 779 | K25: PI 601376 | L25: 1 | M25: 24 | N25: 124 | O25: 324 | R25: 1 | S25: 5 | T25: 58 | U25: =S25&"_"&T25 -> 5_58 | V25: 24 | W25: 124
A26: ISU.IA.MOValley | B26: CF2221.10ft | C26: ISU | D26: IA | E26: MOValley | F26: LC | G26: 2-row | H26: LC_2211 | I26: 16 | J26: 778 | K26: PI 601375 | L26: 1 | M26: 25 | N26: 125 | O26: 222 | R26: 1 | S26: 5 | T26: 59 | U26: =S26&"_"&T26 -> 5_59 | V26: 25 | W26: 125
A27: ISU.IA.MOValley | B27: CF2221.10ft | C27: ISU | D27: IA | E27: MOValley | F27: LC | G27: 2-row | H27: LC_2211 | I27: 20 | J27: W117Ht | K27: Ames 8399 | L27: 1 | M27: 26 | N27: 126 | O27: 273 | R27: 1 | S27: 5 | T27: 60 | U27: =S27&"_"&T27 -> 5_60 | V27: 26 | W27: 126
A28: ISU.IA.MOValley | B28: CF2221.10ft | C28: ISU | D28: IA | E28: MOValley | F28: LC | G28: 2-row | H28: LC_2211 | I28: 30 | J28: P39 | K28: Ames 28186 | L28: 1 | M28: 27 | N28: 127 | O28: 305 | R28: 1 | S28: 5 | T28: 61 | U28: =S28&"_"&T28 -> 5_61 | V28: 27 | W28: 127
A29: ISU.IA.MOValley | B29: CF2221.10ft | C29: ISU | D29: IA | E29: MOValley | F29: LC | G29: 2-row | H29: LC_2211 | I29: 14 | J29: LH57 | K29: PI 601317 | L29: 1 | M29: 28 | N29: 128 | O29: 219 | R29: 1 | S29: 6 | T29: 61 | U29: =S29&"_"&T29 -> 6_61 | V29: 28 | W29: 128
A30: ISU.IA.MOValley | B30: CF2221.10ft | C30: ISU | D30: IA | E30: MOValley | F30: LC | G30: 2-row | H30: LC_2211 | I30: 36 | J30: W153R | K30: PI 587154 | L30: 1 | M30: 29 | N30: 129 | O30: 320 | R30: 1 | S30: 6 | T30: 60 | U30: =S30&"_"&T30 -> 6_60 | V30: 29 | W30: 129
A31: ISU.IA.MOValley | B31: CF2221.10ft | C31: ISU | D31: IA | E31: MOValley | F31: LC | G31: 2-row | H31: LC_2211 | I31: 51 | J31: AK-58 | K31: AK-58 | L31: 1 | M31: 30 | N31: 130 | O31: 374 | R31: 1 | S31: 6 | T31: 59 | U31: =S31&"_"&T31 -> 6_59 | V31: 30 | W31: 130
A32: ISU.IA.MOValley | B32: CF2221.10ft | C32: ISU | D32: IA | E32: MOValley | F32: LC | G32: 2-row | H32: LC_2211 | I32: 34 | J32: A654 | K32: PI 587141 | L32: 1 | M32: 31 | N32: 131 | O32: 318 | R32: 1 | S32: 6 | T32: 58 | U32: =S32&"_"&T32 -> 6_58 | V32: 31 | W32: 131
A33: ISU.IA.MOValley | B33: CF2221.10ft | C33: ISU | D33: IA | E33: MOValley | F33: LC | G33: 2-row | H33: LC_2211 | I33: 4 | J33: NC230 | K33: Ames 12731 | L33: 1 | M33: 32 | N33: 132 | O33: 132 | R33: 1 | S33: 6 | T33: 57 | U33: =S33&"_"&T33 -> 6_57 | V33: 32 | W33: 132
... A36: ISU.IA.MOValley | B36: CF2221.10ft | C36: ISU | D36: IA | E36: MOValley | F36: LC | G36: 2-row | H36: LC_2211 | I36: 22 | J36: CM37 | K36: Ames 20190 | L36: 1 | M36: 35 | N36: 135 | O36: 280 | R36: 1 | S36: 6 | T36: 54 | U36: =S36&"_"&T36 -> 6_54 | V36: 35 | W36: 135
A37: ISU.IA.MOValley | B37: CF2221.10ft | C37: ISU | D37: IA | E37: MOValley | F37: LC | G37: 2-row | H37: LC_2211 | I37: 41 | J37: B73 | K37: B73, check | L37: 1 | M37: 36 | N37: 136 | O37: 328 | P37: Y | R37: 1 | S37: 6 | T37: 53 | U37: =S37&"_"&T37 -> 6_53 | V37: 36 | W37: 136
A38: ISU.IA.MOValley | B38: CF2221.10ft | C38: ISU | D38: IA | E38: MOValley | F38: LC | G38: 2-row | H38: LC_2211 | I38: 38 | J38: S8324 | K38: PI 601611 | L38: 1 | M38: 37 | N38: 137 | O38: 325 | R38: 1 | S38: 7 | T38: 53 | U38: =S38&"_"&T38 -> 7_53 | V38: 37 | W38: 137
A39: ISU.IA.MOValley | B39: CF2221.10ft | C39: ISU | D39: IA | E39: MOValley | F39: LC | G39: 2-row | H39: LC_2211 | I39: 33 | J39: H99 | K39: PI 587129 | L39: 1 | M39: 38 | N39: 138 | O39: 317 | R39: 1 | S39: 7 | T39: 54 | U39: =S39&"_"&T39 -> 7_54 | V39: 38 | W39: 138
A40: ISU.IA.MOValley | B40: CF2221.10ft | C40: ISU | D40: IA | E40: MOValley | F40: LC | G40: 2-row | H40: LC_2211 | I40: 43 | J40: B73 | K40: B73, check | L40: 1 | M40: 39 | N40: 139 | O40: 328 | P40: Y | R40: 1 | S40: 7 | T40: 55 | U40: =S40&"_"&T40 -> 7_55 | V40: 39 | W40: 139
A41: ISU.IA.MOValley | B41: CF2221.10ft | C41: ISU | D41: IA | E41: MOValley | F41: LC | G41: 2-row | H41: LC_2211 | I41: 17 | J41: WIL500 | K41: PI 601689 | L41: 1 | M41: 40 | N41: 140 | O41: 238 | R41: 1 | S41: 7 | T41: 56 | U41: =S41&"_"&T41 -> 7_56 | V41: 40 | W41: 140
A42: ISU.IA.MOValley | B42: CF2221.10ft | C42: ISU | D42: IA | E42: MOValley | F42: LC | G42: 2-row | H42: LC_2211 | I42: 26 | J42: I29 | K42: Ames 27115 | L42: 1 | M42: 41 | N42: 141 | O42: 291 | R42: 1 | S42: 7 | T42: 57 | U42: =S42&"_"&T42 -> 7_57 | V42: 41 | W42: 141
...

Sheet Layout
A1: Layout: Rep and Plot # | O1: Layout: UR_Plot
C2: Row
C3: 53 | D3: 54 | E3: 55 | F3: 56 | G3: 57 | H3: 58 | I3: 59 | J3: 60 | K3: 61 | Q3: 53 | R3: 54 | S3: 55 | T3: 56 | U3: 57 | V3: 58 | W3: 59 | X3: 60 | Y3: 61
A4: Range | B4: 86 | C4: =VLOOKUP($B4&"_"&C$3,Index!$U:$V,2,FALSE) -> Fill | D4: =VLOOKUP($B4&"_"&D$3,Index!$U:$V,2,FALSE) -> Fill | E4: =VLOOKUP($B4&"_"&E$3,Index!$U:$V,2,FALSE) -> 376 | F4: =VLOOKUP($B4&"_"&F$3,Index!$U:$V,2,FALSE) -> 375 | G4: =VLOOKUP($B4&"_"&G$3,Index!$U:$V,2,FALSE) -> 374 | H4: =VLOOKUP($B4&"_"&H$3,Index!$U:$V,2,FALSE) -> 373 | I4: =VLOOKUP($B4&"_"&I$3,Index!$U:$V,2,FALSE) -> 372 | J4: =VLOOKUP($B4&"_"&J$3,Index!$U:$V,2,FALSE) -> 371 | K4: =VLOOKUP($B4&"_"&K$3,Index!$U:$V,2,FALSE) -> 370 | L4: Rep 2 | P4: 86 | Q4: =VLOOKUP($P4&"_"&Q$3,Index!$U:$W,3,FALSE) -> Fill | R4: =VLOOKUP($P4&"_"&R$3,Index!$U:$W,3,FALSE) -> Fill | S4: =VLOOKUP($P4&"_"&S$3,Index!$U:$W,3,FALSE) -> 576 | T4: =VLOOKUP($P4&"_"&T$3,Index!$U:$W,3,FALSE) -> 575 | U4: =VLOOKUP($P4&"_"&U$3,Index!$U:$W,3,FALSE) -> 574 | V4: =VLOOKUP($P4&"_"&V$3,Index!$U:$W,3,FALSE) -> 573 | W4: =VLOOKUP($P4&"_"&W$3,Index!$U:$W,3,FALSE) -> 572 | X4: =VLOOKUP($P4&"_"&X$3,Index!$U:$W,3,FALSE) -> 571 | Y4: =VLOOKUP($P4&"_"&Y$3,Index!$U:$W,3,FALSE) -> 570
B5: 85 | C5: =VLOOKUP($B5&"_"&C$3,Index!$U:$V,2,FALSE) -> 361 | D5: =VLOOKUP($B5&"_"&D$3,Index!$U:$V,2,FALSE) -> 362 | E5: =VLOOKUP($B5&"_"&E$3,Index!$U:$V,2,FALSE) -> 363 | F5: =VLOOKUP($B5&"_"&F$3,Index!$U:$V,2,FALSE) -> 364 | G5: =VLOOKUP($B5&"_"&G$3,Index!$U:$V,2,FALSE) -> 365 | H5: =VLOOKUP($B5&"_"&H$3,Index!$U:$V,2,FALSE) -> 366 | I5: =VLOOKUP($B5&"_"&I$3,Index!$U:$V,2,FALSE) -> 367 | J5: =VLOOKUP($B5&"_"&J$3,Index!$U:$V,2,FALSE) -> 368 | K5: =VLOOKUP($B5&"_"&K$3,Index!$U:$V,2,FALSE) -> 369 | P5: 85 | Q5: =VLOOKUP($P5&"_"&Q$3,Index!$U:$W,3,FALSE) -> 561 | R5: =VLOOKUP($P5&"_"&R$3,Index!$U:$W,3,FALSE) -> 562 | S5: =VLOOKUP($P5&"_"&S$3,Index!$U:$W,3,FALSE) -> 563 | T5: =VLOOKUP($P5&"_"&T$3,Index!$U:$W,3,FALSE) -> 564 | U5: =VLOOKUP($P5&"_"&U$3,Index!$U:$W,3,FALSE) -> 565 | V5: =VLOOKUP($P5&"_"&V$3,Index!$U:$W,3,FALSE) -> 566 | W5: =VLOOKUP($P5&"_"&W$3,Index!$U:$W,3,FALSE) -> 567 | X5: =VLOOKUP($P5&"_"&X$3,Index!$U:$W,3,FALSE) -> 568 | Y5: =VLOOKUP($P5&"_"&Y$3,Index!$U:$W,3,FALSE) -> 569
B6: 84 | C6: =VLOOKUP($B6&"_"&C$3,Index!$U:$V,2,FALSE) -> 360 | D6: =VLOOKUP($B6&"_"&D$3,Index!$U:$V,2,FALSE) -> 359 | E6: =VLOOKUP($B6&"_"&E$3,Index!$U:$V,2,FALSE) -> 358 | F6: =VLOOKUP($B6&"_"&F$3,Index!$U:$V,2,FALSE) -> 357 | G6: =VLOOKUP($B6&"_"&G$3,Index!$U:$V,2,FALSE) -> 356 | H6: =VLOOKUP($B6&"_"&H$3,Index!$U:$V,2,FALSE) -> 355 | I6: =VLOOKUP($B6&"_"&I$3,Index!$U:$V,2,FALSE) -> 354 | J6: =VLOOKUP($B6&"_"&J$3,Index!$U:$V,2,FALSE) -> 353 | K6: =VLOOKUP($B6&"_"&K$3,Index!$U:$V,2,FALSE) -> 352 | P6: 84 | Q6: =VLOOKUP($P6&"_"&Q$3,Index!$U:$W,3,FALSE) -> 560 | R6: =VLOOKUP($P6&"_"&R$3,Index!$U:$W,3,FALSE) -> 559 | S6: =VLOOKUP($P6&"_"&S$3,Index!$U:$W,3,FALSE) -> 558 | T6: =VLOOKUP($P6&"_"&T$3,Index!$U:$W,3,FALSE) -> 557 | U6: =VLOOKUP($P6&"_"&U$3,Index!$U:$W,3,FALSE) -> 556 | V6: =VLOOKUP($P6&"_"&V$3,Index!$U:$W,3,FALSE) -> 555 | W6: =VLOOKUP($P6&"_"&W$3,Index!$U:$W,3,FALSE) -> 554 | X6: =VLOOKUP($P6&"_"&X$3,Index!$U:$W,3,FALSE) -> 553 | Y6: =VLOOKUP($P6&"_"&Y$3,Index!$U:$W,3,FALSE) -> 552
B7: 83 | C7: =VLOOKUP($B7&"_"&C$3,Index!$U:$V,2,FALSE) -> 343 | D7: =VLOOKUP($B7&"_"&D$3,Index!$U:$V,2,FALSE) -> 344 | E7: =VLOOKUP($B7&"_"&E$3,Index!$U:$V,2,FALSE) -> 345 | F7: =VLOOKUP($B7&"_"&F$3,Index!$U:$V,2,FALSE) -> 346 | G7: =VLOOKUP($B7&"_"&G$3,Index!$U:$V,2,FALSE) -> 347 | H7: =VLOOKUP($B7&"_"&H$3,Index!$U:$V,2,FALSE) -> 348 | I7: =VLOOKUP($B7&"_"&I$3,Index!$U:$V,2,FALSE) -> 349 | J7: =VLOOKUP($B7&"_"&J$3,Index!$U:$V,2,FALSE) -> 350 | K7: =VLOOKUP($B7&"_"&K$3,Index!$U:$V,2,FALSE) -> 351 | P7: 83 | Q7: =VLOOKUP($P7&"_"&Q$3,Index!$U:$W,3,FALSE) -> 543 | R7: =VLOOKUP($P7&"_"&R$3,Index!$U:$W,3,FALSE) -> 544 | S7: =VLOOKUP($P7&"_"&S$3,Index!$U:$W,3,FALSE) -> 545 | T7: =VLOOKUP($P7&"_"&T$3,Index!$U:$W,3,FALSE) -> 546 | U7: =VLOOKUP($P7&"_"&U$3,Index!$U:$W,3,FALSE) -> 547 | V7: =VLOOKUP($P7&"_"&V$3,Index!$U:$W,3,FALSE) -> 548 | W7: =VLOOKUP($P7&"_"&W$3,Index!$U:$W,3,FALSE) -> 549 | X7: =VLOOKUP($P7&"_"&X$3,Index!$U:$W,3,FALSE) -> 550 | Y7: =VLOOKUP($P7&"_"&Y$3,Index!$U:$W,3,FALSE) -> 551
B8: 82 | C8: =VLOOKUP($B8&"_"&C$3,Index!$U:$V,2,FALSE) -> 342 | D8: =VLOOKUP($B8&"_"&D$3,Index!$U:$V,2,FALSE) -> 341 | E8: =VLOOKUP($B8&"_"&E$3,Index!$U:$V,2,FALSE) -> 340 | F8: =VLOOKUP($B8&"_"&F$3,Index!$U:$V,2,FALSE) -> 339 | G8: =VLOOKUP($B8&"_"&G$3,Index!$U:$V,2,FALSE) -> 338 | H8: =VLOOKUP($B8&"_"&H$3,Index!$U:$V,2,FALSE) -> 337 | I8: =VLOOKUP($B8&"_"&I$3,Index!$U:$V,2,FALSE) -> 336 | J8: =VLOOKUP($B8&"_"&J$3,Index!$U:$V,2,FALSE) -> 335 | K8: =VLOOKUP($B8&"_"&K$3,Index!$U:$V,2,FALSE) -> 334 | P8: 82 | Q8: =VLOOKUP($P8&"_"&Q$3,Index!$U:$W,3,FALSE) -> 542 | R8: =VLOOKUP($P8&"_"&R$3,Index!$U:$W,3,FALSE) -> 541 | S8: =VLOOKUP($P8&"_"&S$3,Index!$U:$W,3,FALSE) -> 540 | T8: =VLOOKUP($P8&"_"&T$3,Index!$U:$W,3,FALSE) -> 539 | U8: =VLOOKUP($P8&"_"&U$3,Index!$U:$W,3,FALSE) -> 538 | V8: =VLOOKUP($P8&"_"&V$3,Index!$U:$W,3,FALSE) -> 537 | W8: =VLOOKUP($P8&"_"&W$3,Index!$U:$W,3,FALSE) -> 536 | X8: =VLOOKUP($P8&"_"&X$3,Index!$U:$W,3,FALSE) -> 535 | Y8: =VLOOKUP($P8&"_"&Y$3,Index!$U:$W,3,FALSE) -> 534
B9: 81 | C9: =VLOOKUP($B9&"_"&C$3,Index!$U:$V,2,FALSE) -> 325 | D9: =VLOOKUP($B9&"_"&D$3,Index!$U:$V,2,FALSE) -> 326 | E9: =VLOOKUP($B9&"_"&E$3,Index!$U:$V,2,FALSE) -> 327 | F9: =VLOOKUP($B9&"_"&F$3,Index!$U:$V,2,FALSE) -> 328 | G9: =VLOOKUP($B9&"_"&G$3,Index!$U:$V,2,FALSE) -> 329 | H9: =VLOOKUP($B9&"_"&H$3,Index!$U:$V,2,FALSE) -> 330 | I9: =VLOOKUP($B9&"_"&I$3,Index!$U:$V,2,FALSE) -> 331 | J9: =VLOOKUP($B9&"_"&J$3,Index!$U:$V,2,FALSE) -> 332 | K9: =VLOOKUP($B9&"_"&K$3,Index!$U:$V,2,FALSE) -> 333 | P9: 81 | Q9: =VLOOKUP($P9&"_"&Q$3,Index!$U:$W,3,FALSE) -> 525 | R9: =VLOOKUP($P9&"_"&R$3,Index!$U:$W,3,FALSE) -> 526 | S9: =VLOOKUP($P9&"_"&S$3,Index!$U:$W,3,FALSE) -> 527 | T9: =VLOOKUP($P9&"_"&T$3,Index!$U:$W,3,FALSE) -> 528 | U9: =VLOOKUP($P9&"_"&U$3,Index!$U:$W,3,FALSE) -> 529 | V9: =VLOOKUP($P9&"_"&V$3,Index!$U:$W,3,FALSE) -> 530 | W9: =VLOOKUP($P9&"_"&W$3,Index!$U:$W,3,FALSE) -> 531 | X9: =VLOOKUP($P9&"_"&X$3,Index!$U:$W,3,FALSE) -> 532 | Y9: =VLOOKUP($P9&"_"&Y$3,Index!$U:$W,3,FALSE) -> 533
B10: 80 | C10: =VLOOKUP($B10&"_"&C$3,Index!$U:$V,2,FALSE) -> 324 | D10: =VLOOKUP($B10&"_"&D$3,Index!$U:$V,2,FALSE) -> 323 | E10: =VLOOKUP($B10&"_"&E$3,Index!$U:$V,2,FALSE) -> 322 | F10: =VLOOKUP($B10&"_"&F$3,Index!$U:$V,2,FALSE) -> 321 | G10: =VLOOKUP($B10&"_"&G$3,Index!$U:$V,2,FALSE) -> 320 | H10: =VLOOKUP($B10&"_"&H$3,Index!$U:$V,2,FALSE) -> 319 | I10: =VLOOKUP($B10&"_"&I$3,Index!$U:$V,2,FALSE) -> 318 | J10: =VLOOKUP($B10&"_"&J$3,Index!$U:$V,2,FALSE) -> 317 | K10: =VLOOKUP($B10&"_"&K$3,Index!$U:$V,2,FALSE) -> 316 | P10: 80 | Q10: =VLOOKUP($P10&"_"&Q$3,Index!$U:$W,3,FALSE) -> 524 | R10: =VLOOKUP($P10&"_"&R$3,Index!$U:$W,3,FALSE) -> 523 | S10: =VLOOKUP($P10&"_"&S$3,Index!$U:$W,3,FALSE) -> 522 | T10: =VLOOKUP($P10&"_"&T$3,Index!$U:$W,3,FALSE) -> 521 | U10: =VLOOKUP($P10&"_"&U$3,Index!$U:$W,3,FALSE) -> 520 | V10: =VLOOKUP($P10&"_"&V$3,Index!$U:$W,3,FALSE) -> 519 | W10: =VLOOKUP($P10&"_"&W$3,Index!$U:$W,3,FALSE) -> 518 | X10: =VLOOKUP($P10&"_"&X$3,Index!$U:$W,3,FALSE) -> 517 | Y10: =VLOOKUP($P10&"_"&Y$3,Index!$U:$W,3,FALSE) -> 516
B11: 79 | C11: =VLOOKUP($B11&"_"&C$3,Index!$U:$V,2,FALSE) -> 307 | D11: =VLOOKUP($B11&"_"&D$3,Index!$U:$V,2,FALSE) -> 308 | E11: =VLOOKUP($B11&"_"&E$3,Index!$U:$V,2,FALSE) -> 309 | F11: =VLOOKUP($B11&"_"&F$3,Index!$U:$V,2,FALSE) -> 310 | G11: =VLOOKUP($B11&"_"&G$3,Index!$U:$V,2,FALSE) -> 311 | H11: =VLOOKUP($B11&"_"&H$3,Index!$U:$V,2,FALSE) -> 312 | I11: =VLOOKUP($B11&"_"&I$3,Index!$U:$V,2,FALSE) -> 313 | J11: =VLOOKUP($B11&"_"&J$3,Index!$U:$V,2,FALSE) -> 314 | K11: =VLOOKUP($B11&"_"&K$3,Index!$U:$V,2,FALSE) -> 315 | P11: 79 | Q11: =VLOOKUP($P11&"_"&Q$3,Index!$U:$W,3,FALSE) -> 507 | R11: =VLOOKUP($P11&"_"&R$3,Index!$U:$W,3,FALSE) -> 508 | S11: =VLOOKUP($P11&"_"&S$3,Index!$U:$W,3,FALSE) -> 509 | T11: =VLOOKUP($P11&"_"&T$3,Index!$U:$W,3,FALSE) -> 510 | U11: =VLOOKUP($P11&"_"&U$3,Index!$U:$W,3,FALSE) -> 511 | V11: =VLOOKUP($P11&"_"&V$3,Index!$U:$W,3,FALSE) -> 512 | W11: =VLOOKUP($P11&"_"&W$3,Index!$U:$W,3,FALSE) -> 513 | X11: =VLOOKUP($P11&"_"&X$3,Index!$U:$W,3,FALSE) -> 514 | Y11: =VLOOKUP($P11&"_"&Y$3,Index!$U:$W,3,FALSE) -> 515
B12: 78 | C12: =VLOOKUP($B12&"_"&C$3,Index!$U:$V,2,FALSE) -> 306 | D12: =VLOOKUP($B12&"_"&D$3,Index!$U:$V,2,FALSE) -> 305 | E12: =VLOOKUP($B12&"_"&E$3,Index!$U:$V,2,FALSE) -> 304 | F12: =VLOOKUP($B12&"_"&F$3,Index!$U:$V,2,FALSE) -> 303 | G12: =VLOOKUP($B12&"_"&G$3,Index!$U:$V,2,FALSE) -> 302 | H12: =VLOOKUP($B12&"_"&H$3,Index!$U:$V,2,FALSE) -> 301 | I12: =VLOOKUP($B12&"_"&I$3,Index!$U:$V,2,FALSE) -> 300 | J12: =VLOOKUP($B12&"_"&J$3,Index!$U:$V,2,FALSE) -> 299 | K12: =VLOOKUP($B12&"_"&K$3,Index!$U:$V,2,FALSE) -> 298 | P12: 78 | Q12: =VLOOKUP($P12&"_"&Q$3,Index!$U:$W,3,FALSE) -> 506 | R12: =VLOOKUP($P12&"_"&R$3,Index!$U:$W,3,FALSE) -> 505 | S12: =VLOOKUP($P12&"_"&S$3,Index!$U:$W,3,FALSE) -> 504 | T12: =VLOOKUP($P12&"_"&T$3,Index!$U:$W,3,FALSE) -> 503 | U12: =VLOOKUP($P12&"_"&U$3,Index!$U:$W,3,FALSE) -> 502 | V12: =VLOOKUP($P12&"_"&V$3,Index!$U:$W,3,FALSE) -> 501 | W12: =VLOOKUP($P12&"_"&W$3,Index!$U:$W,3,FALSE) -> 500 | X12: =VLOOKUP($P12&"_"&X$3,Index!$U:$W,3,FALSE) -> 499 | Y12: =VLOOKUP($P12&"_"&Y$3,Index!$U:$W,3,FALSE) -> 498
B13: 77 | C13: =VLOOKUP($B13&"_"&C$3,Index!$U:$V,2,FALSE) -> 289 | D13: =VLOOKUP($B13&"_"&D$3,Index!$U:$V,2,FALSE) -> 290 | E13: =VLOOKUP($B13&"_"&E$3,Index!$U:$V,2,FALSE) -> 291 | F13: =VLOOKUP($B13&"_"&F$3,Index!$U:$V,2,FALSE) -> 292 | G13: =VLOOKUP($B13&"_"&G$3,Index!$U:$V,2,FALSE) -> 293 | H13: =VLOOKUP($B13&"_"&H$3,Index!$U:$V,2,FALSE) -> 294 | I13: =VLOOKUP($B13&"_"&I$3,Index!$U:$V,2,FALSE) -> 295 | J13: =VLOOKUP($B13&"_"&J$3,Index!$U:$V,2,FALSE) -> 296 | K13: =VLOOKUP($B13&"_"&K$3,Index!$U:$V,2,FALSE) -> 297 | P13: 77 | Q13: =VLOOKUP($P13&"_"&Q$3,Index!$U:$W,3,FALSE) -> 489 | R13: =VLOOKUP($P13&"_"&R$3,Index!$U:$W,3,FALSE) -> 490 | S13: =VLOOKUP($P13&"_"&S$3,Index!$U:$W,3,FALSE) -> 491 | T13: =VLOOKUP($P13&"_"&T$3,Index!$U:$W,3,FALSE) -> 492 | U13: =VLOOKUP($P13&"_"&U$3,Index!$U:$W,3,FALSE) -> 493 | V13: =VLOOKUP($P13&"_"&V$3,Index!$U:$W,3,FALSE) -> 494 | W13: =VLOOKUP($P13&"_"&W$3,Index!$U:$W,3,FALSE) -> 495 | X13: =VLOOKUP($P13&"_"&X$3,Index!$U:$W,3,FALSE) -> 496 | Y13: =VLOOKUP($P13&"_"&Y$3,Index!$U:$W,3,FALSE) -> 497
B14: 76 | C14: =VLOOKUP($B14&"_"&C$3,Index!$U:$V,2,FALSE) -> 288 | D14: =VLOOKUP($B14&"_"&D$3,Index!$U:$V,2,FALSE) -> 287 | E14: =VLOOKUP($B14&"_"&E$3,Index!$U:$V,2,FALSE) -> 286 | F14: =VLOOKUP($B14&"_"&F$3,Index!$U:$V,2,FALSE) -> 285 | G14: =VLOOKUP($B14&"_"&G$3,Index!$U:$V,2,FALSE) -> 284 | H14: =VLOOKUP($B14&"_"&H$3,Index!$U:$V,2,FALSE) -> 283 | I14: =VLOOKUP($B14&"_"&I$3,Index!$U:$V,2,FALSE) -> 282 | J14: =VLOOKUP($B14&"_"&J$3,Index!$U:$V,2,FALSE) -> 281 | K14: =VLOOKUP($B14&"_"&K$3,Index!$U:$V,2,FALSE) -> 280 | P14: 76 | Q14: =VLOOKUP($P14&"_"&Q$3,Index!$U:$W,3,FALSE) -> 488 | R14: =VLOOKUP($P14&"_"&R$3,Index!$U:$W,3,FALSE) -> 487 | S14: =VLOOKUP($P14&"_"&S$3,Index!$U:$W,3,FALSE) -> 486 | T14: =VLOOKUP($P14&"_"&T$3,Index!$U:$W,3,FALSE) -> 485 | U14: =VLOOKUP($P14&"_"&U$3,Index!$U:$W,3,FALSE) -> 484 | V14: =VLOOKUP($P14&"_"&V$3,Index!$U:$W,3,FALSE) -> 483 | W14: =VLOOKUP($P14&"_"&W$3,Index!$U:$W,3,FALSE) -> 482 | X14: =VLOOKUP($P14&"_"&X$3,Index!$U:$W,3,FALSE) -> 481 | Y14: =VLOOKUP($P14&"_"&Y$3,Index!$U:$W,3,FALSE) -> 480
B15: 75 | C15: =VLOOKUP($B15&"_"&C$3,Index!$U:$V,2,FALSE) -> 271 | D15: =VLOOKUP($B15&"_"&D$3,Index!$U:$V,2,FALSE) -> 272 | E15: =VLOOKUP($B15&"_"&E$3,Index!$U:$V,2,FALSE) -> 273 | F15: =VLOOKUP($B15&"_"&F$3,Index!$U:$V,2,FALSE) -> 274 | G15: =VLOOKUP($B15&"_"&G$3,Index!$U:$V,2,FALSE) -> 275 | H15: =VLOOKUP($B15&"_"&H$3,Index!$U:$V,2,FALSE) -> 276 | I15: =VLOOKUP($B15&"_"&I$3,Index!$U:$V,2,FALSE) -> 277 | J15: =VLOOKUP($B15&"_"&J$3,Index!$U:$V,2,FALSE) -> 278 | K15: =VLOOKUP($B15&"_"&K$3,Index!$U:$V,2,FALSE) -> 279 | P15: 75 | Q15: =VLOOKUP($P15&"_"&Q$3,Index!$U:$W,3,FALSE) -> 471 | R15: =VLOOKUP($P15&"_"&R$3,Index!$U:$W,3,FALSE) -> 472 | S15: =VLOOKUP($P15&"_"&S$3,Index!$U:$W,3,FALSE) -> 473 | T15: =VLOOKUP($P15&"_"&T$3,Index!$U:$W,3,FALSE) -> 474 | U15: =VLOOKUP($P15&"_"&U$3,Index!$U:$W,3,FALSE) -> 475 | V15: =VLOOKUP($P15&"_"&V$3,Index!$U:$W,3,FALSE) -> 476 | W15: =VLOOKUP($P15&"_"&W$3,Index!$U:$W,3,FALSE) -> 477 | X15: =VLOOKUP($P15&"_"&X$3,Index!$U:$W,3,FALSE) -> 478 | Y15: =VLOOKUP($P15&"_"&Y$3,Index!$U:$W,3,FALSE) -> 479
B16: 74 | C16: =VLOOKUP($B16&"_"&C$3,Index!$U:$V,2,FALSE) -> 270 | D16: =VLOOKUP($B16&"_"&D$3,Index!$U:$V,2,FALSE) -> 269 | E16: =VLOOKUP($B16&"_"&E$3,Index!$U:$V,2,FALSE) -> 268 | F16: =VLOOKUP($B16&"_"&F$3,Index!$U:$V,2,FALSE) -> 267 | G16: =VLOOKUP($B16&"_"&G$3,Index!$U:$V,2,FALSE) -> 266 | H16: =VLOOKUP($B16&"_"&H$3,Index!$U:$V,2,FALSE) -> 265 | I16: =VLOOKUP($B16&"_"&I$3,Index!$U:$V,2,FALSE) -> 264 | J16: =VLOOKUP($B16&"_"&J$3,Index!$U:$V,2,FALSE) -> 263 | K16: =VLOOKUP($B16&"_"&K$3,Index!$U:$V,2,FALSE) -> 262 | P16: 74 | Q16: =VLOOKUP($P16&"_"&Q$3,Index!$U:$W,3,FALSE) -> 470 | R16: =VLOOKUP($P16&"_"&R$3,Index!$U:$W,3,FALSE) -> 469 | S16: =VLOOKUP($P16&"_"&S$3,Index!$U:$W,3,FALSE) -> 468 | T16: =VLOOKUP($P16&"_"&T$3,Index!$U:$W,3,FALSE) -> 467 | U16: =VLOOKUP($P16&"_"&U$3,Index!$U:$W,3,FALSE) -> 466 | V16: =VLOOKUP($P16&"_"&V$3,Index!$U:$W,3,FALSE) -> 465 | W16: =VLOOKUP($P16&"_"&W$3,Index!$U:$W,3,FALSE) -> 464 | X16: =VLOOKUP($P16&"_"&X$3,Index!$U:$W,3,FALSE) -> 463 | Y16: =VLOOKUP($P16&"_"&Y$3,Index!$U:$W,3,FALSE) -> 462
... B45: 45 | C45: =VLOOKUP($B45&"_"&C$3,Index!$U:$V,2,FALSE) -> 1 | D45: =VLOOKUP($B45&"_"&D$3,Index!$U:$V,2,FALSE) -> 2 | E45: =VLOOKUP($B45&"_"&E$3,Index!$U:$V,2,FALSE) -> 3 | F45: =VLOOKUP($B45&"_"&F$3,Index!$U:$V,2,FALSE) -> 4 | G45: =VLOOKUP($B45&"_"&G$3,Index!$U:$V,2,FALSE) -> 5 | H45: =VLOOKUP($B45&"_"&H$3,Index!$U:$V,2,FALSE) -> 6 | I45: =VLOOKUP($B45&"_"&I$3,Index!$U:$V,2,FALSE) -> 7 | J45: =VLOOKUP($B45&"_"&J$3,Index!$U:$V,2,FALSE) -> 8 | K45: =VLOOKUP($B45&"_"&K$3,Index!$U:$V,2,FALSE) -> 9 | P45: 45 | Q45: =VLOOKUP($P45&"_"&Q$3,Index!$U:$W,3,FALSE) -> 201 | R45: =VLOOKUP($P45&"_"&R$3,Index!$U:$W,3,FALSE) -> 202 | S45: =VLOOKUP($P45&"_"&S$3,Index!$U:$W,3,FALSE) -> 203 | T45: =VLOOKUP($P45&"_"&T$3,Index!$U:$W,3,FALSE) -> 204 | U45: =VLOOKUP($P45&"_"&U$3,Index!$U:$W,3,FALSE) -> 205 | V45: =VLOOKUP($P45&"_"&V$3,Index!$U:$W,3,FALSE) -> 206 | W45: =VLOOKUP($P45&"_"&W$3,Index!$U:$W,3,FALSE) -> 207 | X45: =VLOOKUP($P45&"_"&X$3,Index!$U:$W,3,FALSE) -> 208 | Y45: =VLOOKUP($P45&"_"&Y$3,Index!$U:$W,3,FALSE) -> 209
B46: 44 | C46: =VLOOKUP($B46&"_"&C$3,Index!$U:$V,2,FALSE) -> Fill | D46: =VLOOKUP($B46&"_"&D$3,Index!$U:$V,2,FALSE) -> Fill | E46: =VLOOKUP($B46&"_"&E$3,Index!$U:$V,2,FALSE) -> 376 | F46: =VLOOKUP($B46&"_"&F$3,Index!$U:$V,2,FALSE) -> 375 | G46: =VLOOKUP($B46&"_"&G$3,Index!$U:$V,2,FALSE) -> 374 | H46: =VLOOKUP($B46&"_"&H$3,Index!$U:$V,2,FALSE) -> 373 | I46: =VLOOKUP($B46&"_"&I$3,Index!$U:$V,2,FALSE) -> 372 | J46: =VLOOKUP($B46&"_"&J$3,Index!$U:$V,2,FALSE) -> 371 | K46: =VLOOKUP($B46&"_"&K$3,Index!$U:$V,2,FALSE) -> 370 | L46: Rep 1 | P46: 44 | Q46: =VLOOKUP($P46&"_"&Q$3,Index!$U:$W,3,FALSE) -> Fill | R46: =VLOOKUP($P46&"_"&R$3,Index!$U:$W,3,FALSE) -> Fill | S46: =VLOOKUP($P46&"_"&S$3,Index!$U:$W,3,FALSE) -> 476 | T46: =VLOOKUP($P46&"_"&T$3,Index!$U:$W,3,FALSE) -> 475 | U46: =VLOOKUP($P46&"_"&U$3,Index!$U:$W,3,FALSE) -> 474 | V46: =VLOOKUP($P46&"_"&V$3,Index!$U:$W,3,FALSE) -> 473 | W46: =VLOOKUP($P46&"_"&W$3,Index!$U:$W,3,FALSE) -> 472 | X46: =VLOOKUP($P46&"_"&X$3,Index!$U:$W,3,FALSE) -> 471 | Y46: =VLOOKUP($P46&"_"&Y$3,Index!$U:$W,3,FALSE) -> 470
B47: 43 | C47: =VLOOKUP($B47&"_"&C$3,Index!$U:$V,2,FALSE) -> 361 | D47: =VLOOKUP($B47&"_"&D$3,Index!$U:$V,2,FALSE) -> 362 | E47: =VLOOKUP($B47&"_"&E$3,Index!$U:$V,2,FALSE) -> 363 | F47: =VLOOKUP($B47&"_"&F$3,Index!$U:$V,2,FALSE) -> 364 | G47: =VLOOKUP($B47&"_"&G$3,Index!$U:$V,2,FALSE) -> 365 | H47: =VLOOKUP($B47&"_"&H$3,Index!$U:$V,2,FALSE) -> 366 | I47: =VLOOKUP($B47&"_"&I$3,Index!$U:$V,2,FALSE) -> 367 | J47: =VLOOKUP($B47&"_"&J$3,Index!$U:$V,2,FALSE) -> 368 | K47: =VLOOKUP($B47&"_"&K$3,Index!$U:$V,2,FALSE) -> 369 | P47: 43 | Q47: =VLOOKUP($P47&"_"&Q$3,Index!$U:$W,3,FALSE) -> 461 | R47: =VLOOKUP($P47&"_"&R$3,Index!$U:$W,3,FALSE) -> 462 | S47: =VLOOKUP($P47&"_"&S$3,Index!$U:$W,3,FALSE) -> 463 | T47: =VLOOKUP($P47&"_"&T$3,Index!$U:$W,3,FALSE) -> 464 | U47: =VLOOKUP($P47&"_"&U$3,Index!$U:$W,3,FALSE) -> 465 | V47: =VLOOKUP($P47&"_"&V$3,Index!$U:$W,3,FALSE) -> 466 | W47: =VLOOKUP($P47&"_"&W$3,Index!$U:$W,3,FALSE) -> 467 | X47: =VLOOKUP($P47&"_"&X$3,Index!$U:$W,3,FALSE) -> 468 | Y47: =VLOOKUP($P47&"_"&Y$3,Index!$U:$W,3,FALSE) -> 469
B48: 42 | C48: =VLOOKUP($B48&"_"&C$3,Index!$U:$V,2,FALSE) -> 360 | D48: =VLOOKUP($B48&"_"&D$3,Index!$U:$V,2,FALSE) -> 359 | E48: =VLOOKUP($B48&"_"&E$3,Index!$U:$V,2,FALSE) -> 358 | F48: =VLOOKUP($B48&"_"&F$3,Index!$U:$V,2,FALSE) -> 357 | G48: =VLOOKUP($B48&"_"&G$3,Index!$U:$V,2,FALSE) -> 356 | H48: =VLOOKUP($B48&"_"&H$3,Index!$U:$V,2,FALSE) -> 355 | I48: =VLOOKUP($B48&"_"&I$3,Index!$U:$V,2,FALSE) -> 354 | J48: =VLOOKUP($B48&"_"&J$3,Index!$U:$V,2,FALSE) -> 353 | K48: =VLOOKUP($B48&"_"&K$3,Index!$U:$V,2,FALSE) -> 352 | P48: 42 | Q48: =VLOOKUP($P48&"_"&Q$3,Index!$U:$W,3,FALSE) -> 460 | R48: =VLOOKUP($P48&"_"&R$3,Index!$U:$W,3,FALSE) -> 459 | S48: =VLOOKUP($P48&"_"&S$3,Index!$U:$W,3,FALSE) -> 458 | T48: =VLOOKUP($P48&"_"&T$3,Index!$U:$W,3,FALSE) -> 457 | U48: =VLOOKUP($P48&"_"&U$3,Index!$U:$W,3,FALSE) -> 456 | V48: =VLOOKUP($P48&"_"&V$3,Index!$U:$W,3,FALSE) -> 455 | W48: =VLOOKUP($P48&"_"&W$3,Index!$U:$W,3,FALSE) -> 454 | X48: =VLOOKUP($P48&"_"&X$3,Index!$U:$W,3,FALSE) -> 453 | Y48: =VLOOKUP($P48&"_"&Y$3,Index!$U:$W,3,FALSE) -> 452
B49: 41 | C49: =VLOOKUP($B49&"_"&C$3,Index!$U:$V,2,FALSE) -> 343 | D49: =VLOOKUP($B49&"_"&D$3,Index!$U:$V,2,FALSE) -> 344 | E49: =VLOOKUP($B49&"_"&E$3,Index!$U:$V,2,FALSE) -> 345 | F49: =VLOOKUP($B49&"_"&F$3,Index!$U:$V,2,FALSE) -> 346 | G49: =VLOOKUP($B49&"_"&G$3,Index!$U:$V,2,FALSE) -> 347 | H49: =VLOOKUP($B49&"_"&H$3,Index!$U:$V,2,FALSE) -> 348 | I49: =VLOOKUP($B49&"_"&I$3,Index!$U:$V,2,FALSE) -> 349 | J49: =VLOOKUP($B49&"_"&J$3,Index!$U:$V,2,FALSE) -> 350 | K49: =VLOOKUP($B49&"_"&K$3,Index!$U:$V,2,FALSE) -> 351 | P49: 41 | Q49: =VLOOKUP($P49&"_"&Q$3,Index!$U:$W,3,FALSE) -> 443 | R49: =VLOOKUP($P49&"_"&R$3,Index!$U:$W,3,FALSE) -> 444 | S49: =VLOOKUP($P49&"_"&S$3,Index!$U:$W,3,FALSE) -> 445 | T49: =VLOOKUP($P49&"_"&T$3,Index!$U:$W,3,FALSE) -> 446 | U49: =VLOOKUP($P49&"_"&U$3,Index!$U:$W,3,FALSE) -> 447 | V49: =VLOOKUP($P49&"_"&V$3,Index!$U:$W,3,FALSE) -> 448 | W49: =VLOOKUP($P49&"_"&W$3,Index!$U:$W,3,FALSE) -> 449 | X49: =VLOOKUP($P49&"_"&X$3,Index!$U:$W,3,FALSE) -> 450 | Y49: =VLOOKUP($P49&"_"&Y$3,Index!$U:$W,3,FALSE) -> 451
B50: 40 | C50: =VLOOKUP($B50&"_"&C$3,Index!$U:$V,2,FALSE) -> 342 | D50: =VLOOKUP($B50&"_"&D$3,Index!$U:$V,2,FALSE) -> 341 | E50: =VLOOKUP($B50&"_"&E$3,Index!$U:$V,2,FALSE) -> 340 | F50: =VLOOKUP($B50&"_"&F$3,Index!$U:$V,2,FALSE) -> 339 | G50: =VLOOKUP($B50&"_"&G$3,Index!$U:$V,2,FALSE) -> 338 | H50: =VLOOKUP($B50&"_"&H$3,Index!$U:$V,2,FALSE) -> 337 | I50: =VLOOKUP($B50&"_"&I$3,Index!$U:$V,2,FALSE) -> 336 | J50: =VLOOKUP($B50&"_"&J$3,Index!$U:$V,2,FALSE) -> 335 | K50: =VLOOKUP($B50&"_"&K$3,Index!$U:$V,2,FALSE) -> 334 | P50: 40 | Q50: =VLOOKUP($P50&"_"&Q$3,Index!$U:$W,3,FALSE) -> 442 | R50: =VLOOKUP($P50&"_"&R$3,Index!$U:$W,3,FALSE) -> 441 | S50: =VLOOKUP($P50&"_"&S$3,Index!$U:$W,3,FALSE) -> 440 | T50: =VLOOKUP($P50&"_"&T$3,Index!$U:$W,3,FALSE) -> 439 | U50: =VLOOKUP($P50&"_"&U$3,Index!$U:$W,3,FALSE) -> 438 | V50: =VLOOKUP($P50&"_"&V$3,Index!$U:$W,3,FALSE) -> 437 | W50: =VLOOKUP($P50&"_"&W$3,Index!$U:$W,3,FALSE) -> 436 | X50: =VLOOKUP($P50&"_"&X$3,Index!$U:$W,3,FALSE) -> 435 | Y50: =VLOOKUP($P50&"_"&Y$3,Index!$U:$W,3,FALSE) -> 434
B51: 39 | C51: =VLOOKUP($B51&"_"&C$3,Index!$U:$V,2,FALSE) -> 325 | D51: =VLOOKUP($B51&"_"&D$3,Index!$U:$V,2,FALSE) -> 326 | E51: =VLOOKUP($B51&"_"&E$3,Index!$U:$V,2,FALSE) -> 327 | F51: =VLOOKUP($B51&"_"&F$3,Index!$U:$V,2,FALSE) -> 328 | G51: =VLOOKUP($B51&"_"&G$3,Index!$U:$V,2,FALSE) -> 329 | H51: =VLOOKUP($B51&"_"&H$3,Index!$U:$V,2,FALSE) -> 330 | I51: =VLOOKUP($B51&"_"&I$3,Index!$U:$V,2,FALSE) -> 331 | J51: =VLOOKUP($B51&"_"&J$3,Index!$U:$V,2,FALSE) -> 332 | K51: =VLOOKUP($B51&"_"&K$3,Index!$U:$V,2,FALSE) -> 333 | P51: 39 | Q51: =VLOOKUP($P51&"_"&Q$3,Index!$U:$W,3,FALSE) -> 425 | R51: =VLOOKUP($P51&"_"&R$3,Index!$U:$W,3,FALSE) -> 426 | S51: =VLOOKUP($P51&"_"&S$3,Index!$U:$W,3,FALSE) -> 427 | T51: =VLOOKUP($P51&"_"&T$3,Index!$U:$W,3,FALSE) -> 428 | U51: =VLOOKUP($P51&"_"&U$3,Index!$U:$W,3,FALSE) -> 429 | V51: =VLOOKUP($P51&"_"&V$3,Index!$U:$W,3,FALSE) -> 430 | W51: =VLOOKUP($P51&"_"&W$3,Index!$U:$W,3,FALSE) -> 431 | X51: =VLOOKUP($P51&"_"&X$3,Index!$U:$W,3,FALSE) -> 432 | Y51: =VLOOKUP($P51&"_"&Y$3,Index!$U:$W,3,FALSE) -> 433
B52: 38 | C52: =VLOOKUP($B52&"_"&C$3,Index!$U:$V,2,FALSE) -> 324 | D52: =VLOOKUP($B52&"_"&D$3,Index!$U:$V,2,FALSE) -> 323 | E52: =VLOOKUP($B52&"_"&E$3,Index!$U:$V,2,FALSE) -> 322 | F52: =VLOOKUP($B52&"_"&F$3,Index!$U:$V,2,FALSE) -> 321 | G52: =VLOOKUP($B52&"_"&G$3,Index!$U:$V,2,FALSE) -> 320 | H52: =VLOOKUP($B52&"_"&H$3,Index!$U:$V,2,FALSE) -> 319 | I52: =VLOOKUP($B52&"_"&I$3,Index!$U:$V,2,FALSE) -> 318 | J52: =VLOOKUP($B52&"_"&J$3,Index!$U:$V,2,FALSE) -> 317 | K52: =VLOOKUP($B52&"_"&K$3,Index!$U:$V,2,FALSE) -> 316 | P52: 38 | Q52: =VLOOKUP($P52&"_"&Q$3,Index!$U:$W,3,FALSE) -> 424 | R52: =VLOOKUP($P52&"_"&R$3,Index!$U:$W,3,FALSE) -> 423 | S52: =VLOOKUP($P52&"_"&S$3,Index!$U:$W,3,FALSE) -> 422 | T52: =VLOOKUP($P52&"_"&T$3,Index!$U:$W,3,FALSE) -> 421 | U52: =VLOOKUP($P52&"_"&U$3,Index!$U:$W,3,FALSE) -> 420 | V52: =VLOOKUP($P52&"_"&V$3,Index!$U:$W,3,FALSE) -> 419 | W52: =VLOOKUP($P52&"_"&W$3,Index!$U:$W,3,FALSE) -> 418 | X52: =VLOOKUP($P52&"_"&X$3,Index!$U:$W,3,FALSE) -> 417 | Y52: =VLOOKUP($P52&"_"&Y$3,Index!$U:$W,3,FALSE) -> 416
B53: 37 | C53: =VLOOKUP($B53&"_"&C$3,Index!$U:$V,2,FALSE) -> 307 | D53: =VLOOKUP($B53&"_"&D$3,Index!$U:$V,2,FALSE) -> 308 | E53: =VLOOKUP($B53&"_"&E$3,Index!$U:$V,2,FALSE) -> 309 | F53: =VLOOKUP($B53&"_"&F$3,Index!$U:$V,2,FALSE) -> 310 | G53: =VLOOKUP($B53&"_"&G$3,Index!$U:$V,2,FALSE) -> 311 | H53: =VLOOKUP($B53&"_"&H$3,Index!$U:$V,2,FALSE) -> 312 | I53: =VLOOKUP($B53&"_"&I$3,Index!$U:$V,2,FALSE) -> 313 | J53: =VLOOKUP($B53&"_"&J$3,Index!$U:$V,2,FALSE) -> 314 | K53: =VLOOKUP($B53&"_"&K$3,Index!$U:$V,2,FALSE) -> 315 | P53: 37 | Q53: =VLOOKUP($P53&"_"&Q$3,Index!$U:$W,3,FALSE) -> 407 | R53: =VLOOKUP($P53&"_"&R$3,Index!$U:$W,3,FALSE) -> 408 | S53: =VLOOKUP($P53&"_"&S$3,Index!$U:$W,3,FALSE) -> 409 | T53: =VLOOKUP($P53&"_"&T$3,Index!$U:$W,3,FALSE) -> 410 | U53: =VLOOKUP($P53&"_"&U$3,Index!$U:$W,3,FALSE) -> 411 | V53: =VLOOKUP($P53&"_"&V$3,Index!$U:$W,3,FALSE) -> 412 | W53: =VLOOKUP($P53&"_"&W$3,Index!$U:$W,3,FALSE) -> 413 | X53: =VLOOKUP($P53&"_"&X$3,Index!$U:$W,3,FALSE) -> 414 | Y53: =VLOOKUP($P53&"_"&Y$3,Index!$U:$W,3,FALSE) -> 415
B54: 36 | C54: =VLOOKUP($B54&"_"&C$3,Index!$U:$V,2,FALSE) -> 306 | D54: =VLOOKUP($B54&"_"&D$3,Index!$U:$V,2,FALSE) -> 305 | E54: =VLOOKUP($B54&"_"&E$3,Index!$U:$V,2,FALSE) -> 304 | F54: =VLOOKUP($B54&"_"&F$3,Index!$U:$V,2,FALSE) -> 303 | G54: =VLOOKUP($B54&"_"&G$3,Index!$U:$V,2,FALSE) -> 302 | H54: =VLOOKUP($B54&"_"&H$3,Index!$U:$V,2,FALSE) -> 301 | I54: =VLOOKUP($B54&"_"&I$3,Index!$U:$V,2,FALSE) -> 300 | J54: =VLOOKUP($B54&"_"&J$3,Index!$U:$V,2,FALSE) -> 299 | K54: =VLOOKUP($B54&"_"&K$3,Index!$U:$V,2,FALSE) -> 298 | P54: 36 | Q54: =VLOOKUP($P54&"_"&Q$3,Index!$U:$W,3,FALSE) -> 406 | R54: =VLOOKUP($P54&"_"&R$3,Index!$U:$W,3,FALSE) -> 405 | S54: =VLOOKUP($P54&"_"&S$3,Index!$U:$W,3,FALSE) -> 404 | T54: =VLOOKUP($P54&"_"&T$3,Index!$U:$W,3,FALSE) -> 403 | U54: =VLOOKUP($P54&"_"&U$3,Index!$U:$W,3,FALSE) -> 402 | V54: =VLOOKUP($P54&"_"&V$3,Index!$U:$W,3,FALSE) -> 401 | W54: =VLOOKUP($P54&"_"&W$3,Index!$U:$W,3,FALSE) -> 400 | X54: =VLOOKUP($P54&"_"&X$3,Index!$U:$W,3,FALSE) -> 399 | Y54: =VLOOKUP($P54&"_"&Y$3,Index!$U:$W,3,FALSE) -> 398
B55: 35 | C55: =VLOOKUP($B55&"_"&C$3,Index!$U:$V,2,FALSE) -> 289 | D55: =VLOOKUP($B55&"_"&D$3,Index!$U:$V,2,FALSE) -> 290 | E55: =VLOOKUP($B55&"_"&E$3,Index!$U:$V,2,FALSE) -> 291 | F55: =VLOOKUP($B55&"_"&F$3,Index!$U:$V,2,FALSE) -> 292 | G55: =VLOOKUP($B55&"_"&G$3,Index!$U:$V,2,FALSE) -> 293 | H55: =VLOOKUP($B55&"_"&H$3,Index!$U:$V,2,FALSE) -> 294 | I55: =VLOOKUP($B55&"_"&I$3,Index!$U:$V,2,FALSE) -> 295 | J55: =VLOOKUP($B55&"_"&J$3,Index!$U:$V,2,FALSE) -> 296 | K55: =VLOOKUP($B55&"_"&K$3,Index!$U:$V,2,FALSE) -> 297 | P55: 35 | Q55: =VLOOKUP($P55&"_"&Q$3,Index!$U:$W,3,FALSE) -> 389 | R55: =VLOOKUP($P55&"_"&R$3,Index!$U:$W,3,FALSE) -> 390 | S55: =VLOOKUP($P55&"_"&S$3,Index!$U:$W,3,FALSE) -> 391 | T55: =VLOOKUP($P55&"_"&T$3,Index!$U:$W,3,FALSE) -> 392 | U55: =VLOOKUP($P55&"_"&U$3,Index!$U:$W,3,FALSE) -> 393 | V55: =VLOOKUP($P55&"_"&V$3,Index!$U:$W,3,FALSE) -> 394 | W55: =VLOOKUP($P55&"_"&W$3,Index!$U:$W,3,FALSE) -> 395 | X55: =VLOOKUP($P55&"_"&X$3,Index!$U:$W,3,FALSE) -> 396 | Y55: =VLOOKUP($P55&"_"&Y$3,Index!$U:$W,3,FALSE) -> 397
B56: 34 | C56: =VLOOKUP($B56&"_"&C$3,Index!$U:$V,2,FALSE) -> 288 | D56: =VLOOKUP($B56&"_"&D$3,Index!$U:$V,2,FALSE) -> 287 | E56: =VLOOKUP($B56&"_"&E$3,Index!$U:$V,2,FALSE) -> 286 | F56: =VLOOKUP($B56&"_"&F$3,Index!$U:$V,2,FALSE) -> 285 | G56: =VLOOKUP($B56&"_"&G$3,Index!$U:$V,2,FALSE) -> 284 | H56: =VLOOKUP($B56&"_"&H$3,Index!$U:$V,2,FALSE) -> 283 | I56: =VLOOKUP($B56&"_"&I$3,Index!$U:$V,2,FALSE) -> 282 | J56: =VLOOKUP($B56&"_"&J$3,Index!$U:$V,2,FALSE) -> 281 | K56: =VLOOKUP($B56&"_"&K$3,Index!$U:$V,2,FALSE) -> 280 | P56: 34 | Q56: =VLOOKUP($P56&"_"&Q$3,Index!$U:$W,3,FALSE) -> 388 | R56: =VLOOKUP($P56&"_"&R$3,Index!$U:$W,3,FALSE) -> 387 | S56: =VLOOKUP($P56&"_"&S$3,Index!$U:$W,3,FALSE) -> 386 | T56: =VLOOKUP($P56&"_"&T$3,Index!$U:$W,3,FALSE) -> 385 | U56: =VLOOKUP($P56&"_"&U$3,Index!$U:$W,3,FALSE) -> 384 | V56: =VLOOKUP($P56&"_"&V$3,Index!$U:$W,3,FALSE) -> 383 | W56: =VLOOKUP($P56&"_"&W$3,Index!$U:$W,3,FALSE) -> 382 | X56: =VLOOKUP($P56&"_"&X$3,Index!$U:$W,3,FALSE) -> 381 | Y56: =VLOOKUP($P56&"_"&Y$3,Index!$U:$W,3,FALSE) -> 380
B57: 33 | C57: =VLOOKUP($B57&"_"&C$3,Index!$U:$V,2,FALSE) -> 271 | D57: =VLOOKUP($B57&"_"&D$3,Index!$U:$V,2,FALSE) -> 272 | E57: =VLOOKUP($B57&"_"&E$3,Index!$U:$V,2,FALSE) -> 273 | F57: =VLOOKUP($B57&"_"&F$3,Index!$U:$V,2,FALSE) -> 274 | G57: =VLOOKUP($B57&"_"&G$3,Index!$U:$V,2,FALSE) -> 275 | H57: =VLOOKUP($B57&"_"&H$3,Index!$U:$V,2,FALSE) -> 276 | I57: =VLOOKUP($B57&"_"&I$3,Index!$U:$V,2,FALSE) -> 277 | J57: =VLOOKUP($B57&"_"&J$3,Index!$U:$V,2,FALSE) -> 278 | K57: =VLOOKUP($B57&"_"&K$3,Index!$U:$V,2,FALSE) -> 279 | P57: 33 | Q57: =VLOOKUP($P57&"_"&Q$3,Index!$U:$W,3,FALSE) -> 371 | R57: =VLOOKUP($P57&"_"&R$3,Index!$U:$W,3,FALSE) -> 372 | S57: =VLOOKUP($P57&"_"&S$3,Index!$U:$W,3,FALSE) -> 373 | T57: =VLOOKUP($P57&"_"&T$3,Index!$U:$W,3,FALSE) -> 374 | U57: =VLOOKUP($P57&"_"&U$3,Index!$U:$W,3,FALSE) -> 375 | V57: =VLOOKUP($P57&"_"&V$3,Index!$U:$W,3,FALSE) -> 376 | W57: =VLOOKUP($P57&"_"&W$3,Index!$U:$W,3,FALSE) -> 377 | X57: =VLOOKUP($P57&"_"&X$3,Index!$U:$W,3,FALSE) -> 378 | Y57: =VLOOKUP($P57&"_"&Y$3,Index!$U:$W,3,FALSE) -> 379
B58: 32 | C58: =VLOOKUP($B58&"_"&C$3,Index!$U:$V,2,FALSE) -> 270 | D58: =VLOOKUP($B58&"_"&D$3,Index!$U:$V,2,FALSE) -> 269 | E58: =VLOOKUP($B58&"_"&E$3,Index!$U:$V,2,FALSE) -> 268 | F58: =VLOOKUP($B58&"_"&F$3,Index!$U:$V,2,FALSE) -> 267 | G58: =VLOOKUP($B58&"_"&G$3,Index!$U:$V,2,FALSE) -> 266 | H58: =VLOOKUP($B58&"_"&H$3,Index!$U:$V,2,FALSE) -> 265 | I58: =VLOOKUP($B58&"_"&I$3,Index!$U:$V,2,FALSE) -> 264 | J58: =VLOOKUP($B58&"_"&J$3,Index!$U:$V,2,FALSE) -> 263 | K58: =VLOOKUP($B58&"_"&K$3,Index!$U:$V,2,FALSE) -> 262 | P58: 32 | Q58: =VLOOKUP($P58&"_"&Q$3,Index!$U:$W,3,FALSE) -> 370 | R58: =VLOOKUP($P58&"_"&R$3,Index!$U:$W,3,FALSE) -> 369 | S58: =VLOOKUP($P58&"_"&S$3,Index!$U:$W,3,FALSE) -> 368 | T58: =VLOOKUP($P58&"_"&T$3,Index!$U:$W,3,FALSE) -> 367 | U58: =VLOOKUP($P58&"_"&U$3,Index!$U:$W,3,FALSE) -> 366 | V58: =VLOOKUP($P58&"_"&V$3,Index!$U:$W,3,FALSE) -> 365 | W58: =VLOOKUP($P58&"_"&W$3,Index!$U:$W,3,FALSE) -> 364 | X58: =VLOOKUP($P58&"_"&X$3,Index!$U:$W,3,FALSE) -> 363 | Y58: =VLOOKUP($P58&"_"&Y$3,Index!$U:$W,3,FALSE) -> 362
... B87: 3 | C87: =VLOOKUP($B87&"_"&C$3,Index!$U:$V,2,FALSE) -> 1 | D87: =VLOOKUP($B87&"_"&D$3,Index!$U:$V,2,FALSE) -> 2 | E87: =VLOOKUP($B87&"_"&E$3,Index!$U:$V,2,FALSE) -> 3 | F87: =VLOOKUP($B87&"_"&F$3,Index!$U:$V,2,FALSE) -> 4 | G87: =VLOOKUP($B87&"_"&G$3,Index!$U:$V,2,FALSE) -> 5 | H87: =VLOOKUP($B87&"_"&H$3,Index!$U:$V,2,FALSE) -> 6 | I87: =VLOOKUP($B87&"_"&I$3,Index!$U:$V,2,FALSE) -> 7 | J87: =VLOOKUP($B87&"_"&J$3,Index!$U:$V,2,FALSE) -> 8 | K87: =VLOOKUP($B87&"_"&K$3,Index!$U:$V,2,FALSE) -> 9 | P87: 3 | Q87: =VLOOKUP($P87&"_"&Q$3,Index!$U:$W,3,FALSE) -> 101 | R87: =VLOOKUP($P87&"_"&R$3,Index!$U:$W,3,FALSE) -> 102 | S87: =VLOOKUP($P87&"_"&S$3,Index!$U:$W,3,FALSE) -> 103 | T87: =VLOOKUP($P87&"_"&T$3,Index!$U:$W,3,FALSE) -> 104 | U87: =VLOOKUP($P87&"_"&U$3,Index!$U:$W,3,FALSE) -> 105 | V87: =VLOOKUP($P87&"_"&V$3,Index!$U:$W,3,FALSE) -> 106 | W87: =VLOOKUP($P87&"_"&W$3,Index!$U:$W,3,FALSE) -> 107 | X87: =VLOOKUP($P87&"_"&X$3,Index!$U:$W,3,FALSE) -> 108 | Y87: =VLOOKUP($P87&"_"&Y$3,Index!$U:$W,3,FALSE) -> 109
C88: 53 | D88: 54 | E88: 55 | F88: 56 | G88: 57 | H88: 58 | I88: 59 | J88: 60 | K88: 61 | Q88: 53 | R88: 54 | S88: 55 | T88: 56 | U88: 57 | V88: 58 | W88: 59 | X88: 60 | Y88: 61
