Workbook

Sheet ReadMe
A1: About this Document | K1: Metadata
B2: This is Turkus's summary of the 2023 Missouri Valley HIPS fields | L2: Fields were planted on land of Dean Mackintosh
B4: This is based on Information sent to him by Lisa Coffey | L4: Fields were cared for by the Iowa CROPS organization (company?)
L6: Harvest performed on 9/16/23)
A9: Original Index
B10: Copy/paste of the document:
C11: YTMC.LC.xlsx
A13: Original Maps
B14: Screenshots of the following documents:
C15: Map.MOValley.10ft.pdf
C16: Map.MOValley.20ft mark up.pdf
C17: MO Valley IA HIPS 2023.pdf

Sheet Original Index
A1: Index | B1: PedId | C1: ISU RecId | D1: Type | E1: Tier# | F1: Serp | G1: Rep | H1: Location | I1: Exp | J1: Ent# | K1: Entry | L1: Pass | M1: Range | N1: Plot | O1: Plot Row | Q1: Legend
A2: =IF(OR(I2="LC2125",I2="LC2125_ER"),"Hybrid HIPS",IF(I2="LC2120","Inbred HIPS","ERROR"))&"_"&O2&"_"&M2 -> Inbred HIPS_11_3 | B2: 1715465 | C2: 1723020 | D2: 2-row | E2: 1 | F2: 35 | G2: 1 | H2: ISU.IA.MOValley | I2: LC2120 | J2: 9 | K2: 3IIH6 | L2: 11 | M2: 3 | N2: 110 | O2: =IF(OR(I2="LC2125",I2="LC2125_ER"),(L2+3)/4,IF(I2="LC2120",L2,"ERROR")) -> 11 | R2: Exp | S2: Population it Refers To
A3: =IF(OR(I3="LC2125",I3="LC2125_ER"),"Hybrid HIPS",IF(I3="LC2120","Inbred HIPS","ERROR"))&"_"&O3&"_"&M3 -> Inbred HIPS_10_3 | B3: 1715610 | C3: 1723065 | D3: 2-row | E3: 1 | F3: 34 | G3: 1 | H3: ISU.IA.MOValley | I3: LC2120 | J3: 54 | K3: B64 | L3: 10 | M3: 3 | N3: 109 | O3: =IF(OR(I3="LC2125",I3="LC2125_ER"),(L3+3)/4,IF(I3="LC2120",L3,"ERROR")) -> 10 | R3: LC2120 | S3: Inbred HIPS
A4: =IF(OR(I4="LC2125",I4="LC2125_ER"),"Hybrid HIPS",IF(I4="LC2120","Inbred HIPS","ERROR"))&"_"&O4&"_"&M4 -> Inbred HIPS_9_3 | B4: 1715887 | C4: 1729242 | D4: 2-row | E4: 1 | F4: 33 | G4: 1 | H4: ISU.IA.MOValley | I4: LC2120 | J4: 231 | K4: Il677a | L4: 9 | M4: 3 | N4: 108 | O4: =IF(OR(I4="LC2125",I4="LC2125_ER"),(L4+3)/4,IF(I4="LC2120",L4,"ERROR")) -> 9 | R4: LC2125 | S4: Hybrid HIPS
A5: =IF(OR(I5="LC2125",I5="LC2125_ER"),"Hybrid HIPS",IF(I5="LC2120","Inbred HIPS","ERROR"))&"_"&O5&"_"&M5 -> Inbred HIPS_8_3 | B5: 1716045 | C5: 1729300 | D5: 2-row | E5: 1 | F5: 32 | G5: 1 | H5: ISU.IA.MOValley | I5: LC2120 | J5: 289 | K5: Ia5125 | L5: 8 | M5: 3 | N5: 107 | O5: =IF(OR(I5="LC2125",I5="LC2125_ER"),(L5+3)/4,IF(I5="LC2120",L5,"ERROR")) -> 8 | R5: LC2125_ER | S5: Hybrid HIPS (plots they couldn't squeeze into the same spot)
A6: =IF(OR(I6="LC2125",I6="LC2125_ER"),"Hybrid HIPS",IF(I6="LC2120","Inbred HIPS","ERROR"))&"_"&O6&"_"&M6 -> Inbred HIPS_7_3 | B6: 1716015 | C6: 1729270 | D6: 2-row | E6: 1 | F6: 31 | G6: 1 | H6: ISU.IA.MOValley | I6: LC2120 | J6: 259 | K6: CML38 | L6: 7 | M6: 3 | N6: 106 | O6: =IF(OR(I6="LC2125",I6="LC2125_ER"),(L6+3)/4,IF(I6="LC2120",L6,"ERROR")) -> 7
A7: =IF(OR(I7="LC2125",I7="LC2125_ER"),"Hybrid HIPS",IF(I7="LC2120","Inbred HIPS","ERROR"))&"_"&O7&"_"&M7 -> Inbred HIPS_6_3 | B7: 1716215 | C7: 1729367 | D7: 2-row | E7: 1 | F7: 30 | G7: 1 | H7: ISU.IA.MOValley | I7: LC2120 | J7: 356 | K7: B73 | L7: 6 | M7: 3 | N7: 105 | O7: =IF(OR(I7="LC2125",I7="LC2125_ER"),(L7+3)/4,IF(I7="LC2120",L7,"ERROR")) -> 6
A8: =IF(OR(I8="LC2125",I8="LC2125_ER"),"Hybrid HIPS",IF(I8="LC2120","Inbred HIPS","ERROR"))&"_"&O8&"_"&M8 -> Inbred HIPS_5_3 | B8: 1715621 | C8: 1723076 | D8: 2-row | E8: 1 | F8: 29 | G8: 1 | H8: ISU.IA.MOValley | I8: LC2120 | J8: 65 | K8: ML606 | L8: 5 | M8: 3 | N8: 104 | O8: =IF(OR(I8="LC2125",I8="LC2125_ER"),(L8+3)/4,IF(I8="LC2120",L8,"ERROR")) -> 5
A9: =IF(OR(I9="LC2125",I9="LC2125_ER"),"Hybrid HIPS",IF(I9="LC2120","Inbred HIPS","ERROR"))&"_"&O9&"_"&M9 -> Inbred HIPS_4_3 | B9: 1715813 | C9: 1729168 | D9: 2-row | E9: 1 | F9: 28 | G9: 1 | H9: ISU.IA.MOValley | I9: LC2120 | J9: 157 | K9: LH183 | L9: 4 | M9: 3 | N9: 103 | O9: =IF(OR(I9="LC2125",I9="LC2125_ER"),(L9+3)/4,IF(I9="LC2120",L9,"ERROR")) -> 4
A10: =IF(OR(I10="LC2125",I10="LC2125_ER"),"Hybrid HIPS",IF(I10="LC2120","Inbred HIPS","ERROR"))&"_"&O10&"_"&M10 -> Inbred HIPS_3_3 | B10: 1715678 | C10: 1729133 | D10: 2-row | E10: 1 | F10: 27 | G10: 1 | H10: ISU.IA.MOValley | I10: LC2120 | J10: 122 | K10: NC260 | L10: 3 | M10: 3 | N10: 102 | O10: =IF(OR(I10="LC2125",I10="LC2125_ER"),(L10+3)/4,IF(I10="LC2120",L10,"ERROR")) -> 3
A11: =IF(OR(I11="LC2125",I11="LC2125_ER"),"Hybrid HIPS",IF(I11="LC2120","Inbred HIPS","ERROR"))&"_"&O11&"_"&M11 -> Inbred HIPS_2_3 | B11: 1716014 | C11: 1729269 | D11: 2-row | E11: 1 | F11: 26 | G11: 1 | H11: ISU.IA.MOValley | I11: LC2120 | J11: 258 | K11: B104 | L11: 2 | M11: 3 | N11: 101 | O11: =IF(OR(I11="LC2125",I11="LC2125_ER"),(L11+3)/4,IF(I11="LC2120",L11,"ERROR")) -> 2
A12: =IF(OR(I12="LC2125",I12="LC2125_ER"),"Hybrid HIPS",IF(I12="LC2120","Inbred HIPS","ERROR"))&"_"&O12&"_"&M12 -> Inbred HIPS_2_4 | B12: 1715470 | C12: 1723025 | D12: 2-row | E12: 1 | F12: 47 | G12: 1 | H12: ISU.IA.MOValley | I12: LC2120 | J12: 14 | K12: A634 | L12: 2 | M12: 4 | N12: 120 | O12: =IF(OR(I12="LC2125",I12="LC2125_ER"),(L12+3)/4,IF(I12="LC2120",L12,"ERROR")) -> 2
A13: =IF(OR(I13="LC2125",I13="LC2125_ER"),"Hybrid HIPS",IF(I13="LC2120","Inbred HIPS","ERROR"))&"_"&O13&"_"&M13 -> Inbred HIPS_3_4 | B13: 1715871 | C13: 1729226 | D13: 2-row | E13: 1 | F13: 46 | G13: 1 | H13: ISU.IA.MOValley | I13: LC2120 | J13: 215 | K13: DE1 | L13: 3 | M13: 4 | N13: 119 | O13: =IF(OR(I13="LC2125",I13="LC2125_ER"),(L13+3)/4,IF(I13="LC2120",L13,"ERROR")) -> 3
A14: =IF(OR(I14="LC2125",I14="LC2125_ER"),"Hybrid HIPS",IF(I14="LC2120","Inbred HIPS","ERROR"))&"_"&O14&"_"&M14 -> Inbred HIPS_4_4 | B14: 1715820 | C14: 1729175 | D14: 2-row | E14: 1 | F14: 45 | G14: 1 | H14: ISU.IA.MOValley | I14: LC2120 | J14: 164 | K14: A679 | L14: 4 | M14: 4 | N14: 118 | O14: =IF(OR(I14="LC2125",I14="LC2125_ER"),(L14+3)/4,IF(I14="LC2120",L14,"ERROR")) -> 4
A15: =IF(OR(I15="LC2125",I15="LC2125_ER"),"Hybrid HIPS",IF(I15="LC2120","Inbred HIPS","ERROR"))&"_"&O15&"_"&M15 -> Inbred HIPS_5_4 | B15: 1716032 | C15: 1729287 | D15: 2-row | E15: 1 | F15: 44 | G15: 1 | H15: ISU.IA.MOValley | I15: LC2120 | J15: 276 | K15: B79 | L15: 5 | M15: 4 | N15: 117 | O15: =IF(OR(I15="LC2125",I15="LC2125_ER"),(L15+3)/4,IF(I15="LC2120",L15,"ERROR")) -> 5
A16: =IF(OR(I16="LC2125",I16="LC2125_ER"),"Hybrid HIPS",IF(I16="LC2120","Inbred HIPS","ERROR"))&"_"&O16&"_"&M16 -> Inbred HIPS_6_4 | B16: 1715835 | C16: 1729190 | D16: 2-row | E16: 1 | F16: 43 | G16: 1 | H16: ISU.IA.MOValley | I16: LC2120 | J16: 179 | K16: BO9 | L16: 6 | M16: 4 | N16: 116 | O16: =IF(OR(I16="LC2125",I16="LC2125_ER"),(L16+3)/4,IF(I16="LC2120",L16,"ERROR")) -> 6
A17: =IF(OR(I17="LC2125",I17="LC2125_ER"),"Hybrid HIPS",IF(I17="LC2120","Inbred HIPS","ERROR"))&"_"&O17&"_"&M17 -> Inbred HIPS_7_4 | B17: 1715474 | C17: 1723029 | D17: 2-row | E17: 1 | F17: 42 | G17: 1 | H17: ISU.IA.MOValley | I17: LC2120 | J17: 18 | K17: K55 | L17: 7 | M17: 4 | N17: 115 | O17: =IF(OR(I17="LC2125",I17="LC2125_ER"),(L17+3)/4,IF(I17="LC2120",L17,"ERROR")) -> 7
... A1029: =IF(OR(I1029="LC2125",I1029="LC2125_ER"),"Hybrid HIPS",IF(I1029="LC2120","Inbred HIPS","ERROR"))&"_"&O1029&"_"&M1029 -> Hybrid HIPS_21_41 | B1029: 1739801 | C1029: 1744302 | D1029: 4-row | E1029: 1 | F1029: 945 | G1029: 2 | H1029: ISU.IA.MOValley | I1029: LC2125_ER | J1029: 25 | K1029: ER-Pair 31 | L1029: 81 | M1029: 41 | N1029: 231 | O1029: =IF(OR(I1029="LC2125",I1029="LC2125_ER"),(L1029+3)/4,IF(I1029="LC2120",L1029,"ERROR")) -> 21

Sheet Original Maps
A1: Turkus Notes about Missouri Valley Fields
B2: LC2125 and LC2125_ER are the hybrid HIPS fields
B4: Exp Name | C4: Rep # | D4: Start plot # | E4: end plot # | F4: Note
B5: LC2125 | C5: 1 | D5: 101 | E5: 187 | F5: what would be plots 188-190 are filler
B6: LC2125 | C6: 2 | D6: 201 | E6: 287 | F6: what would be plots 288-290 are filler
B7: LC2125_ER | C7: 1 | D7: 101 | E7: 131 | F7: *part of the weird L
B8: LC2125_ER | C8: 2 | D8: 201 | E8: 231 | F8: *part of the weird L
B9: LC2120 | C9: 1 | D9: 1 | E9: 396 | F9: what would be plots 397-400 are filler
B10: LC2120 | C10: 2 | D10: 1 | E10: 396 | F10: what would be plots 397-400 are filler
B14: Other notes:
C15: Plot numbering is serpentine
C16: Hybrid's have an irregular layout (specifically for the LC2125_ER)
C17: Field is located to the North of the silos. Not sure if it's directly along the field, though.
C19: In Hybrids, rep 1 plots have the numbers 1XX, while rep2 had 2XX
C20: In inbreds, rep 1 and 2 have the same plot numbers
B23: Questions:
C24: Are row numbers staked?
D25: if yes, what are they for the inbred HIPS field?
E26: 1-12? or 85-106?

Sheet Turkus Layout
A1: Hybrid HIPS (By Plot #) | AA1: North | CK1: Inbred HIPS (By Plot #) | CP1: Rep 2
H2: LC2125 - Rep 1 | L2: LC2125 - Rep 2 | R2: LC2125_ER - Rep 1 | V2: LC2125_ER - Rep 2 | CP2: Rep 1
B4: Plot Row | C4: 1 | G4: 2 | K4: 3 | O4: 4 | S4: 5 | W4: 6 | AA4: 7 | AE4: 8 | AI4: 9 | AM4: 10 | AQ4: 11 | AU4: 12 | AY4: 13 | BC4: 14 | BG4: 15 | BK4: 16 | BO4: 17 | BS4: 18 | BW4: 19 | CA4: 20 | CE4: 21 | CM4: Plot Row | CN4: 1 | CP4: 2 | CR4: 3 | CT4: 4 | CV4: 5 | CX4: 6 | CZ4: 7 | DB4: 8 | DD4: 9 | DF4: 10 | DH4: 11 | DJ4: 12
B5: Field Row | C5: 1 | D5: 2 | E5: 3 | F5: 4 | G5: 5 | H5: 6 | I5: 7 | J5: 8 | K5: 9 | L5: 10 | M5: 11 | N5: 12 | O5: 13 | P5: 14 | Q5: 15 | R5: 16 | S5: 17 | T5: 18 | U5: 19 | V5: 20 | W5: 21 | X5: 22 | Y5: 23 | Z5: 24 | AA5: 25 | AB5: 26 | AC5: 27 | AD5: 28 | AE5: 29 | AF5: 30 | AG5: 31 | AH5: 32 | AI5: 33 | AJ5: 34 | AK5: 35 | AL5: 36 | AM5: 37 | AN5: 38 | AO5: 39 | AP5: 40 | AQ5: 41 | AR5: 42 | AS5: 43 | AT5: 44 | AU5: 45 | AV5: 46 | AW5: 47 | AX5: 48 | AY5: 49 | AZ5: 50 | BA5: 51 | BB5: 52 | BC5: 53 | BD5: 54 | BE5: 55 | BF5: 56 | BG5: 57 | BH5: 58 | BI5: 59 | BJ5: 60 | BK5: 61 | BL5: 62 | BM5: 63 | BN5: 64 | BO5: 65 | BP5: 66 | BQ5: 67 | BR5: 68 | BS5: 69 | BT5: 70 | BU5: 71 | BV5: 72 | BW5: 73 | BX5: 74 | BY5: 75 | BZ5: 76 | CA5: 77 | CB5: 78 | CC5: 79 | CD5: 80 | CE5: 81 | CF5: 82 | CG5: 83 | CH5: 84 | CM5: Field Row | CN5: 1 | CO5: 2 | CP5: 3 | CQ5: 4 | CR5: 5 | CS5: 6 | CT5: 7 | CU5: 8 | CV5: 9 | CW5: 10 | CX5: 11 | CY5: 12 | CZ5: 13 | DA5: 14 | DB5: 15 | DC5: 16 | DD5: 17 | DE5: 18 | DF5: 19 | DG5: 20 | DH5: 21 | DI5: 22 | DJ5: 23 | DK5: 24
B6: 42 | C6: NA | G6: NA | K6: NA | O6: NA | S6: NA | W6: NA | AA6: NA | AE6: NA | AI6: NA | AM6: NA | AQ6: NA | AU6: NA | AY6: NA | BC6: NA | BG6: NA | BK6: NA | BO6: NA | BS6: NA | BW6: NA | CA6: NA | CE6: NA | CM6: 84 | CN6: =IF(ISERROR(VLOOKUP("Inbred HIPS_"&CN$4&"_"&$CM6,'Turkus Index'!$A:$D,4,FALSE)),"NA",VLOOKUP("Inbred HIPS_"&CN$4&"_"&$CM6,'Turkus Index'!$A:$D,4,FALSE)) -> NA | CP6: =IF(ISERROR(VLOOKUP("Inbred HIPS_"&CP$4&"_"&$CM6,'Turkus Index'!$A:$D,4,FALSE)),"NA",VLOOKUP("Inbred HIPS_"&CP$4&"_"&$CM6,'Turkus Index'!$A:$D,4,FALSE)) -> NA | CR6: =IF(ISERROR(VLOOKUP("Inbred HIPS_"&CR$4&"_"&$CM6,'Turkus Index'!$A:$D,4,FALSE)),"NA",VLOOKUP("Inbred HIPS_"&CR$4&"_"&$CM6,'Turkus Index'!$A:$D,4,FALSE)) -> NA | CT6: =IF(ISERROR(VLOOKUP("Inbred HIPS_"&CT$4&"_"&$CM6,'Turkus Index'!$A:$D,4,FALSE)),"NA",VLOOKUP("Inbred HIPS_"&CT$4&"_"&$CM6,'Turkus Index'!$A:$D,4,FALSE)) -> NA | CV6: =IF(ISERROR(VLOOKUP("Inbred HIPS_"&CV$4&"_"&$CM6,'Turkus Index'!$A:$D,4,FALSE)),"NA",VLOOKUP("Inbred HIPS_"&CV$4&"_"&$CM6,'Turkus Index'!$A:$D,4,FALSE)) -> NA | CX6: =IF(ISERROR(VLOOKUP("Inbred HIPS_"&CX$4&"_"&$CM6,'Turkus Index'!$A:$D,4,FALSE)),"NA",VLOOKUP("Inbred HIPS_"&CX$4&"_"&$CM6,'Turkus Index'!$A:$D,4,FALSE)) -> NA | CZ6: =IF(ISERROR(VLOOKUP("Inbred HIPS_"&CZ$4&"_"&$CM6,'Turkus Index'!$A:$D,4,FALSE)),"NA",VLOOKUP("Inbred HIPS_"&CZ$4&"_"&$CM6,'Turkus Index'!$A:$D,4,FALSE)) -> NA | DB6: =IF(ISERROR(VLOOKUP("Inbred HIPS_"&DB$4&"_"&$CM6,'Turkus Index'!$A:$D,4,FALSE)),"NA",VLOOKUP("Inbred HIPS_"&DB$4&"_"&$CM6,'Turkus Index'!$A:$D,4,FALSE)) -> NA | DD6: =IF(ISERROR(VLOOKUP("Inbred HIPS_"&DD$4&"_"&$CM6,'Turkus Index'!$A:$D,4,FALSE)),"NA",VLOOKUP("Inbred HIPS_"&DD$4&"_"&$CM6,'Turkus Index'!$A:$D,4,FALSE)) -> NA | DF6: =IF(ISERROR(VLOOKUP("Inbred HIPS_"&DF$4&"_"&$CM6,'Turkus Index'!$A:$D,4,FALSE)),"NA",VLOOKUP("Inbred HIPS_"&DF$4&"_"&$CM6,'Turkus Index'!$A:$D,4,FALSE)) -> NA | DH6: =IF(ISERROR(VLOOKUP("Inbred HIPS_"&DH$4&"_"&$CM6,'Turkus Index'!$A:$D,4,FALSE)),"NA",VLOOKUP("Inbred HIPS_"&DH$4&"_"&$CM6,'Turkus Index'!$A:$D,4,FALSE)) -> NA | DJ6: =IF(ISERROR(VLOOKUP("Inbred HIPS_"&DJ$4&"_"&$CM6,'Turkus Index'!$A:$D,4,FALSE)),"NA",VLOOKUP("Inbred HIPS_"&DJ$4&"_"&$CM6,'Turkus Index'!$A:$D,4,FALSE)) -> NA
A7: Range | B7: 41 | C7: NA | G7: NA | K7: NA | O7: NA | S7: NA | W7: NA | AA7: NA | AE7: NA | AI7: NA | AM7: NA | AQ7: NA | AU7: NA | AY7: =AY8+1 -> 223 | BC7: =AY7+1 -> 224 | BG7: =BC7+1 -> 225 | BK7: =BG7+1 -> 226 | BO7: =BK7+1 -> 227 | BS7: =BO7+1 -> 228 | BW7: =BS7+1 -> 229 | CA7: =BW7+1 -> 230 | CE7: =CA7+1 -> 231 | CL7: Range | CM7: 83 | CN7: =IF(ISERROR(VLOOKUP("Inbred HIPS_"&CN$4&"_"&$CM7,'Turkus Index'!$A:$D,4,FALSE)),"NA",VLOOKUP("Inbred HIPS_"&CN$4&"_"&$CM7,'Turkus Index'!$A:$D,4,FALSE)) -> NA | CP7: =IF(ISERROR(VLOOKUP("Inbred HIPS_"&CP$4&"_"&$CM7,'Turkus Index'!$A:$D,4,FALSE)),"NA",VLOOKUP("Inbred HIPS_"&CP$4&"_"&$CM7,'Turkus Index'!$A:$D,4,FALSE)) -> NA | CR7: =IF(ISERROR(VLOOKUP("Inbred HIPS_"&CR$4&"_"&$CM7,'Turkus Index'!$A:$D,4,FALSE)),"NA",VLOOKUP("Inbred HIPS_"&CR$4&"_"&$CM7,'Turkus Index'!$A:$D,4,FALSE)) -> NA | CT7: =IF(ISERROR(VLOOKUP("Inbred HIPS_"&CT$4&"_"&$CM7,'Turkus Index'!$A:$D,4,FALSE)),"NA",VLOOKUP("Inbred HIPS_"&CT$4&"_"&$CM7,'Turkus Index'!$A:$D,4,FALSE)) -> NA | CV7: =IF(ISERROR(VLOOKUP("Inbred HIPS_"&CV$4&"_"&$CM7,'Turkus Index'!$A:$D,4,FALSE)),"NA",VLOOKUP("Inbred HIPS_"&CV$4&"_"&$CM7,'Turkus Index'!$A:$D,4,FALSE)) -> NA | CX7: =IF(ISERROR(VLOOKUP("Inbred HIPS_"&CX$4&"_"&$CM7,'Turkus Index'!$A:$D,4,FALSE)),"NA",VLOOKUP("Inbred HIPS_"&CX$4&"_"&$CM7,'Turkus Index'!$A:$D,4,FALSE)) -> NA | CZ7: =IF(ISERROR(VLOOKUP("Inbred HIPS_"&CZ$4&"_"&$CM7,'Turkus Index'!$A:$D,4,FALSE)),"NA",VLOOKUP("Inbred HIPS_"&CZ$4&"_"&$CM7,'Turkus Index'!$A:$D,4,FALSE)) -> NA | DB7: =IF(ISERROR(VLOOKUP("Inbred HIPS_"&DB$4&"_"&$CM7,'Turkus Index'!$A:$D,4,FALSE)),"NA",VLOOKUP("Inbred HIPS_"&DB$4&"_"&$CM7,'Turkus Index'!$A:$D,4,FALSE)) -> NA | DD7: =IF(ISERROR(VLOOKUP("Inbred HIPS_"&DD$4&"_"&$CM7,'Turkus Index'!$A:$D,4,FALSE)),"NA",VLOOKUP("Inbred HIPS_"&DD$4&"_"&$CM7,'Turkus Index'!$A:$D,4,FALSE)) -> NA | DF7: =IF(ISERROR(VLOOKUP("Inbred HIPS_"&DF$4&"_"&$CM7,'Turkus Index'!$A:$D,4,FALSE)),"NA",VLOOKUP("Inbred HIPS_"&DF$4&"_"&$CM7,'Turkus Index'!$A:$D,4,FALSE)) -> NA | DH7: =IF(ISERROR(VLOOKUP("Inbred HIPS_"&DH$4&"_"&$CM7,'Turkus Index'!$A:$D,4,FALSE)),"NA",VLOOKUP("Inbred HIPS_"&DH$4&"_"&$CM7,'Turkus Index'!$A:$D,4,FALSE)) -> NA | DJ7: =IF(ISERROR(VLOOKUP("Inbred HIPS_"&DJ$4&"_"&$CM7,'Turkus Index'!$A:$D,4,FALSE)),"NA",VLOOKUP("Inbred HIPS_"&DJ$4&"_"&$CM7,'Turkus Index'!$A:$D,4,FALSE)) -> NA
B8: 40 | C8: NA | G8: NA | K8: NA | O8: NA | S8: NA | W8: NA | AA8: NA | AE8: NA | AI8: NA | AM8: NA | AQ8: NA | AU8: NA | AY8: =BC8+1 -> 222 | BC8: =BG8+1 -> 221 | BG8: =BK8+1 -> 220 | BK8: =BO8+1 -> 219 | BO8: =BS8+1 -> 218 | BS8: =BW8+1 -> 217 | BW8: =CA8+1 -> 216 | CA8: =CE8+1 -> 215 | CE8: =CE9+1 -> 214 | CM8: 82 | CN8: =IF(ISERROR(VLOOKUP("Inbred HIPS_"&CN$4&"_"&$CM8,'Turkus Index'!$A:$D,4,FALSE)),"NA",VLOOKUP("Inbred HIPS_"&CN$4&"_"&$CM8,'Turkus Index'!$A:$D,4,FALSE)) -> NA | CP8: =IF(ISERROR(VLOOKUP("Inbred HIPS_"&CP$4&"_"&$CM8,'Turkus Index'!$A:$D,4,FALSE)),"NA",VLOOKUP("Inbred HIPS_"&CP$4&"_"&$CM8,'Turkus Index'!$A:$D,4,FALSE)) -> Filler | CR8: =IF(ISERROR(VLOOKUP("Inbred HIPS_"&CR$4&"_"&$CM8,'Turkus Index'!$A:$D,4,FALSE)),"NA",VLOOKUP("Inbred HIPS_"&CR$4&"_"&$CM8,'Turkus Index'!$A:$D,4,FALSE)) -> Filler | CT8: =IF(ISERROR(VLOOKUP("Inbred HIPS_"&CT$4&"_"&$CM8,'Turkus Index'!$A:$D,4,FALSE)),"NA",VLOOKUP("Inbred HIPS_"&CT$4&"_"&$CM8,'Turkus Index'!$A:$D,4,FALSE)) -> Filler | CV8: =IF(ISERROR(VLOOKUP("Inbred HIPS_"&CV$4&"_"&$CM8,'Turkus Index'!$A:$D,4,FALSE)),"NA",VLOOKUP("Inbred HIPS_"&CV$4&"_"&$CM8,'Turkus Index'!$A:$D,4,FALSE)) -> Filler | CX8: =IF(ISERROR(VLOOKUP("Inbred HIPS_"&CX$4&"_"&$CM8,'Turkus Index'!$A:$D,4,FALSE)),"NA",VLOOKUP("Inbred HIPS_"&CX$4&"_"&$CM8,'Turkus Index'!$A:$D,4,FALSE)) -> 596 | CZ8: =IF(ISERROR(VLOOKUP("Inbred HIPS_"&CZ$4&"_"&$CM8,'Turkus Index'!$A:$D,4,FALSE)),"NA",VLOOKUP("Inbred HIPS_"&CZ$4&"_"&$CM8,'Turkus Index'!$A:$D,4,FALSE)) -> 595 | DB8: =IF(ISERROR(VLOOKUP("Inbred HIPS_"&DB$4&"_"&$CM8,'Turkus Index'!$A:$D,4,FALSE)),"NA",VLOOKUP("Inbred HIPS_"&DB$4&"_"&$CM8,'Turkus Index'!$A:$D,4,FALSE)) -> 594 | DD8: =IF(ISERROR(VLOOKUP("Inbred HIPS_"&DD$4&"_"&$CM8,'Turkus Index'!$A:$D,4,FALSE)),"NA",VLOOKUP("Inbred HIPS_"&DD$4&"_"&$CM8,'Turkus Index'!$A:$D,4,FALSE)) -> 593 | DF8: =IF(ISERROR(VLOOKUP("Inbred HIPS_"&DF$4&"_"&$CM8,'Turkus Index'!$A:$D,4,FALSE)),"NA",VLOOKUP("Inbred HIPS_"&DF$4&"_"&$CM8,'Turkus Index'!$A:$D,4,FALSE)) -> 592 | DH8: =IF(ISERROR(VLOOKUP("Inbred HIPS_"&DH$4&"_"&$CM8,'Turkus Index'!$A:$D,4,FALSE)),"NA",VLOOKUP("Inbred HIPS_"&DH$4&"_"&$CM8,'Turkus Index'!$A:$D,4,FALSE)) -> 591 | DJ8: =IF(ISERROR(VLOOKUP("Inbred HIPS_"&DJ$4&"_"&$CM8,'Turkus Index'!$A:$D,4,FALSE)),"NA",VLOOKUP("Inbred HIPS_"&DJ$4&"_"&$CM8,'Turkus Index'!$A:$D,4,FALSE)) -> NA
B9: 39 | C9: NA | G9: NA | K9: NA | O9: NA | S9: NA | W9: NA | AA9: NA | AE9: NA | AI9: NA | AM9: NA | AQ9: NA | AU9: NA | AY9: NA | BC9: NA | BG9: NA | BK9: NA | BO9: NA | BS9: NA | BW9: NA | CA9: =CA10+1 -> 212 | CE9: =CA9+1 -> 213 | CM9: 81 | CN9: =IF(ISERROR(VLOOKUP("Inbred HIPS_"&CN$4&"_"&$CM9,'Turkus Index'!$A:$D,4,FALSE)),"NA",VLOOKUP("Inbred HIPS_"&CN$4&"_"&$CM9,'Turkus Index'!$A:$D,4,FALSE)) -> NA | CP9: =IF(ISERROR(VLOOKUP("Inbred HIPS_"&CP$4&"_"&$CM9,'Turkus Index'!$A:$D,4,FALSE)),"NA",VLOOKUP("Inbred HIPS_"&CP$4&"_"&$CM9,'Turkus Index'!$A:$D,4,FALSE)) -> 581 | CR9: =IF(ISERROR(VLOOKUP("Inbred HIPS_"&CR$4&"_"&$CM9,'Turkus Index'!$A:$D,4,FALSE)),"NA",VLOOKUP("Inbred HIPS_"&CR$4&"_"&$CM9,'Turkus Index'!$A:$D,4,FALSE)) -> 582 | CT9: =IF(ISERROR(VLOOKUP("Inbred HIPS_"&CT$4&"_"&$CM9,'Turkus Index'!$A:$D,4,FALSE)),"NA",VLOOKUP("Inbred HIPS_"&CT$4&"_"&$CM9,'Turkus Index'!$A:$D,4,FALSE)) -> 583 | CV9: =IF(ISERROR(VLOOKUP("Inbred HIPS_"&CV$4&"_"&$CM9,'Turkus Index'!$A:$D,4,FALSE)),"NA",VLOOKUP("Inbred HIPS_"&CV$4&"_"&$CM9,'Turkus Index'!$A:$D,4,FALSE)) -> 584 | CX9: =IF(ISERROR(VLOOKUP("Inbred HIPS_"&CX$4&"_"&$CM9,'Turkus Index'!$A:$D,4,FALSE)),"NA",VLOOKUP("Inbred HIPS_"&CX$4&"_"&$CM9,'Turkus Index'!$A:$D,4,FALSE)) -> 585 | CZ9: =IF(ISERROR(VLOOKUP("Inbred HIPS_"&CZ$4&"_"&$CM9,'Turkus Index'!$A:$D,4,FALSE)),"NA",VLOOKUP("Inbred HIPS_"&CZ$4&"_"&$CM9,'Turkus Index'!$A:$D,4,FALSE)) -> 586 | DB9: =IF(ISERROR(VLOOKUP("Inbred HIPS_"&DB$4&"_"&$CM9,'Turkus Index'!$A:$D,4,FALSE)),"NA",VLOOKUP("Inbred HIPS_"&DB$4&"_"&$CM9,'Turkus Index'!$A:$D,4,FALSE)) -> 587 | DD9: =IF(ISERROR(VLOOKUP("Inbred HIPS_"&DD$4&"_"&$CM9,'Turkus Index'!$A:$D,4,FALSE)),"NA",VLOOKUP("Inbred HIPS_"&DD$4&"_"&$CM9,'Turkus Index'!$A:$D,4,FALSE)) -> 588 | DF9: =IF(ISERROR(VLOOKUP("Inbred HIPS_"&DF$4&"_"&$CM9,'Turkus Index'!$A:$D,4,FALSE)),"NA",VLOOKUP("Inbred HIPS_"&DF$4&"_"&$CM9,'Turkus Index'!$A:$D,4,FALSE)) -> 589 | DH9: =IF(ISERROR(VLOOKUP("Inbred HIPS_"&DH$4&"_"&$CM9,'Turkus Index'!$A:$D,4,FALSE)),"NA",VLOOKUP("Inbred HIPS_"&DH$4&"_"&$CM9,'Turkus Index'!$A:$D,4,FALSE)) -> 590 | DJ9: =IF(ISERROR(VLOOKUP("Inbred HIPS_"&DJ$4&"_"&$CM9,'Turkus Index'!$A:$D,4,FALSE)),"NA",VLOOKUP("Inbred HIPS_"&DJ$4&"_"&$CM9,'Turkus Index'!$A:$D,4,FALSE)) -> NA
B10: 38 | C10: NA | G10: NA | K10: NA | O10: NA | S10: NA | W10: NA | AA10: NA | AE10: NA | AI10: NA | AM10: NA | AQ10: NA | AU10: NA | AY10: NA | BC10: NA | BG10: NA | BK10: NA | BO10: NA | BS10: NA | BW10: NA | CA10: =CE10+1 -> 211 | CE10: =CE11+1 -> 210 | CM10: 80 | CN10: =IF(ISERROR(VLOOKUP("Inbred HIPS_"&CN$4&"_"&$CM10,'Turkus Index'!$A:$D,4,FALSE)),"NA",VLOOKUP("Inbred HIPS_"&CN$4&"_"&$CM10,'Turkus Index'!$A:$D,4,FALSE)) -> NA | CP10: =IF(ISERROR(VLOOKUP("Inbred HIPS_"&CP$4&"_"&$CM10,'Turkus Index'!$A:$D,4,FALSE)),"NA",VLOOKUP("Inbred HIPS_"&CP$4&"_"&$CM10,'Turkus Index'!$A:$D,4,FALSE)) -> 580 | CR10: =IF(ISERROR(VLOOKUP("Inbred HIPS_"&CR$4&"_"&$CM10,'Turkus Index'!$A:$D,4,FALSE)),"NA",VLOOKUP("Inbred HIPS_"&CR$4&"_"&$CM10,'Turkus Index'!$A:$D,4,FALSE)) -> 579 | CT10: =IF(ISERROR(VLOOKUP("Inbred HIPS_"&CT$4&"_"&$CM10,'Turkus Index'!$A:$D,4,FALSE)),"NA",VLOOKUP("Inbred HIPS_"&CT$4&"_"&$CM10,'Turkus Index'!$A:$D,4,FALSE)) -> 578 | CV10: =IF(ISERROR(VLOOKUP("Inbred HIPS_"&CV$4&"_"&$CM10,'Turkus Index'!$A:$D,4,FALSE)),"NA",VLOOKUP("Inbred HIPS_"&CV$4&"_"&$CM10,'Turkus Index'!$A:$D,4,FALSE)) -> 577 | CX10: =IF(ISERROR(VLOOKUP("Inbred HIPS_"&CX$4&"_"&$CM10,'Turkus Index'!$A:$D,4,FALSE)),"NA",VLOOKUP("Inbred HIPS_"&CX$4&"_"&$CM10,'Turkus Index'!$A:$D,4,FALSE)) -> 576 | CZ10: =IF(ISERROR(VLOOKUP("Inbred HIPS_"&CZ$4&"_"&$CM10,'Turkus Index'!$A:$D,4,FALSE)),"NA",VLOOKUP("Inbred HIPS_"&CZ$4&"_"&$CM10,'Turkus Index'!$A:$D,4,FALSE)) -> 575 | DB10: =IF(ISERROR(VLOOKUP("Inbred HIPS_"&DB$4&"_"&$CM10,'Turkus Index'!$A:$D,4,FALSE)),"NA",VLOOKUP("Inbred HIPS_"&DB$4&"_"&$CM10,'Turkus Index'!$A:$D,4,FALSE)) -> 574 | DD10: =IF(ISERROR(VLOOKUP("Inbred HIPS_"&DD$4&"_"&$CM10,'Turkus Index'!$A:$D,4,FALSE)),"NA",VLOOKUP("Inbred HIPS_"&DD$4&"_"&$CM10,'Turkus Index'!$A:$D,4,FALSE)) -> 573 | DF10: =IF(ISERROR(VLOOKUP("Inbred HIPS_"&DF$4&"_"&$CM10,'Turkus Index'!$A:$D,4,FALSE)),"NA",VLOOKUP("Inbred HIPS_"&DF$4&"_"&$CM10,'Turkus Index'!$A:$D,4,FALSE)) -> 572 | DH10: =IF(ISERROR(VLOOKUP("Inbred HIPS_"&DH$4&"_"&$CM10,'Turkus Index'!$A:$D,4,FALSE)),"NA",VLOOKUP("Inbred HIPS_"&DH$4&"_"&$CM10,'Turkus Index'!$A:$D,4,FALSE)) -> 571 | DJ10: =IF(ISERROR(VLOOKUP("Inbred HIPS_"&DJ$4&"_"&$CM10,'Turkus Index'!$A:$D,4,FALSE)),"NA",VLOOKUP("Inbred HIPS_"&DJ$4&"_"&$CM10,'Turkus Index'!$A:$D,4,FALSE)) -> NA
B11: 37 | C11: NA | G11: NA | K11: NA | O11: NA | S11: NA | W11: NA | AA11: NA | AE11: NA | AI11: NA | AM11: NA | AQ11: NA | AU11: NA | AY11: NA | BC11: NA | BG11: NA | BK11: NA | BO11: NA | BS11: NA | BW11: NA | CA11: =CA12+1 -> 208 | CE11: =CA11+1 -> 209 | CM11: 79 | CN11: =IF(ISERROR(VLOOKUP("Inbred HIPS_"&CN$4&"_"&$CM11,'Turkus Index'!$A:$D,4,FALSE)),"NA",VLOOKUP("Inbred HIPS_"&CN$4&"_"&$CM11,'Turkus Index'!$A:$D,4,FALSE)) -> NA | CP11: =IF(ISERROR(VLOOKUP("Inbred HIPS_"&CP$4&"_"&$CM11,'Turkus Index'!$A:$D,4,FALSE)),"NA",VLOOKUP("Inbred HIPS_"&CP$4&"_"&$CM11,'Turkus Index'!$A:$D,4,FALSE)) -> 561 | CR11: =IF(ISERROR(VLOOKUP("Inbred HIPS_"&CR$4&"_"&$CM11,'Turkus Index'!$A:$D,4,FALSE)),"NA",VLOOKUP("Inbred HIPS_"&CR$4&"_"&$CM11,'Turkus Index'!$A:$D,4,FALSE)) -> 562 | CT11: =IF(ISERROR(VLOOKUP("Inbred HIPS_"&CT$4&"_"&$CM11,'Turkus Index'!$A:$D,4,FALSE)),"NA",VLOOKUP("Inbred HIPS_"&CT$4&"_"&$CM11,'Turkus Index'!$A:$D,4,FALSE)) -> 563 | CV11: =IF(ISERROR(VLOOKUP("Inbred HIPS_"&CV$4&"_"&$CM11,'Turkus Index'!$A:$D,4,FALSE)),"NA",VLOOKUP("Inbred HIPS_"&CV$4&"_"&$CM11,'Turkus Index'!$A:$D,4,FALSE)) -> 564 | CX11: =IF(ISERROR(VLOOKUP("Inbred HIPS_"&CX$4&"_"&$CM11,'Turkus Index'!$A:$D,4,FALSE)),"NA",VLOOKUP("Inbred HIPS_"&CX$4&"_"&$CM11,'Turkus Index'!$A:$D,4,FALSE)) -> 565 | CZ11: =IF(ISERROR(VLOOKUP("Inbred HIPS_"&CZ$4&"_"&$CM11,'Turkus Index'!$A:$D,4,FALSE)),"NA",VLOOKUP("Inbred HIPS_"&CZ$4&"_"&$CM11,'Turkus Index'!$A:$D,4,FALSE)) -> 566 | DB11: =IF(ISERROR(VLOOKUP("Inbred HIPS_"&DB$4&"_"&$CM11,'Turkus Index'!$A:$D,4,FALSE)),"NA",VLOOKUP("Inbred HIPS_"&DB$4&"_"&$CM11,'Turkus Index'!$A:$D,4,FALSE)) -> 567 | DD11: =IF(ISERROR(VLOOKUP("Inbred HIPS_"&DD$4&"_"&$CM11,'Turkus Index'!$A:$D,4,FALSE)),"NA",VLOOKUP("Inbred HIPS_"&DD$4&"_"&$CM11,'Turkus Index'!$A:$D,4,FALSE)) -> 568 | DF11: =IF(ISERROR(VLOOKUP("Inbred HIPS_"&DF$4&"_"&$CM11,'Turkus Index'!$A:$D,4,FALSE)),"NA",VLOOKUP("Inbred HIPS_"&DF$4&"_"&$CM11,'Turkus Index'!$A:$D,4,FALSE)) -> 569 | DH11: =IF(ISERROR(VLOOKUP("Inbred HIPS_"&DH$4&"_"&$CM11,'Turkus Index'!$A:$D,4,FALSE)),"NA",VLOOKUP("Inbred HIPS_"&DH$4&"_"&$CM11,'Turkus Index'!$A:$D,4,FALSE)) -> 570 | DJ11: =IF(ISERROR(VLOOKUP("Inbred HIPS_"&DJ$4&"_"&$CM11,'Turkus Index'!$A:$D,4,FALSE)),"NA",VLOOKUP("Inbred HIPS_"&DJ$4&"_"&$CM11,'Turkus Index'!$A:$D,4,FALSE)) -> NA
B12: 36 | C12: NA | G12: NA | K12: NA | O12: NA | S12: NA | W12: NA | AA12: NA | AE12: NA | AI12: NA | AM12: NA | AQ12: NA | AU12: NA | AY12: NA | BC12: NA | BG12: NA | BK12: NA | BO12: NA | BS12: NA | BW12: NA | CA12: =CE12+1 -> 207 | CE12: =CE13+1 -> 206 | CM12: 78 | CN12: =IF(ISERROR(VLOOKUP("Inbred HIPS_"&CN$4&"_"&$CM12,'Turkus Index'!$A:$D,4,FALSE)),"NA",VLOOKUP("Inbred HIPS_"&CN$4&"_"&$CM12,'Turkus Index'!$A:$D,4,FALSE)) -> NA | CP12: =IF(ISERROR(VLOOKUP("Inbred HIPS_"&CP$4&"_"&$CM12,'Turkus Index'!$A:$D,4,FALSE)),"NA",VLOOKUP("Inbred HIPS_"&CP$4&"_"&$CM12,'Turkus Index'!$A:$D,4,FALSE)) -> 560 | CR12: =IF(ISERROR(VLOOKUP("Inbred HIPS_"&CR$4&"_"&$CM12,'Turkus Index'!$A:$D,4,FALSE)),"NA",VLOOKUP("Inbred HIPS_"&CR$4&"_"&$CM12,'Turkus Index'!$A:$D,4,FALSE)) -> 559 | CT12: =IF(ISERROR(VLOOKUP("Inbred HIPS_"&CT$4&"_"&$CM12,'Turkus Index'!$A:$D,4,FALSE)),"NA",VLOOKUP("Inbred HIPS_"&CT$4&"_"&$CM12,'Turkus Index'!$A:$D,4,FALSE)) -> 558 | CV12: =IF(ISERROR(VLOOKUP("Inbred HIPS_"&CV$4&"_"&$CM12,'Turkus Index'!$A:$D,4,FALSE)),"NA",VLOOKUP("Inbred HIPS_"&CV$4&"_"&$CM12,'Turkus Index'!$A:$D,4,FALSE)) -> 557 | CX12: =IF(ISERROR(VLOOKUP("Inbred HIPS_"&CX$4&"_"&$CM12,'Turkus Index'!$A:$D,4,FALSE)),"NA",VLOOKUP("Inbred HIPS_"&CX$4&"_"&$CM12,'Turkus Index'!$A:$D,4,FALSE)) -> 556 | CZ12: =IF(ISERROR(VLOOKUP("Inbred HIPS_"&CZ$4&"_"&$CM12,'Turkus Index'!$A:$D,4,FALSE)),"NA",VLOOKUP("Inbred HIPS_"&CZ$4&"_"&$CM12,'Turkus Index'!$A:$D,4,FALSE)) -> 555 | DB12: =IF(ISERROR(VLOOKUP("Inbred HIPS_"&DB$4&"_"&$CM12,'Turkus Index'!$A:$D,4,FALSE)),"NA",VLOOKUP("Inbred HIPS_"&DB$4&"_"&$CM12,'Turkus Index'!$A:$D,4,FALSE)) -> 554 | DD12: =IF(ISERROR(VLOOKUP("Inbred HIPS_"&DD$4&"_"&$CM12,'Turkus Index'!$A:$D,4,FALSE)),"NA",VLOOKUP("Inbred HIPS_"&DD$4&"_"&$CM12,'Turkus Index'!$A:$D,4,FALSE)) -> 553 | DF12: =IF(ISERROR(VLOOKUP("Inbred HIPS_"&DF$4&"_"&$CM12,'Turkus Index'!$A:$D,4,FALSE)),"NA",VLOOKUP("Inbred HIPS_"&DF$4&"_"&$CM12,'Turkus Index'!$A:$D,4,FALSE)) -> 552 | DH12: =IF(ISERROR(VLOOKUP("Inbred HIPS_"&DH$4&"_"&$CM12,'Turkus Index'!$A:$D,4,FALSE)),"NA",VLOOKUP("Inbred HIPS_"&DH$4&"_"&$CM12,'Turkus Index'!$A:$D,4,FALSE)) -> 551 | DJ12: =IF(ISERROR(VLOOKUP("Inbred HIPS_"&DJ$4&"_"&$CM12,'Turkus Index'!$A:$D,4,FALSE)),"NA",VLOOKUP("Inbred HIPS_"&DJ$4&"_"&$CM12,'Turkus Index'!$A:$D,4,FALSE)) -> NA
B13: 35 | C13: NA | G13: NA | K13: NA | O13: NA | S13: NA | W13: NA | AA13: NA | AE13: NA | AI13: NA | AM13: NA | AQ13: NA | AU13: NA | AY13: NA | BC13: NA | BG13: NA | BK13: NA | BO13: NA | BS13: NA | BW13: NA | CA13: =CA14+1 -> 204 | CE13: =CA13+1 -> 205 | CM13: 77 | CN13: =IF(ISERROR(VLOOKUP("Inbred HIPS_"&CN$4&"_"&$CM13,'Turkus Index'!$A:$D,4,FALSE)),"NA",VLOOKUP("Inbred HIPS_"&CN$4&"_"&$CM13,'Turkus Index'!$A:$D,4,FALSE)) -> NA | CP13: =IF(ISERROR(VLOOKUP("Inbred HIPS_"&CP$4&"_"&$CM13,'Turkus Index'!$A:$D,4,FALSE)),"NA",VLOOKUP("Inbred HIPS_"&CP$4&"_"&$CM13,'Turkus Index'!$A:$D,4,FALSE)) -> 541 | CR13: =IF(ISERROR(VLOOKUP("Inbred HIPS_"&CR$4&"_"&$CM13,'Turkus Index'!$A:$D,4,FALSE)),"NA",VLOOKUP("Inbred HIPS_"&CR$4&"_"&$CM13,'Turkus Index'!$A:$D,4,FALSE)) -> 542 | CT13: =IF(ISERROR(VLOOKUP("Inbred HIPS_"&CT$4&"_"&$CM13,'Turkus Index'!$A:$D,4,FALSE)),"NA",VLOOKUP("Inbred HIPS_"&CT$4&"_"&$CM13,'Turkus Index'!$A:$D,4,FALSE)) -> 543 | CV13: =IF(ISERROR(VLOOKUP("Inbred HIPS_"&CV$4&"_"&$CM13,'Turkus Index'!$A:$D,4,FALSE)),"NA",VLOOKUP("Inbred HIPS_"&CV$4&"_"&$CM13,'Turkus Index'!$A:$D,4,FALSE)) -> 544 | CX13: =IF(ISERROR(VLOOKUP("Inbred HIPS_"&CX$4&"_"&$CM13,'Turkus Index'!$A:$D,4,FALSE)),"NA",VLOOKUP("Inbred HIPS_"&CX$4&"_"&$CM13,'Turkus Index'!$A:$D,4,FALSE)) -> 545 | CZ13: =IF(ISERROR(VLOOKUP("Inbred HIPS_"&CZ$4&"_"&$CM13,'Turkus Index'!$A:$D,4,FALSE)),"NA",VLOOKUP("Inbred HIPS_"&CZ$4&"_"&$CM13,'Turkus Index'!$A:$D,4,FALSE)) -> 546 | DB13: =IF(ISERROR(VLOOKUP("Inbred HIPS_"&DB$4&"_"&$CM13,'Turkus Index'!$A:$D,4,FALSE)),"NA",VLOOKUP("Inbred HIPS_"&DB$4&"_"&$CM13,'Turkus Index'!$A:$D,4,FALSE)) -> 547 | DD13: =IF(ISERROR(VLOOKUP("Inbred HIPS_"&DD$4&"_"&$CM13,'Turkus Index'!$A:$D,4,FALSE)),"NA",VLOOKUP("Inbred HIPS_"&DD$4&"_"&$CM13,'Turkus Index'!$A:$D,4,FALSE)) -> 548 | DF13: =IF(ISERROR(VLOOKUP("Inbred HIPS_"&DF$4&"_"&$CM13,'Turkus Index'!$A:$D,4,FALSE)),"NA",VLOOKUP("Inbred HIPS_"&DF$4&"_"&$CM13,'Turkus Index'!$A:$D,4,FALSE)) -> 549 | DH13: =IF(ISERROR(VLOOKUP("Inbred HIPS_"&DH$4&"_"&$CM13,'Turkus Index'!$A:$D,4,FALSE)),"NA",VLOOKUP("Inbred HIPS_"&DH$4&"_"&$CM13,'Turkus Index'!$A:$D,4,FALSE)) -> 550 | DJ13: =IF(ISERROR(VLOOKUP("Inbred HIPS_"&DJ$4&"_"&$CM13,'Turkus Index'!$A:$D,4,FALSE)),"NA",VLOOKUP("Inbred HIPS_"&DJ$4&"_"&$CM13,'Turkus Index'!$A:$D,4,FALSE)) -> NA
B14: 34 | C14: NA | G14: NA | K14: NA | O14: NA | S14: NA | W14: NA | AA14: NA | AE14: NA | AI14: NA | AM14: NA | AQ14: NA | AU14: NA | AY14: NA | BC14: NA | BG14: NA | BK14: NA | BO14: NA | BS14: NA | BW14: NA | CA14: =CE14+1 -> 203 | CE14: 202 | CM14: 76 | CN14: =IF(ISERROR(VLOOKUP("Inbred HIPS_"&CN$4&"_"&$CM14,'Turkus Index'!$A:$D,4,FALSE)),"NA",VLOOKUP("Inbred HIPS_"&CN$4&"_"&$CM14,'Turkus Index'!$A:$D,4,FALSE)) -> NA | CP14: =IF(ISERROR(VLOOKUP("Inbred HIPS_"&CP$4&"_"&$CM14,'Turkus Index'!$A:$D,4,FALSE)),"NA",VLOOKUP("Inbred HIPS_"&CP$4&"_"&$CM14,'Turkus Index'!$A:$D,4,FALSE)) -> 540 | CR14: =IF(ISERROR(VLOOKUP("Inbred HIPS_"&CR$4&"_"&$CM14,'Turkus Index'!$A:$D,4,FALSE)),"NA",VLOOKUP("Inbred HIPS_"&CR$4&"_"&$CM14,'Turkus Index'!$A:$D,4,FALSE)) -> 539 | CT14: =IF(ISERROR(VLOOKUP("Inbred HIPS_"&CT$4&"_"&$CM14,'Turkus Index'!$A:$D,4,FALSE)),"NA",VLOOKUP("Inbred HIPS_"&CT$4&"_"&$CM14,'Turkus Index'!$A:$D,4,FALSE)) -> 538 | CV14: =IF(ISERROR(VLOOKUP("Inbred HIPS_"&CV$4&"_"&$CM14,'Turkus Index'!$A:$D,4,FALSE)),"NA",VLOOKUP("Inbred HIPS_"&CV$4&"_"&$CM14,'Turkus Index'!$A:$D,4,FALSE)) -> 537 | CX14: =IF(ISERROR(VLOOKUP("Inbred HIPS_"&CX$4&"_"&$CM14,'Turkus Index'!$A:$D,4,FALSE)),"NA",VLOOKUP("Inbred HIPS_"&CX$4&"_"&$CM14,'Turkus Index'!$A:$D,4,FALSE)) -> 536 | CZ14: =IF(ISERROR(VLOOKUP("Inbred HIPS_"&CZ$4&"_"&$CM14,'Turkus Index'!$A:$D,4,FALSE)),"NA",VLOOKUP("Inbred HIPS_"&CZ$4&"_"&$CM14,'Turkus Index'!$A:$D,4,FALSE)) -> 535 | DB14: =IF(ISERROR(VLOOKUP("Inbred HIPS_"&DB$4&"_"&$CM14,'Turkus Index'!$A:$D,4,FALSE)),"NA",VLOOKUP("Inbred HIPS_"&DB$4&"_"&$CM14,'Turkus Index'!$A:$D,4,FALSE)) -> 534 | DD14: =IF(ISERROR(VLOOKUP("Inbred HIPS_"&DD$4&"_"&$CM14,'Turkus Index'!$A:$D,4,FALSE)),"NA",VLOOKUP("Inbred HIPS_"&DD$4&"_"&$CM14,'Turkus Index'!$A:$D,4,FALSE)) -> 533 | DF14: =IF(ISERROR(VLOOKUP("Inbred HIPS_"&DF$4&"_"&$CM14,'Turkus Index'!$A:$D,4,FALSE)),"NA",VLOOKUP("Inbred HIPS_"&DF$4&"_"&$CM14,'Turkus Index'!$A:$D,4,FALSE)) -> 532 | DH14: =IF(ISERROR(VLOOKUP("Inbred HIPS_"&DH$4&"_"&$CM14,'Turkus Index'!$A:$D,4,FALSE)),"NA",VLOOKUP("Inbred HIPS_"&DH$4&"_"&$CM14,'Turkus Index'!$A:$D,4,FALSE)) -> 531 | DJ14: =IF(ISERROR(VLOOKUP("Inbred HIPS_"&DJ$4&"_"&$CM14,'Turkus Index'!$A:$D,4,FALSE)),"NA",VLOOKUP("Inbred HIPS_"&DJ$4&"_"&$CM14,'Turkus Index'!$A:$D,4,FALSE)) -> NA
B15: 33 | C15: NA | G15: NA | K15: NA | O15: NA | S15: NA | W15: NA | AA15: NA | AE15: NA | AI15: NA | AM15: NA | AQ15: NA | AU15: NA | AY15: NA | BC15: NA | BG15: NA | BK15: NA | BO15: NA | BS15: NA | BW15: NA | CA15: 201 | CE15: =CE16+1 -> 131 | CM15: 75 | CN15: =IF(ISERROR(VLOOKUP("Inbred HIPS_"&CN$4&"_"&$CM15,'Turkus Index'!$A:$D,4,FALSE)),"NA",VLOOKUP("Inbred HIPS_"&CN$4&"_"&$CM15,'Turkus Index'!$A:$D,4,FALSE)) -> NA | CP15: =IF(ISERROR(VLOOKUP("Inbred HIPS_"&CP$4&"_"&$CM15,'Turkus Index'!$A:$D,4,FALSE)),"NA",VLOOKUP("Inbred HIPS_"&CP$4&"_"&$CM15,'Turkus Index'!$A:$D,4,FALSE)) -> 521 | CR15: =IF(ISERROR(VLOOKUP("Inbred HIPS_"&CR$4&"_"&$CM15,'Turkus Index'!$A:$D,4,FALSE)),"NA",VLOOKUP("Inbred HIPS_"&CR$4&"_"&$CM15,'Turkus Index'!$A:$D,4,FALSE)) -> 522 | CT15: =IF(ISERROR(VLOOKUP("Inbred HIPS_"&CT$4&"_"&$CM15,'Turkus Index'!$A:$D,4,FALSE)),"NA",VLOOKUP("Inbred HIPS_"&CT$4&"_"&$CM15,'Turkus Index'!$A:$D,4,FALSE)) -> 523 | CV15: =IF(ISERROR(VLOOKUP("Inbred HIPS_"&CV$4&"_"&$CM15,'Turkus Index'!$A:$D,4,FALSE)),"NA",VLOOKUP("Inbred HIPS_"&CV$4&"_"&$CM15,'Turkus Index'!$A:$D,4,FALSE)) -> 524 | CX15: =IF(ISERROR(VLOOKUP("Inbred HIPS_"&CX$4&"_"&$CM15,'Turkus Index'!$A:$D,4,FALSE)),"NA",VLOOKUP("Inbred HIPS_"&CX$4&"_"&$CM15,'Turkus Index'!$A:$D,4,FALSE)) -> 525 | CZ15: =IF(ISERROR(VLOOKUP("Inbred HIPS_"&CZ$4&"_"&$CM15,'Turkus Index'!$A:$D,4,FALSE)),"NA",VLOOKUP("Inbred HIPS_"&CZ$4&"_"&$CM15,'Turkus Index'!$A:$D,4,FALSE)) -> 526 | DB15: =IF(ISERROR(VLOOKUP("Inbred HIPS_"&DB$4&"_"&$CM15,'Turkus Index'!$A:$D,4,FALSE)),"NA",VLOOKUP("Inbred HIPS_"&DB$4&"_"&$CM15,'Turkus Index'!$A:$D,4,FALSE)) -> 527 | DD15: =IF(ISERROR(VLOOKUP("Inbred HIPS_"&DD$4&"_"&$CM15,'Turkus Index'!$A:$D,4,FALSE)),"NA",VLOOKUP("Inbred HIPS_"&DD$4&"_"&$CM15,'Turkus Index'!$A:$D,4,FALSE)) -> 528 | DF15: =IF(ISERROR(VLOOKUP("Inbred HIPS_"&DF$4&"_"&$CM15,'Turkus Index'!$A:$D,4,FALSE)),"NA",VLOOKUP("Inbred HIPS_"&DF$4&"_"&$CM15,'Turkus Index'!$A:$D,4,FALSE)) -> 529 | DH15: =IF(ISERROR(VLOOKUP("Inbred HIPS_"&DH$4&"_"&$CM15,'Turkus Index'!$A:$D,4,FALSE)),"NA",VLOOKUP("Inbred HIPS_"&DH$4&"_"&$CM15,'Turkus Index'!$A:$D,4,FALSE)) -> 530 | DJ15: =IF(ISERROR(VLOOKUP("Inbred HIPS_"&DJ$4&"_"&$CM15,'Turkus Index'!$A:$D,4,FALSE)),"NA",VLOOKUP("Inbred HIPS_"&DJ$4&"_"&$CM15,'Turkus Index'!$A:$D,4,FALSE)) -> NA
B16: 32 | C16: NA | G16: NA | K16: NA | O16: NA | S16: NA | W16: NA | AA16: NA | AE16: NA | AI16: NA | AM16: NA | AQ16: NA | AU16: NA | AY16: NA | BC16: NA | BG16: NA | BK16: NA | BO16: NA | BS16: NA | BW16: NA | CA16: =CA17+1 -> 129 | CE16: =CA16+1 -> 130 | CM16: 74 | CN16: =IF(ISERROR(VLOOKUP("Inbred HIPS_"&CN$4&"_"&$CM16,'Turkus Index'!$A:$D,4,FALSE)),"NA",VLOOKUP("Inbred HIPS_"&CN$4&"_"&$CM16,'Turkus Index'!$A:$D,4,FALSE)) -> NA | CP16: =IF(ISERROR(VLOOKUP("Inbred HIPS_"&CP$4&"_"&$CM16,'Turkus Index'!$A:$D,4,FALSE)),"NA",VLOOKUP("Inbred HIPS_"&CP$4&"_"&$CM16,'Turkus Index'!$A:$D,4,FALSE)) -> 520 | CR16: =IF(ISERROR(VLOOKUP("Inbred HIPS_"&CR$4&"_"&$CM16,'Turkus Index'!$A:$D,4,FALSE)),"NA",VLOOKUP("Inbred HIPS_"&CR$4&"_"&$CM16,'Turkus Index'!$A:$D,4,FALSE)) -> 519 | CT16: =IF(ISERROR(VLOOKUP("Inbred HIPS_"&CT$4&"_"&$CM16,'Turkus Index'!$A:$D,4,FALSE)),"NA",VLOOKUP("Inbred HIPS_"&CT$4&"_"&$CM16,'Turkus Index'!$A:$D,4,FALSE)) -> 518 | CV16: =IF(ISERROR(VLOOKUP("Inbred HIPS_"&CV$4&"_"&$CM16,'Turkus Index'!$A:$D,4,FALSE)),"NA",VLOOKUP("Inbred HIPS_"&CV$4&"_"&$CM16,'Turkus Index'!$A:$D,4,FALSE)) -> 517 | CX16: =IF(ISERROR(VLOOKUP("Inbred HIPS_"&CX$4&"_"&$CM16,'Turkus Index'!$A:$D,4,FALSE)),"NA",VLOOKUP("Inbred HIPS_"&CX$4&"_"&$CM16,'Turkus Index'!$A:$D,4,FALSE)) -> 516 | CZ16: =IF(ISERROR(VLOOKUP("Inbred HIPS_"&CZ$4&"_"&$CM16,'Turkus Index'!$A:$D,4,FALSE)),"NA",VLOOKUP("Inbred HIPS_"&CZ$4&"_"&$CM16,'Turkus Index'!$A:$D,4,FALSE)) -> 515 | DB16: =IF(ISERROR(VLOOKUP("Inbred HIPS_"&DB$4&"_"&$CM16,'Turkus Index'!$A:$D,4,FALSE)),"NA",VLOOKUP("Inbred HIPS_"&DB$4&"_"&$CM16,'Turkus Index'!$A:$D,4,FALSE)) -> 514 | DD16: =IF(ISERROR(VLOOKUP("Inbred HIPS_"&DD$4&"_"&$CM16,'Turkus Index'!$A:$D,4,FALSE)),"NA",VLOOKUP("Inbred HIPS_"&DD$4&"_"&$CM16,'Turkus Index'!$A:$D,4,FALSE)) -> 513 | DF16: =IF(ISERROR(VLOOKUP("Inbred HIPS_"&DF$4&"_"&$CM16,'Turkus Index'!$A:$D,4,FALSE)),"NA",VLOOKUP("Inbred HIPS_"&DF$4&"_"&$CM16,'Turkus Index'!$A:$D,4,FALSE)) -> 512 | DH16: =IF(ISERROR(VLOOKUP("Inbred HIPS_"&DH$4&"_"&$CM16,'Turkus Index'!$A:$D,4,FALSE)),"NA",VLOOKUP("Inbred HIPS_"&DH$4&"_"&$CM16,'Turkus Index'!$A:$D,4,FALSE)) -> 511 | DJ16: =IF(ISERROR(VLOOKUP("Inbred HIPS_"&DJ$4&"_"&$CM16,'Turkus Index'!$A:$D,4,FALSE)),"NA",VLOOKUP("Inbred HIPS_"&DJ$4&"_"&$CM16,'Turkus Index'!$A:$D,4,FALSE)) -> NA
B17: 31 | C17: NA | G17: NA | K17: NA | O17: NA | S17: NA | W17: NA | AA17: NA | AE17: NA | AI17: NA | AM17: NA | AQ17: NA | AU17: NA | AY17: NA | BC17: NA | BG17: NA | BK17: NA | BO17: NA | BS17: NA | BW17: NA | CA17: =CE17+1 -> 128 | CE17: =CE18+1 -> 127 | CM17: 73 | CN17: =IF(ISERROR(VLOOKUP("Inbred HIPS_"&CN$4&"_"&$CM17,'Turkus Index'!$A:$D,4,FALSE)),"NA",VLOOKUP("Inbred HIPS_"&CN$4&"_"&$CM17,'Turkus Index'!$A:$D,4,FALSE)) -> NA | CP17: =IF(ISERROR(VLOOKUP("Inbred HIPS_"&CP$4&"_"&$CM17,'Turkus Index'!$A:$D,4,FALSE)),"NA",VLOOKUP("Inbred HIPS_"&CP$4&"_"&$CM17,'Turkus Index'!$A:$D,4,FALSE)) -> 501 | CR17: =IF(ISERROR(VLOOKUP("Inbred HIPS_"&CR$4&"_"&$CM17,'Turkus Index'!$A:$D,4,FALSE)),"NA",VLOOKUP("Inbred HIPS_"&CR$4&"_"&$CM17,'Turkus Index'!$A:$D,4,FALSE)) -> 502 | CT17: =IF(ISERROR(VLOOKUP("Inbred HIPS_"&CT$4&"_"&$CM17,'Turkus Index'!$A:$D,4,FALSE)),"NA",VLOOKUP("Inbred HIPS_"&CT$4&"_"&$CM17,'Turkus Index'!$A:$D,4,FALSE)) -> 503 | CV17: =IF(ISERROR(VLOOKUP("Inbred HIPS_"&CV$4&"_"&$CM17,'Turkus Index'!$A:$D,4,FALSE)),"NA",VLOOKUP("Inbred HIPS_"&CV$4&"_"&$CM17,'Turkus Index'!$A:$D,4,FALSE)) -> 504 | CX17: =IF(ISERROR(VLOOKUP("Inbred HIPS_"&CX$4&"_"&$CM17,'Turkus Index'!$A:$D,4,FALSE)),"NA",VLOOKUP("Inbred HIPS_"&CX$4&"_"&$CM17,'Turkus Index'!$A:$D,4,FALSE)) -> 505 | CZ17: =IF(ISERROR(VLOOKUP("Inbred HIPS_"&CZ$4&"_"&$CM17,'Turkus Index'!$A:$D,4,FALSE)),"NA",VLOOKUP("Inbred HIPS_"&CZ$4&"_"&$CM17,'Turkus Index'!$A:$D,4,FALSE)) -> 506 | DB17: =IF(ISERROR(VLOOKUP("Inbred HIPS_"&DB$4&"_"&$CM17,'Turkus Index'!$A:$D,4,FALSE)),"NA",VLOOKUP("Inbred HIPS_"&DB$4&"_"&$CM17,'Turkus Index'!$A:$D,4,FALSE)) -> 507 | DD17: =IF(ISERROR(VLOOKUP("Inbred HIPS_"&DD$4&"_"&$CM17,'Turkus Index'!$A:$D,4,FALSE)),"NA",VLOOKUP("Inbred HIPS_"&DD$4&"_"&$CM17,'Turkus Index'!$A:$D,4,FALSE)) -> 508 | DF17: =IF(ISERROR(VLOOKUP("Inbred HIPS_"&DF$4&"_"&$CM17,'Turkus Index'!$A:$D,4,FALSE)),"NA",VLOOKUP("Inbred HIPS_"&DF$4&"_"&$CM17,'Turkus Index'!$A:$D,4,FALSE)) -> 509 | DH17: =IF(ISERROR(VLOOKUP("Inbred HIPS_"&DH$4&"_"&$CM17,'Turkus Index'!$A:$D,4,FALSE)),"NA",VLOOKUP("Inbred HIPS_"&DH$4&"_"&$CM17,'Turkus Index'!$A:$D,4,FALSE)) -> 510 | DJ17: =IF(ISERROR(VLOOKUP("Inbred HIPS_"&DJ$4&"_"&$CM17,'Turkus Index'!$A:$D,4,FALSE)),"NA",VLOOKUP("Inbred HIPS_"&DJ$4&"_"&$CM17,'Turkus Index'!$A:$D,4,FALSE)) -> NA
B18: 30 | C18: NA | G18: NA | K18: NA | O18: NA | S18: NA | W18: NA | AA18: NA | AE18: NA | AI18: NA | AM18: NA | AQ18: NA | AU18: NA | AY18: NA | BC18: NA | BG18: NA | BK18: NA | BO18: NA | BS18: NA | BW18: NA | CA18: =CA19+1 -> 125 | CE18: =CA18+1 -> 126 | CM18: 72 | CN18: =IF(ISERROR(VLOOKUP("Inbred HIPS_"&CN$4&"_"&$CM18,'Turkus Index'!$A:$D,4,FALSE)),"NA",VLOOKUP("Inbred HIPS_"&CN$4&"_"&$CM18,'Turkus Index'!$A:$D,4,FALSE)) -> NA | CP18: =IF(ISERROR(VLOOKUP("Inbred HIPS_"&CP$4&"_"&$CM18,'Turkus Index'!$A:$D,4,FALSE)),"NA",VLOOKUP("Inbred HIPS_"&CP$4&"_"&$CM18,'Turkus Index'!$A:$D,4,FALSE)) -> 500 | CR18: =IF(ISERROR(VLOOKUP("Inbred HIPS_"&CR$4&"_"&$CM18,'Turkus Index'!$A:$D,4,FALSE)),"NA",VLOOKUP("Inbred HIPS_"&CR$4&"_"&$CM18,'Turkus Index'!$A:$D,4,FALSE)) -> 499 | CT18: =IF(ISERROR(VLOOKUP("Inbred HIPS_"&CT$4&"_"&$CM18,'Turkus Index'!$A:$D,4,FALSE)),"NA",VLOOKUP("Inbred HIPS_"&CT$4&"_"&$CM18,'Turkus Index'!$A:$D,4,FALSE)) -> 498 | CV18: =IF(ISERROR(VLOOKUP("Inbred HIPS_"&CV$4&"_"&$CM18,'Turkus Index'!$A:$D,4,FALSE)),"NA",VLOOKUP("Inbred HIPS_"&CV$4&"_"&$CM18,'Turkus Index'!$A:$D,4,FALSE)) -> 497 | CX18: =IF(ISERROR(VLOOKUP("Inbred HIPS_"&CX$4&"_"&$CM18,'Turkus Index'!$A:$D,4,FALSE)),"NA",VLOOKUP("Inbred HIPS_"&CX$4&"_"&$CM18,'Turkus Index'!$A:$D,4,FALSE)) -> 496 | CZ18: =IF(ISERROR(VLOOKUP("Inbred HIPS_"&CZ$4&"_"&$CM18,'Turkus Index'!$A:$D,4,FALSE)),"NA",VLOOKUP("Inbred HIPS_"&CZ$4&"_"&$CM18,'Turkus Index'!$A:$D,4,FALSE)) -> 495 | DB18: =IF(ISERROR(VLOOKUP("Inbred HIPS_"&DB$4&"_"&$CM18,'Turkus Index'!$A:$D,4,FALSE)),"NA",VLOOKUP("Inbred HIPS_"&DB$4&"_"&$CM18,'Turkus Index'!$A:$D,4,FALSE)) -> 494 | DD18: =IF(ISERROR(VLOOKUP("Inbred HIPS_"&DD$4&"_"&$CM18,'Turkus Index'!$A:$D,4,FALSE)),"NA",VLOOKUP("Inbred HIPS_"&DD$4&"_"&$CM18,'Turkus Index'!$A:$D,4,FALSE)) -> 493 | DF18: =IF(ISERROR(VLOOKUP("Inbred HIPS_"&DF$4&"_"&$CM18,'Turkus Index'!$A:$D,4,FALSE)),"NA",VLOOKUP("Inbred HIPS_"&DF$4&"_"&$CM18,'Turkus Index'!$A:$D,4,FALSE)) -> 492 | DH18: =IF(ISERROR(VLOOKUP("Inbred HIPS_"&DH$4&"_"&$CM18,'Turkus Index'!$A:$D,4,FALSE)),"NA",VLOOKUP("Inbred HIPS_"&DH$4&"_"&$CM18,'Turkus Index'!$A:$D,4,FALSE)) -> 491 | DJ18: =IF(ISERROR(VLOOKUP("Inbred HIPS_"&DJ$4&"_"&$CM18,'Turkus Index'!$A:$D,4,FALSE)),"NA",VLOOKUP("Inbred HIPS_"&DJ$4&"_"&$CM18,'Turkus Index'!$A:$D,4,FALSE)) -> NA
B19: 29 | C19: NA | G19: NA | K19: NA | O19: NA | S19: NA | W19: NA | AA19: NA | AE19: NA | AI19: NA | AM19: NA | AQ19: NA | AU19: NA | AY19: NA | BC19: NA | BG19: NA | BK19: NA | BO19: NA | BS19: NA | BW19: NA | CA19: =CE19+1 -> 124 | CE19: =CE20+1 -> 123 | CM19: 71 | CN19: =IF(ISERROR(VLOOKUP("Inbred HIPS_"&CN$4&"_"&$CM19,'Turkus Index'!$A:$D,4,FALSE)),"NA",VLOOKUP("Inbred HIPS_"&CN$4&"_"&$CM19,'Turkus Index'!$A:$D,4,FALSE)) -> NA | CP19: =IF(ISERROR(VLOOKUP("Inbred HIPS_"&CP$4&"_"&$CM19,'Turkus Index'!$A:$D,4,FALSE)),"NA",VLOOKUP("Inbred HIPS_"&CP$4&"_"&$CM19,'Turkus Index'!$A:$D,4,FALSE)) -> 481 | CR19: =IF(ISERROR(VLOOKUP("Inbred HIPS_"&CR$4&"_"&$CM19,'Turkus Index'!$A:$D,4,FALSE)),"NA",VLOOKUP("Inbred HIPS_"&CR$4&"_"&$CM19,'Turkus Index'!$A:$D,4,FALSE)) -> 482 | CT19: =IF(ISERROR(VLOOKUP("Inbred HIPS_"&CT$4&"_"&$CM19,'Turkus Index'!$A:$D,4,FALSE)),"NA",VLOOKUP("Inbred HIPS_"&CT$4&"_"&$CM19,'Turkus Index'!$A:$D,4,FALSE)) -> 483 | CV19: =IF(ISERROR(VLOOKUP("Inbred HIPS_"&CV$4&"_"&$CM19,'Turkus Index'!$A:$D,4,FALSE)),"NA",VLOOKUP("Inbred HIPS_"&CV$4&"_"&$CM19,'Turkus Index'!$A:$D,4,FALSE)) -> 484 | CX19: =IF(ISERROR(VLOOKUP("Inbred HIPS_"&CX$4&"_"&$CM19,'Turkus Index'!$A:$D,4,FALSE)),"NA",VLOOKUP("Inbred HIPS_"&CX$4&"_"&$CM19,'Turkus Index'!$A:$D,4,FALSE)) -> 485 | CZ19: =IF(ISERROR(VLOOKUP("Inbred HIPS_"&CZ$4&"_"&$CM19,'Turkus Index'!$A:$D,4,FALSE)),"NA",VLOOKUP("Inbred HIPS_"&CZ$4&"_"&$CM19,'Turkus Index'!$A:$D,4,FALSE)) -> 486 | DB19: =IF(ISERROR(VLOOKUP("Inbred HIPS_"&DB$4&"_"&$CM19,'Turkus Index'!$A:$D,4,FALSE)),"NA",VLOOKUP("Inbred HIPS_"&DB$4&"_"&$CM19,'Turkus Index'!$A:$D,4,FALSE)) -> 487 | DD19: =IF(ISERROR(VLOOKUP("Inbred HIPS_"&DD$4&"_"&$CM19,'Turkus Index'!$A:$D,4,FALSE)),"NA",VLOOKUP("Inbred HIPS_"&DD$4&"_"&$CM19,'Turkus Index'!$A:$D,4,FALSE)) -> 488 | DF19: =IF(ISERROR(VLOOKUP("Inbred HIPS_"&DF$4&"_"&$CM19,'Turkus Index'!$A:$D,4,FALSE)),"NA",VLOOKUP("Inbred HIPS_"&DF$4&"_"&$CM19,'Turkus Index'!$A:$D,4,FALSE)) -> 489 | DH19: =IF(ISERROR(VLOOKUP("Inbred HIPS_"&DH$4&"_"&$CM19,'Turkus Index'!$A:$D,4,FALSE)),"NA",VLOOKUP("Inbred HIPS_"&DH$4&"_"&$CM19,'Turkus Index'!$A:$D,4,FALSE)) -> 490 | DJ19: =IF(ISERROR(VLOOKUP("Inbred HIPS_"&DJ$4&"_"&$CM19,'Turkus Index'!$A:$D,4,FALSE)),"NA",VLOOKUP("Inbred HIPS_"&DJ$4&"_"&$CM19,'Turkus Index'!$A:$D,4,FALSE)) -> NA
B20: 28 | C20: NA | G20: NA | K20: NA | O20: NA | S20: NA | W20: NA | AA20: NA | AE20: NA | AI20: NA | AM20: NA | AQ20: NA | AU20: NA | AY20: NA | BC20: NA | BG20: NA | BK20: NA | BO20: NA | BS20: NA | BW20: NA | CA20: =CA21+1 -> 121 | CE20: =CA20+1 -> 122 | CM20: 70 | CN20: =IF(ISERROR(VLOOKUP("Inbred HIPS_"&CN$4&"_"&$CM20,'Turkus Index'!$A:$D,4,FALSE)),"NA",VLOOKUP("Inbred HIPS_"&CN$4&"_"&$CM20,'Turkus Index'!$A:$D,4,FALSE)) -> NA | CP20: =IF(ISERROR(VLOOKUP("Inbred HIPS_"&CP$4&"_"&$CM20,'Turkus Index'!$A:$D,4,FALSE)),"NA",VLOOKUP("Inbred HIPS_"&CP$4&"_"&$CM20,'Turkus Index'!$A:$D,4,FALSE)) -> 480 | CR20: =IF(ISERROR(VLOOKUP("Inbred HIPS_"&CR$4&"_"&$CM20,'Turkus Index'!$A:$D,4,FALSE)),"NA",VLOOKUP("Inbred HIPS_"&CR$4&"_"&$CM20,'Turkus Index'!$A:$D,4,FALSE)) -> 479 | CT20: =IF(ISERROR(VLOOKUP("Inbred HIPS_"&CT$4&"_"&$CM20,'Turkus Index'!$A:$D,4,FALSE)),"NA",VLOOKUP("Inbred HIPS_"&CT$4&"_"&$CM20,'Turkus Index'!$A:$D,4,FALSE)) -> 478 | CV20: =IF(ISERROR(VLOOKUP("Inbred HIPS_"&CV$4&"_"&$CM20,'Turkus Index'!$A:$D,4,FALSE)),"NA",VLOOKUP("Inbred HIPS_"&CV$4&"_"&$CM20,'Turkus Index'!$A:$D,4,FALSE)) -> 477 | CX20: =IF(ISERROR(VLOOKUP("Inbred HIPS_"&CX$4&"_"&$CM20,'Turkus Index'!$A:$D,4,FALSE)),"NA",VLOOKUP("Inbred HIPS_"&CX$4&"_"&$CM20,'Turkus Index'!$A:$D,4,FALSE)) -> 476 | CZ20: =IF(ISERROR(VLOOKUP("Inbred HIPS_"&CZ$4&"_"&$CM20,'Turkus Index'!$A:$D,4,FALSE)),"NA",VLOOKUP("Inbred HIPS_"&CZ$4&"_"&$CM20,'Turkus Index'!$A:$D,4,FALSE)) -> 475 | DB20: =IF(ISERROR(VLOOKUP("Inbred HIPS_"&DB$4&"_"&$CM20,'Turkus Index'!$A:$D,4,FALSE)),"NA",VLOOKUP("Inbred HIPS_"&DB$4&"_"&$CM20,'Turkus Index'!$A:$D,4,FALSE)) -> 474 | DD20: =IF(ISERROR(VLOOKUP("Inbred HIPS_"&DD$4&"_"&$CM20,'Turkus Index'!$A:$D,4,FALSE)),"NA",VLOOKUP("Inbred HIPS_"&DD$4&"_"&$CM20,'Turkus Index'!$A:$D,4,FALSE)) -> 473 | DF20: =IF(ISERROR(VLOOKUP("Inbred HIPS_"&DF$4&"_"&$CM20,'Turkus Index'!$A:$D,4,FALSE)),"NA",VLOOKUP("Inbred HIPS_"&DF$4&"_"&$CM20,'Turkus Index'!$A:$D,4,FALSE)) -> 472 | DH20: =IF(ISERROR(VLOOKUP("Inbred HIPS_"&DH$4&"_"&$CM20,'Turkus Index'!$A:$D,4,FALSE)),"NA",VLOOKUP("Inbred HIPS_"&DH$4&"_"&$CM20,'Turkus Index'!$A:$D,4,FALSE)) -> 471 | DJ20: =IF(ISERROR(VLOOKUP("Inbred HIPS_"&DJ$4&"_"&$CM20,'Turkus Index'!$A:$D,4,FALSE)),"NA",VLOOKUP("Inbred HIPS_"&DJ$4&"_"&$CM20,'Turkus Index'!$A:$D,4,FALSE)) -> NA
B21: 27 | C21: NA | G21: NA | K21: NA | O21: NA | S21: NA | W21: NA | AA21: NA | AE21: NA | AI21: NA | AM21: NA | AQ21: NA | AU21: NA | AY21: NA | BC21: NA | BG21: NA | BK21: NA | BO21: NA | BS21: NA | BW21: NA | CA21: =CE21+1 -> 120 | CE21: =CE22+1 -> 119 | CM21: 69 | CN21: =IF(ISERROR(VLOOKUP("Inbred HIPS_"&CN$4&"_"&$CM21,'Turkus Index'!$A:$D,4,FALSE)),"NA",VLOOKUP("Inbred HIPS_"&CN$4&"_"&$CM21,'Turkus Index'!$A:$D,4,FALSE)) -> NA | CP21: =IF(ISERROR(VLOOKUP("Inbred HIPS_"&CP$4&"_"&$CM21,'Turkus Index'!$A:$D,4,FALSE)),"NA",VLOOKUP("Inbred HIPS_"&CP$4&"_"&$CM21,'Turkus Index'!$A:$D,4,FALSE)) -> 461 | CR21: =IF(ISERROR(VLOOKUP("Inbred HIPS_"&CR$4&"_"&$CM21,'Turkus Index'!$A:$D,4,FALSE)),"NA",VLOOKUP("Inbred HIPS_"&CR$4&"_"&$CM21,'Turkus Index'!$A:$D,4,FALSE)) -> 462 | CT21: =IF(ISERROR(VLOOKUP("Inbred HIPS_"&CT$4&"_"&$CM21,'Turkus Index'!$A:$D,4,FALSE)),"NA",VLOOKUP("Inbred HIPS_"&CT$4&"_"&$CM21,'Turkus Index'!$A:$D,4,FALSE)) -> 463 | CV21: =IF(ISERROR(VLOOKUP("Inbred HIPS_"&CV$4&"_"&$CM21,'Turkus Index'!$A:$D,4,FALSE)),"NA",VLOOKUP("Inbred HIPS_"&CV$4&"_"&$CM21,'Turkus Index'!$A:$D,4,FALSE)) -> 464 | CX21: =IF(ISERROR(VLOOKUP("Inbred HIPS_"&CX$4&"_"&$CM21,'Turkus Index'!$A:$D,4,FALSE)),"NA",VLOOKUP("Inbred HIPS_"&CX$4&"_"&$CM21,'Turkus Index'!$A:$D,4,FALSE)) -> 465 | CZ21: =IF(ISERROR(VLOOKUP("Inbred HIPS_"&CZ$4&"_"&$CM21,'Turkus Index'!$A:$D,4,FALSE)),"NA",VLOOKUP("Inbred HIPS_"&CZ$4&"_"&$CM21,'Turkus Index'!$A:$D,4,FALSE)) -> 466 | DB21: =IF(ISERROR(VLOOKUP("Inbred HIPS_"&DB$4&"_"&$CM21,'Turkus Index'!$A:$D,4,FALSE)),"NA",VLOOKUP("Inbred HIPS_"&DB$4&"_"&$CM21,'Turkus Index'!$A:$D,4,FALSE)) -> 467 | DD21: =IF(ISERROR(VLOOKUP("Inbred HIPS_"&DD$4&"_"&$CM21,'Turkus Index'!$A:$D,4,FALSE)),"NA",VLOOKUP("Inbred HIPS_"&DD$4&"_"&$CM21,'Turkus Index'!$A:$D,4,FALSE)) -> 468 | DF21: =IF(ISERROR(VLOOKUP("Inbred HIPS_"&DF$4&"_"&$CM21,'Turkus Index'!$A:$D,4,FALSE)),"NA",VLOOKUP("Inbred HIPS_"&DF$4&"_"&$CM21,'Turkus Index'!$A:$D,4,FALSE)) -> 469 | DH21: =IF(ISERROR(VLOOKUP("Inbred HIPS_"&DH$4&"_"&$CM21,'Turkus Index'!$A:$D,4,FALSE)),"NA",VLOOKUP("Inbred HIPS_"&DH$4&"_"&$CM21,'Turkus Index'!$A:$D,4,FALSE)) -> 470 | DJ21: =IF(ISERROR(VLOOKUP("Inbred HIPS_"&DJ$4&"_"&$CM21,'Turkus Index'!$A:$D,4,FALSE)),"NA",VLOOKUP("Inbred HIPS_"&DJ$4&"_"&$CM21,'Turkus Index'!$A:$D,4,FALSE)) -> NA
B22: 26 | C22: NA | G22: NA | K22: NA | O22: NA | S22: NA | W22: NA | AA22: NA | AE22: NA | AI22: NA | AM22: NA | AQ22: NA | AU22: NA | AY22: NA | BC22: NA | BG22: NA | BK22: NA | BO22: NA | BS22: NA | BW22: NA | CA22: =CA23+1 -> 117 | CE22: =CA22+1 -> 118 | CM22: 68 | CN22: =IF(ISERROR(VLOOKUP("Inbred HIPS_"&CN$4&"_"&$CM22,'Turkus Index'!$A:$D,4,FALSE)),"NA",VLOOKUP("Inbred HIPS_"&CN$4&"_"&$CM22,'Turkus Index'!$A:$D,4,FALSE)) -> NA | CP22: =IF(ISERROR(VLOOKUP("Inbred HIPS_"&CP$4&"_"&$CM22,'Turkus Index'!$A:$D,4,FALSE)),"NA",VLOOKUP("Inbred HIPS_"&CP$4&"_"&$CM22,'Turkus Index'!$A:$D,4,FALSE)) -> 460 | CR22: =IF(ISERROR(VLOOKUP("Inbred HIPS_"&CR$4&"_"&$CM22,'Turkus Index'!$A:$D,4,FALSE)),"NA",VLOOKUP("Inbred HIPS_"&CR$4&"_"&$CM22,'Turkus Index'!$A:$D,4,FALSE)) -> 459 | CT22: =IF(ISERROR(VLOOKUP("Inbred HIPS_"&CT$4&"_"&$CM22,'Turkus Index'!$A:$D,4,FALSE)),"NA",VLOOKUP("Inbred HIPS_"&CT$4&"_"&$CM22,'Turkus Index'!$A:$D,4,FALSE)) -> 458 | CV22: =IF(ISERROR(VLOOKUP("Inbred HIPS_"&CV$4&"_"&$CM22,'Turkus Index'!$A:$D,4,FALSE)),"NA",VLOOKUP("Inbred HIPS_"&CV$4&"_"&$CM22,'Turkus Index'!$A:$D,4,FALSE)) -> 457 | CX22: =IF(ISERROR(VLOOKUP("Inbred HIPS_"&CX$4&"_"&$CM22,'Turkus Index'!$A:$D,4,FALSE)),"NA",VLOOKUP("Inbred HIPS_"&CX$4&"_"&$CM22,'Turkus Index'!$A:$D,4,FALSE)) -> 456 | CZ22: =IF(ISERROR(VLOOKUP("Inbred HIPS_"&CZ$4&"_"&$CM22,'Turkus Index'!$A:$D,4,FALSE)),"NA",VLOOKUP("Inbred HIPS_"&CZ$4&"_"&$CM22,'Turkus Index'!$A:$D,4,FALSE)) -> 455 | DB22: =IF(ISERROR(VLOOKUP("Inbred HIPS_"&DB$4&"_"&$CM22,'Turkus Index'!$A:$D,4,FALSE)),"NA",VLOOKUP("Inbred HIPS_"&DB$4&"_"&$CM22,'Turkus Index'!$A:$D,4,FALSE)) -> 454 | DD22: =IF(ISERROR(VLOOKUP("Inbred HIPS_"&DD$4&"_"&$CM22,'Turkus Index'!$A:$D,4,FALSE)),"NA",VLOOKUP("Inbred HIPS_"&DD$4&"_"&$CM22,'Turkus Index'!$A:$D,4,FALSE)) -> 453 | DF22: =IF(ISERROR(VLOOKUP("Inbred HIPS_"&DF$4&"_"&$CM22,'Turkus Index'!$A:$D,4,FALSE)),"NA",VLOOKUP("Inbred HIPS_"&DF$4&"_"&$CM22,'Turkus Index'!$A:$D,4,FALSE)) -> 452 | DH22: =IF(ISERROR(VLOOKUP("Inbred HIPS_"&DH$4&"_"&$CM22,'Turkus Index'!$A:$D,4,FALSE)),"NA",VLOOKUP("Inbred HIPS_"&DH$4&"_"&$CM22,'Turkus Index'!$A:$D,4,FALSE)) -> 451 | DJ22: =IF(ISERROR(VLOOKUP("Inbred HIPS_"&DJ$4&"_"&$CM22,'Turkus Index'!$A:$D,4,FALSE)),"NA",VLOOKUP("Inbred HIPS_"&DJ$4&"_"&$CM22,'Turkus Index'!$A:$D,4,FALSE)) -> NA
B23: 25 | C23: NA | G23: NA | K23: NA | O23: NA | S23: NA | W23: NA | AA23: NA | AE23: NA | AI23: NA | AM23: NA | AQ23: NA | AU23: NA | AY23: NA | BC23: NA | BG23: NA | BK23: NA | BO23: NA | BS23: NA | BW23: NA | CA23: =CE23+1 -> 116 | CE23: =CE24+1 -> 115 | CM23: 67 | CN23: =IF(ISERROR(VLOOKUP("Inbred HIPS_"&CN$4&"_"&$CM23,'Turkus Index'!$A:$D,4,FALSE)),"NA",VLOOKUP("Inbred HIPS_"&CN$4&"_"&$CM23,'Turkus Index'!$A:$D,4,FALSE)) -> NA | CP23: =IF(ISERROR(VLOOKUP("Inbred HIPS_"&CP$4&"_"&$CM23,'Turkus Index'!$A:$D,4,FALSE)),"NA",VLOOKUP("Inbred HIPS_"&CP$4&"_"&$CM23,'Turkus Index'!$A:$D,4,FALSE)) -> 441 | CR23: =IF(ISERROR(VLOOKUP("Inbred HIPS_"&CR$4&"_"&$CM23,'Turkus Index'!$A:$D,4,FALSE)),"NA",VLOOKUP("Inbred HIPS_"&CR$4&"_"&$CM23,'Turkus Index'!$A:$D,4,FALSE)) -> 442 | CT23: =IF(ISERROR(VLOOKUP("Inbred HIPS_"&CT$4&"_"&$CM23,'Turkus Index'!$A:$D,4,FALSE)),"NA",VLOOKUP("Inbred HIPS_"&CT$4&"_"&$CM23,'Turkus Index'!$A:$D,4,FALSE)) -> 443 | CV23: =IF(ISERROR(VLOOKUP("Inbred HIPS_"&CV$4&"_"&$CM23,'Turkus Index'!$A:$D,4,FALSE)),"NA",VLOOKUP("Inbred HIPS_"&CV$4&"_"&$CM23,'Turkus Index'!$A:$D,4,FALSE)) -> 444 | CX23: =IF(ISERROR(VLOOKUP("Inbred HIPS_"&CX$4&"_"&$CM23,'Turkus Index'!$A:$D,4,FALSE)),"NA",VLOOKUP("Inbred HIPS_"&CX$4&"_"&$CM23,'Turkus Index'!$A:$D,4,FALSE)) -> 445 | CZ23: =IF(ISERROR(VLOOKUP("Inbred HIPS_"&CZ$4&"_"&$CM23,'Turkus Index'!$A:$D,4,FALSE)),"NA",VLOOKUP("Inbred HIPS_"&CZ$4&"_"&$CM23,'Turkus Index'!$A:$D,4,FALSE)) -> 446 | DB23: =IF(ISERROR(VLOOKUP("Inbred HIPS_"&DB$4&"_"&$CM23,'Turkus Index'!$A:$D,4,FALSE)),"NA",VLOOKUP("Inbred HIPS_"&DB$4&"_"&$CM23,'Turkus Index'!$A:$D,4,FALSE)) -> 447 | DD23: =IF(ISERROR(VLOOKUP("Inbred HIPS_"&DD$4&"_"&$CM23,'Turkus Index'!$A:$D,4,FALSE)),"NA",VLOOKUP("Inbred HIPS_"&DD$4&"_"&$CM23,'Turkus Index'!$A:$D,4,FALSE)) -> 448 | DF23: =IF(ISERROR(VLOOKUP("Inbred HIPS_"&DF$4&"_"&$CM23,'Turkus Index'!$A:$D,4,FALSE)),"NA",VLOOKUP("Inbred HIPS_"&DF$4&"_"&$CM23,'Turkus Index'!$A:$D,4,FALSE)) -> 449 | DH23: =IF(ISERROR(VLOOKUP("Inbred HIPS_"&DH$4&"_"&$CM23,'Turkus Index'!$A:$D,4,FALSE)),"NA",VLOOKUP("Inbred HIPS_"&DH$4&"_"&$CM23,'Turkus Index'!$A:$D,4,FALSE)) -> 450 | DJ23: =IF(ISERROR(VLOOKUP("Inbred HIPS_"&DJ$4&"_"&$CM23,'Turkus Index'!$A:$D,4,FALSE)),"NA",VLOOKUP("Inbred HIPS_"&DJ$4&"_"&$CM23,'Turkus Index'!$A:$D,4,FALSE)) -> NA
B24: 24 | C24: NA | G24: NA | K24: NA | O24: NA | S24: NA | W24: NA | AA24: NA | AE24: NA | AI24: NA | AM24: NA | AQ24: NA | AU24: NA | AY24: NA | BC24: NA | BG24: NA | BK24: NA | BO24: NA | BS24: NA | BW24: NA | CA24: =CA25+1 -> 113 | CE24: =CA24+1 -> 114 | CM24: 66 | CN24: =IF(ISERROR(VLOOKUP("Inbred HIPS_"&CN$4&"_"&$CM24,'Turkus Index'!$A:$D,4,FALSE)),"NA",VLOOKUP("Inbred HIPS_"&CN$4&"_"&$CM24,'Turkus Index'!$A:$D,4,FALSE)) -> NA | CP24: =IF(ISERROR(VLOOKUP("Inbred HIPS_"&CP$4&"_"&$CM24,'Turkus Index'!$A:$D,4,FALSE)),"NA",VLOOKUP("Inbred HIPS_"&CP$4&"_"&$CM24,'Turkus Index'!$A:$D,4,FALSE)) -> 440 | CR24: =IF(ISERROR(VLOOKUP("Inbred HIPS_"&CR$4&"_"&$CM24,'Turkus Index'!$A:$D,4,FALSE)),"NA",VLOOKUP("Inbred HIPS_"&CR$4&"_"&$CM24,'Turkus Index'!$A:$D,4,FALSE)) -> 439 | CT24: =IF(ISERROR(VLOOKUP("Inbred HIPS_"&CT$4&"_"&$CM24,'Turkus Index'!$A:$D,4,FALSE)),"NA",VLOOKUP("Inbred HIPS_"&CT$4&"_"&$CM24,'Turkus Index'!$A:$D,4,FALSE)) -> 438 | CV24: =IF(ISERROR(VLOOKUP("Inbred HIPS_"&CV$4&"_"&$CM24,'Turkus Index'!$A:$D,4,FALSE)),"NA",VLOOKUP("Inbred HIPS_"&CV$4&"_"&$CM24,'Turkus Index'!$A:$D,4,FALSE)) -> 437 | CX24: =IF(ISERROR(VLOOKUP("Inbred HIPS_"&CX$4&"_"&$CM24,'Turkus Index'!$A:$D,4,FALSE)),"NA",VLOOKUP("Inbred HIPS_"&CX$4&"_"&$CM24,'Turkus Index'!$A:$D,4,FALSE)) -> 436 | CZ24: =IF(ISERROR(VLOOKUP("Inbred HIPS_"&CZ$4&"_"&$CM24,'Turkus Index'!$A:$D,4,FALSE)),"NA",VLOOKUP("Inbred HIPS_"&CZ$4&"_"&$CM24,'Turkus Index'!$A:$D,4,FALSE)) -> 435 | DB24: =IF(ISERROR(VLOOKUP("Inbred HIPS_"&DB$4&"_"&$CM24,'Turkus Index'!$A:$D,4,FALSE)),"NA",VLOOKUP("Inbred HIPS_"&DB$4&"_"&$CM24,'Turkus Index'!$A:$D,4,FALSE)) -> 434 | DD24: =IF(ISERROR(VLOOKUP("Inbred HIPS_"&DD$4&"_"&$CM24,'Turkus Index'!$A:$D,4,FALSE)),"NA",VLOOKUP("Inbred HIPS_"&DD$4&"_"&$CM24,'Turkus Index'!$A:$D,4,FALSE)) -> 433 | DF24: =IF(ISERROR(VLOOKUP("Inbred HIPS_"&DF$4&"_"&$CM24,'Turkus Index'!$A:$D,4,FALSE)),"NA",VLOOKUP("Inbred HIPS_"&DF$4&"_"&$CM24,'Turkus Index'!$A:$D,4,FALSE)) -> 432 | DH24: =IF(ISERROR(VLOOKUP("Inbred HIPS_"&DH$4&"_"&$CM24,'Turkus Index'!$A:$D,4,FALSE)),"NA",VLOOKUP("Inbred HIPS_"&DH$4&"_"&$CM24,'Turkus Index'!$A:$D,4,FALSE)) -> 431 | DJ24: =IF(ISERROR(VLOOKUP("Inbred HIPS_"&DJ$4&"_"&$CM24,'Turkus Index'!$A:$D,4,FALSE)),"NA",VLOOKUP("Inbred HIPS_"&DJ$4&"_"&$CM24,'Turkus Index'!$A:$D,4,FALSE)) -> NA
B25: 23 | C25: NA | G25: NA | K25: NA | O25: NA | S25: NA | W25: NA | AA25: NA | AE25: NA | AI25: NA | AM25: NA | AQ25: NA | AU25: NA | AY25: NA | BC25: NA | BG25: NA | BK25: NA | BO25: NA | BS25: NA | BW25: NA | CA25: =CE25+1 -> 112 | CE25: =CE26+1 -> 111 | CM25: 65 | CN25: =IF(ISERROR(VLOOKUP("Inbred HIPS_"&CN$4&"_"&$CM25,'Turkus Index'!$A:$D,4,FALSE)),"NA",VLOOKUP("Inbred HIPS_"&CN$4&"_"&$CM25,'Turkus Index'!$A:$D,4,FALSE)) -> NA | CP25: =IF(ISERROR(VLOOKUP("Inbred HIPS_"&CP$4&"_"&$CM25,'Turkus Index'!$A:$D,4,FALSE)),"NA",VLOOKUP("Inbred HIPS_"&CP$4&"_"&$CM25,'Turkus Index'!$A:$D,4,FALSE)) -> 421 | CR25: =IF(ISERROR(VLOOKUP("Inbred HIPS_"&CR$4&"_"&$CM25,'Turkus Index'!$A:$D,4,FALSE)),"NA",VLOOKUP("Inbred HIPS_"&CR$4&"_"&$CM25,'Turkus Index'!$A:$D,4,FALSE)) -> 422 | CT25: =IF(ISERROR(VLOOKUP("Inbred HIPS_"&CT$4&"_"&$CM25,'Turkus Index'!$A:$D,4,FALSE)),"NA",VLOOKUP("Inbred HIPS_"&CT$4&"_"&$CM25,'Turkus Index'!$A:$D,4,FALSE)) -> 423 | CV25: =IF(ISERROR(VLOOKUP("Inbred HIPS_"&CV$4&"_"&$CM25,'Turkus Index'!$A:$D,4,FALSE)),"NA",VLOOKUP("Inbred HIPS_"&CV$4&"_"&$CM25,'Turkus Index'!$A:$D,4,FALSE)) -> 424 | CX25: =IF(ISERROR(VLOOKUP("Inbred HIPS_"&CX$4&"_"&$CM25,'Turkus Index'!$A:$D,4,FALSE)),"NA",VLOOKUP("Inbred HIPS_"&CX$4&"_"&$CM25,'Turkus Index'!$A:$D,4,FALSE)) -> 425 | CZ25: =IF(ISERROR(VLOOKUP("Inbred HIPS_"&CZ$4&"_"&$CM25,'Turkus Index'!$A:$D,4,FALSE)),"NA",VLOOKUP("Inbred HIPS_"&CZ$4&"_"&$CM25,'Turkus Index'!$A:$D,4,FALSE)) -> 426 | DB25: =IF(ISERROR(VLOOKUP("Inbred HIPS_"&DB$4&"_"&$CM25,'Turkus Index'!$A:$D,4,FALSE)),"NA",VLOOKUP("Inbred HIPS_"&DB$4&"_"&$CM25,'Turkus Index'!$A:$D,4,FALSE)) -> 427 | DD25: =IF(ISERROR(VLOOKUP("Inbred HIPS_"&DD$4&"_"&$CM25,'Turkus Index'!$A:$D,4,FALSE)),"NA",VLOOKUP("Inbred HIPS_"&DD$4&"_"&$CM25,'Turkus Index'!$A:$D,4,FALSE)) -> 428 | DF25: =IF(ISERROR(VLOOKUP("Inbred HIPS_"&DF$4&"_"&$CM25,'Turkus Index'!$A:$D,4,FALSE)),"NA",VLOOKUP("Inbred HIPS_"&DF$4&"_"&$CM25,'Turkus Index'!$A:$D,4,FALSE)) -> 429 | DH25: =IF(ISERROR(VLOOKUP("Inbred HIPS_"&DH$4&"_"&$CM25,'Turkus Index'!$A:$D,4,FALSE)),"NA",VLOOKUP("Inbred HIPS_"&DH$4&"_"&$CM25,'Turkus Index'!$A:$D,4,FALSE)) -> 430 | DJ25: =IF(ISERROR(VLOOKUP("Inbred HIPS_"&DJ$4&"_"&$CM25,'Turkus Index'!$A:$D,4,FALSE)),"NA",VLOOKUP("Inbred HIPS_"&DJ$4&"_"&$CM25,'Turkus Index'!$A:$D,4,FALSE)) -> NA
B26: 22 | C26: NA | G26: NA | K26: NA | O26: NA | S26: NA | W26: NA | AA26: NA | AE26: NA | AI26: NA | AM26: NA | AQ26: NA | AU26: NA | AY26: NA | BC26: NA | BG26: NA | BK26: NA | BO26: NA | BS26: NA | BW26: NA | CA26: =CA27+1 -> 109 | CE26: =CA26+1 -> 110 | CM26: 64 | CN26: =IF(ISERROR(VLOOKUP("Inbred HIPS_"&CN$4&"_"&$CM26,'Turkus Index'!$A:$D,4,FALSE)),"NA",VLOOKUP("Inbred HIPS_"&CN$4&"_"&$CM26,'Turkus Index'!$A:$D,4,FALSE)) -> NA | CP26: =IF(ISERROR(VLOOKUP("Inbred HIPS_"&CP$4&"_"&$CM26,'Turkus Index'!$A:$D,4,FALSE)),"NA",VLOOKUP("Inbred HIPS_"&CP$4&"_"&$CM26,'Turkus Index'!$A:$D,4,FALSE)) -> 420 | CR26: =IF(ISERROR(VLOOKUP("Inbred HIPS_"&CR$4&"_"&$CM26,'Turkus Index'!$A:$D,4,FALSE)),"NA",VLOOKUP("Inbred HIPS_"&CR$4&"_"&$CM26,'Turkus Index'!$A:$D,4,FALSE)) -> 419 | CT26: =IF(ISERROR(VLOOKUP("Inbred HIPS_"&CT$4&"_"&$CM26,'Turkus Index'!$A:$D,4,FALSE)),"NA",VLOOKUP("Inbred HIPS_"&CT$4&"_"&$CM26,'Turkus Index'!$A:$D,4,FALSE)) -> 418 | CV26: =IF(ISERROR(VLOOKUP("Inbred HIPS_"&CV$4&"_"&$CM26,'Turkus Index'!$A:$D,4,FALSE)),"NA",VLOOKUP("Inbred HIPS_"&CV$4&"_"&$CM26,'Turkus Index'!$A:$D,4,FALSE)) -> 417 | CX26: =IF(ISERROR(VLOOKUP("Inbred HIPS_"&CX$4&"_"&$CM26,'Turkus Index'!$A:$D,4,FALSE)),"NA",VLOOKUP("Inbred HIPS_"&CX$4&"_"&$CM26,'Turkus Index'!$A:$D,4,FALSE)) -> 416 | CZ26: =IF(ISERROR(VLOOKUP("Inbred HIPS_"&CZ$4&"_"&$CM26,'Turkus Index'!$A:$D,4,FALSE)),"NA",VLOOKUP("Inbred HIPS_"&CZ$4&"_"&$CM26,'Turkus Index'!$A:$D,4,FALSE)) -> 415 | DB26: =IF(ISERROR(VLOOKUP("Inbred HIPS_"&DB$4&"_"&$CM26,'Turkus Index'!$A:$D,4,FALSE)),"NA",VLOOKUP("Inbred HIPS_"&DB$4&"_"&$CM26,'Turkus Index'!$A:$D,4,FALSE)) -> 414 | DD26: =IF(ISERROR(VLOOKUP("Inbred HIPS_"&DD$4&"_"&$CM26,'Turkus Index'!$A:$D,4,FALSE)),"NA",VLOOKUP("Inbred HIPS_"&DD$4&"_"&$CM26,'Turkus Index'!$A:$D,4,FALSE)) -> 413 | DF26: =IF(ISERROR(VLOOKUP("Inbred HIPS_"&DF$4&"_"&$CM26,'Turkus Index'!$A:$D,4,FALSE)),"NA",VLOOKUP("Inbred HIPS_"&DF$4&"_"&$CM26,'Turkus Index'!$A:$D,4,FALSE)) -> 412 | DH26: =IF(ISERROR(VLOOKUP("Inbred HIPS_"&DH$4&"_"&$CM26,'Turkus Index'!$A:$D,4,FALSE)),"NA",VLOOKUP("Inbred HIPS_"&DH$4&"_"&$CM26,'Turkus Index'!$A:$D,4,FALSE)) -> 411 | DJ26: =IF(ISERROR(VLOOKUP("Inbred HIPS_"&DJ$4&"_"&$CM26,'Turkus Index'!$A:$D,4,FALSE)),"NA",VLOOKUP("Inbred HIPS_"&DJ$4&"_"&$CM26,'Turkus Index'!$A:$D,4,FALSE)) -> NA
