Workbook

Sheet ReadMe
A1: About this Document
B2: This is the summary file for the Inbred HIPS 2023 - Lincoln
A10: Sheet | B10: Description
A11: Metadata
B12: Info about the field
A15: Field Layout
B16: Visual representation of the field
B18: Two types of maps are present:
C19: Layout (Unit is Plot)
D20: The fundamental unit in this map is the plot
C22: Layout (Unit is Field Row)
D23: The fundamental unit in this map is a single 10 foot row
A25: Index
B26: This is the index based on the the "Layout (Unit is Plot)" layout
B28: Genotype and PI information is based on what was provided by Lisa Coffey from ISU in the document:
C29: Lisa Coffey 2023 Inbred HIPS field book.xlsx

Sheet Metadata
I1: Pesticide application schedule
A2: Field Width (E-W) | B2: 170 feet | J2: Date | K2: Type of Product | L2: Purpose | M2: Components | N2: Component Ratio
A3: Field Length (N-S) | B3: 270 feet | J3: 45036 | K3: Herbicides | L3: Pre-planting control of weeds | M3: Acuron + Roundup + Choice | N3: 4 gal + 2.5 gal + .25 gal
A4: # of Experimental Plots | B4: 800 | J4: 45070 | K4: Herbicides | L4: Control of weeds | M4: Acuron + Choice | N4: 4 gal + .25 gal
A5: # of Border Plots | B5: 118
A6: Plot Width (E-W) | B6: 5 feet
A7: Plot Length (N-S) (center to center) | B7: 10 feet
A8: Pre-Planting Nitrogen Application Date | B8: 45021
A9: Nitrogen Application Level | B9: 150lbs N/acre
A10: Type of Fertilizer | B10: Liquid urea
A11: Planting density | B11: six inches between seeds
A12: Border Genotype | B12: Pioneer P1237AM
A13: Genotype in Filler in plots 1397-1400, 2397-2400 | B13: Pioneer P1185AM
A14: Planting date | B14: 45055 | C14: Planted between 9am and 11:30am
A15: Hand Harvest date | B15: 45199

Sheet Field Layout
A1: Layout (Unit is Plot) | K1: North | AI1: 29 | AQ1: Layout (Unit is Field Row) | BY1: North
C3: 1001 | D3: = 5' wide (row) x 10' long (range) 2 row plot | AS3: 2016-1 | AT3: = 2.5' wide (1 row) x 10' long (range) 1 row for a 2 row plot
C4: Row
AR5: Excel column | AS5: C | AT5: C | AU5: D | AV5: D | AW5: E | AX5: E | AY5: F | AZ5: F | BA5: G | BB5: G | BC5: H | BD5: H | BE5: I | BF5: I | BG5: J | BH5: J | BI5: K | BJ5: K | BK5: L | BL5: L | BM5: M | BN5: M | BO5: N | BP5: N | BQ5: O | BR5: O | BS5: P | BT5: P | BU5: Q | BV5: Q | BW5: R | BX5: R | BY5: S | BZ5: S | CA5: T | CB5: T | CC5: U | CD5: U | CE5: V | CF5: V | CG5: W | CH5: W | CI5: X | CJ5: X | CK5: Y | CL5: Y | CM5: Z | CN5: Z | CO5: AA | CP5: AA | CQ5: AB | CR5: AB | CS5: AC | CT5: AC | CU5: AD | CV5: AD | CW5: AE | CX5: AE | CY5: AF | CZ5: AF | DA5: AG | DB5: AG | DC5: AH | DD5: AH | DE5: AI | DF5: AI | DG5: AJ | DH5: AJ
AR6: Excel Row | AS6: 9 | AT6: 9 | AU6: 9 | AV6: 9 | AW6: 9 | AX6: 9 | AY6: 9 | AZ6: 9 | BA6: 9 | BB6: 9 | BC6: 9 | BD6: 9 | BE6: 9 | BF6: 9 | BG6: 9 | BH6: 9 | BI6: 9 | BJ6: 9 | BK6: 9 | BL6: 9 | BM6: 9 | BN6: 9 | BO6: 9 | BP6: 9 | BQ6: 9 | BR6: 9 | BS6: 9 | BT6: 9 | BU6: 9 | BV6: 9 | BW6: 9 | BX6: 9 | BY6: 9 | BZ6: 9 | CA6: 9 | CB6: 9 | CC6: 9 | CD6: 9 | CE6: 9 | CF6: 9 | CG6: 9 | CH6: 9 | CI6: 9 | CJ6: 9 | CK6: 9 | CL6: 9 | CM6: 9 | CN6: 9 | CO6: 9 | CP6: 9 | CQ6: 9 | CR6: 9 | CS6: 9 | CT6: 9 | CU6: 9 | CV6: 9 | CW6: 9 | CX6: 9 | CY6: 9 | CZ6: 9 | DA6: 9 | DB6: 9 | DC6: 9 | DD6: 9 | DE6: 9 | DF6: 9 | DG6: 9 | DH6: 9
A7: Inbred HIPS | AR7: Plot Row | AS7: 34 | AU7: 33 | AW7: 32 | AY7: 31 | BA7: 30 | BC7: 29 | BE7: 28 | BG7: 27 | BI7: 26 | BK7: 25 | BM7: 24 | BO7: 23 | BQ7: 22 | BS7: 21 | BU7: 20 | BW7: 19 | BY7: 18 | CA7: 17 | CC7: 16 | CE7: 15 | CG7: 14 | CI7: 13 | CK7: 12 | CM7: 11 | CO7: 10 | CQ7: 9 | CS7: 8 | CU7: 7 | CW7: 6 | CY7: 5 | DA7: 4 | DC7: 3 | DE7: 2 | DG7: 1
C8: 34 | D8: 33 | E8: 32 | F8: 31 | G8: 30 | H8: 29 | I8: 28 | J8: 27 | K8: 26 | L8: 25 | M8: 24 | N8: 23 | O8: 22 | P8: 21 | Q8: 20 | R8: 19 | S8: 18 | T8: 17 | U8: 16 | V8: 15 | W8: 14 | X8: 13 | Y8: 12 | Z8: 11 | AA8: 10 | AB8: 9 | AC8: 8 | AD8: 7 | AE8: 6 | AF8: 5 | AG8: 4 | AH8: 3 | AI8: 2 | AJ8: 1 | AR8: Field Row | AS8: 68 | AT8: 67 | AU8: 66 | AV8: 65 | AW8: 64 | AX8: 63 | AY8: 62 | AZ8: 61 | BA8: 60 | BB8: 59 | BC8: 58 | BD8: 57 | BE8: 56 | BF8: 55 | BG8: 54 | BH8: 53 | BI8: 52 | BJ8: 51 | BK8: 50 | BL8: 49 | BM8: 48 | BN8: 47 | BO8: 46 | BP8: 45 | BQ8: 44 | BR8: 43 | BS8: 42 | BT8: 41 | BU8: 40 | BV8: 39 | BW8: 38 | BX8: 37 | BY8: 36 | BZ8: 35 | CA8: 34 | CB8: 33 | CC8: 32 | CD8: 31 | CE8: 30 | CF8: 29 | CG8: 28 | CH8: 27 | CI8: 26 | CJ8: 25 | CK8: 24 | CL8: 23 | CM8: 22 | CN8: 21 | CO8: 20 | CP8: 19 | CQ8: 18 | CR8: 17 | CS8: 16 | CT8: 15 | CU8: 14 | CV8: 13 | CW8: 12 | CX8: 11 | CY8: 10 | CZ8: 9 | DA8: 8 | DB8: 7 | DC8: 6 | DD8: 5 | DE8: 4 | DF8: 3 | DG8: 2 | DH8: 1
A9: Range | B9: 1 | C9: Border | D9: Border | E9: Border | F9: Border | G9: Border | H9: Border | I9: Border | J9: Border | K9: Border | L9: Border | M9: Border | N9: Border | O9: Border | P9: Border | Q9: Border | R9: Border | S9: Border | T9: Border | U9: Border | V9: Border | W9: Border | X9: Border | Y9: Border | Z9: Border | AA9: Border | AB9: Border | AC9: Border | AD9: Border | AE9: Border | AF9: Border | AG9: Border | AH9: Border | AI9: Border | AJ9: Border | AQ9: Range | AR9: 1 | AS9: {=INDIRECT(AS$5&$AR9+8)} -> Border | AT9: {=INDIRECT(AT$5&$AR9+8)} -> Border | AU9: {=INDIRECT(AU$5&$AR9+8)} -> Border | AV9: {=INDIRECT(AV$5&$AR9+8)} -> Border | AW9: {=INDIRECT(AW$5&$AR9+8)} -> Border | AX9: {=INDIRECT(AX$5&$AR9+8)} -> Border | AY9: {=INDIRECT(AY$5&$AR9+8)} -> Border | AZ9: {=INDIRECT(AZ$5&$AR9+8)} -> Border | ... DH9: {=INDIRECT(DH$5&$AR9+8)} -> Border
B10: 2 | C10: Border | D10: =E10+1 -> 2016 | E10: =F10+1 -> 2015 | F10: =G10+1 -> 2014 | G10: =H10+1 -> 2013 | H10: =I10+1 -> 2012 | I10: =J10+1 -> 2011 | J10: =K10+1 -> 2010 | K10: =L10+1 -> 2009 | ... R10: =S10+1 -> 2002 | S10: 2001 | T10: =U10+1 -> 1016 | U10: =V10+1 -> 1015 | V10: =W10+1 -> 1014 | W10: =X10+1 -> 1013 | X10: =Y10+1 -> 1012 | Y10: =Z10+1 -> 1011 | Z10: =AA10+1 -> 1010 | AA10: =AB10+1 -> 1009 | ... AH10: =AI10+1 -> 1002 | AI10: 1001 | AJ10: Border | AR10: 2 | AS10: {=INDIRECT(AS$5&$AR10+8)} -> Border | AT10: {=INDIRECT(AT$5&$AR10+8)} -> Border | AU10: {=INDIRECT(AU$5&$AR10+8)&"-"&1} -> 2016-1 | AV10: {=INDIRECT(AV$5&$AR10+8)&"-"&2} -> 2016-2 | AW10: {=INDIRECT(AW$5&$AR10+8)&"-"&1} -> 2015-1 | AX10: {=INDIRECT(AX$5&$AR10+8)&"-"&2} -> 2015-2 | AY10: {=INDIRECT(AY$5&$AR10+8)&"-"&1} -> 2014-1 | AZ10: {=INDIRECT(AZ$5&$AR10+8)&"-"&2} -> 2014-2 | BA10: {=INDIRECT(BA$5&$AR10+8)&"-"&1} -> 2013-1 | BB10: {=INDIRECT(BB$5&$AR10+8)&"-"&2} -> 2013-2 | BC10: {=INDIRECT(BC$5&$AR10+8)&"-"&1} -> 2012-1 | BD10: {=INDIRECT(BD$5&$AR10+8)&"-"&2} -> 2012-2 | BE10: {=INDIRECT(BE$5&$AR10+8)&"-"&1} -> 2011-1 | BF10: {=INDIRECT(BF$5&$AR10+8)&"-"&2} -> 2011-2 | BG10: {=INDIRECT(BG$5&$AR10+8)&"-"&1} -> 2010-1 | BH10: {=INDIRECT(BH$5&$AR10+8)&"-"&2} -> 2010-2 | BI10: {=INDIRECT(BI$5&$AR10+8)&"-"&1} -> 2009-1 | BJ10: {=INDIRECT(BJ$5&$AR10+8)&"-"&2} -> 2009-2 | BK10: {=INDIRECT(BK$5&$AR10+8)&"-"&1} -> 2008-1 | BL10: {=INDIRECT(BL$5&$AR10+8)&"-"&2} -> 2008-2 | BM10: {=INDIRECT(BM$5&$AR10+8)&"-"&1} -> 2007-1 | BN10: {=INDIRECT(BN$5&$AR10+8)&"-"&2} -> 2007-2 | BO10: {=INDIRECT(BO$5&$AR10+8)&"-"&1} -> 2006-1 | BP10: {=INDIRECT(BP$5&$AR10+8)&"-"&2} -> 2006-2 | BQ10: {=INDIRECT(BQ$5&$AR10+8)&"-"&1} -> 2005-1 | BR10: {=INDIRECT(BR$5&$AR10+8)&"-"&2} -> 2005-2 | BS10: {=INDIRECT(BS$5&$AR10+8)&"-"&1} -> 2004-1 | BT10: {=INDIRECT(BT$5&$AR10+8)&"-"&2} -> 2004-2 | BU10: {=INDIRECT(BU$5&$AR10+8)&"-"&1} -> 2003-1 | BV10: {=INDIRECT(BV$5&$AR10+8)&"-"&2} -> 2003-2 | BW10: {=INDIRECT(BW$5&$AR10+8)&"-"&1} -> 2002-1 | BX10: {=INDIRECT(BX$5&$AR10+8)&"-"&2} -> 2002-2 | BY10: {=INDIRECT(BY$5&$AR10+8)&"-"&1} -> 2001-1 | BZ10: {=INDIRECT(BZ$5&$AR10+8)&"-"&2} -> 2001-2 | CA10: {=INDIRECT(CA$5&$AR10+8)&"-"&1} -> 1016-1 | CB10: {=INDIRECT(CB$5&$AR10+8)&"-"&2} -> 1016-2 | CC10: {=INDIRECT(CC$5&$AR10+8)&"-"&1} -> 1015-1 | CD10: {=INDIRECT(CD$5&$AR10+8)&"-"&2} -> 1015-2 | CE10: {=INDIRECT(CE$5&$AR10+8)&"-"&1} -> 1014-1 | CF10: {=INDIRECT(CF$5&$AR10+8)&"-"&2} -> 1014-2 | CG10: {=INDIRECT(CG$5&$AR10+8)&"-"&1} -> 1013-1 | CH10: {=INDIRECT(CH$5&$AR10+8)&"-"&2} -> 1013-2 | CI10: {=INDIRECT(CI$5&$AR10+8)&"-"&1} -> 1012-1 | CJ10: {=INDIRECT(CJ$5&$AR10+8)&"-"&2} -> 1012-2 | CK10: {=INDIRECT(CK$5&$AR10+8)&"-"&1} -> 1011-1 | CL10: {=INDIRECT(CL$5&$AR10+8)&"-"&2} -> 1011-2 | CM10: {=INDIRECT(CM$5&$AR10+8)&"-"&1} -> 1010-1 | CN10: {=INDIRECT(CN$5&$AR10+8)&"-"&2} -> 1010-2 | CO10: {=INDIRECT(CO$5&$AR10+8)&"-"&1} -> 1009-1 | CP10: {=INDIRECT(CP$5&$AR10+8)&"-"&2} -> 1009-2 | CQ10: {=INDIRECT(CQ$5&$AR10+8)&"-"&1} -> 1008-1 | CR10: {=INDIRECT(CR$5&$AR10+8)&"-"&2} -> 1008-2 | CS10: {=INDIRECT(CS$5&$AR10+8)&"-"&1} -> 1007-1 | CT10: {=INDIRECT(CT$5&$AR10+8)&"-"&2} -> 1007-2 | CU10: {=INDIRECT(CU$5&$AR10+8)&"-"&1} -> 1006-1 | CV10: {=INDIRECT(CV$5&$AR10+8)&"-"&2} -> 1006-2 | CW10: {=INDIRECT(CW$5&$AR10+8)&"-"&1} -> 1005-1 | CX10: {=INDIRECT(CX$5&$AR10+8)&"-"&2} -> 1005-2 | CY10: {=INDIRECT(CY$5&$AR10+8)&"-"&1} -> 1004-1 | CZ10: {=INDIRECT(CZ$5&$AR10+8)&"-"&2} -> 1004-2 | DA10: {=INDIRECT(DA$5&$AR10+8)&"-"&1} -> 1003-1 | DB10: {=INDIRECT(DB$5&$AR10+8)&"-"&2} -> 1003-2 | DC10: {=INDIRECT(DC$5&$AR10+8)&"-"&1} -> 1002-1 | DD10: {=INDIRECT(DD$5&$AR10+8)&"-"&2} -> 1002-2 | DE10: {=INDIRECT(DE$5&$AR10+8)&"-"&1} -> 1001-1 | DF10: {=INDIRECT(DF$5&$AR10+8)&"-"&2} -> 1001-2 | DG10: {=INDIRECT(DG$5&$AR10+8)} -> Border | DH10: {=INDIRECT(DH$5&$AR10+8)} -> Border
B11: 3 | C11: Border | D11: =E11+1 -> 2032 | E11: =F11+1 -> 2031 | F11: =G11+1 -> 2030 | G11: =H11+1 -> 2029 | H11: =I11+1 -> 2028 | I11: =J11+1 -> 2027 | J11: =K11+1 -> 2026 | K11: =L11+1 -> 2025 | ... R11: =S11+1 -> 2018 | S11: {=D10+1} -> 2017 | T11: =U11+1 -> 1032 | U11: =V11+1 -> 1031 | V11: =W11+1 -> 1030 | W11: =X11+1 -> 1029 | X11: =Y11+1 -> 1028 | Y11: =Z11+1 -> 1027 | Z11: =AA11+1 -> 1026 | AA11: =AB11+1 -> 1025 | ... AH11: =AI11+1 -> 1018 | AI11: =T10+1 -> 1017 | AJ11: Border | AR11: 3 | AS11: {=INDIRECT(AS$5&$AR11+8)} -> Border | AT11: {=INDIRECT(AT$5&$AR11+8)} -> Border | AU11: {=INDIRECT(AU$5&$AR11+8)&"-"&1} -> 2032-1 | AV11: {=INDIRECT(AV$5&$AR11+8)&"-"&2} -> 2032-2 | AW11: {=INDIRECT(AW$5&$AR11+8)&"-"&1} -> 2031-1 | AX11: {=INDIRECT(AX$5&$AR11+8)&"-"&2} -> 2031-2 | AY11: {=INDIRECT(AY$5&$AR11+8)&"-"&1} -> 2030-1 | AZ11: {=INDIRECT(AZ$5&$AR11+8)&"-"&2} -> 2030-2 | BA11: {=INDIRECT(BA$5&$AR11+8)&"-"&1} -> 2029-1 | BB11: {=INDIRECT(BB$5&$AR11+8)&"-"&2} -> 2029-2 | BC11: {=INDIRECT(BC$5&$AR11+8)&"-"&1} -> 2028-1 | BD11: {=INDIRECT(BD$5&$AR11+8)&"-"&2} -> 2028-2 | BE11: {=INDIRECT(BE$5&$AR11+8)&"-"&1} -> 2027-1 | BF11: {=INDIRECT(BF$5&$AR11+8)&"-"&2} -> 2027-2 | BG11: {=INDIRECT(BG$5&$AR11+8)&"-"&1} -> 2026-1 | BH11: {=INDIRECT(BH$5&$AR11+8)&"-"&2} -> 2026-2 | BI11: {=INDIRECT(BI$5&$AR11+8)&"-"&1} -> 2025-1 | BJ11: {=INDIRECT(BJ$5&$AR11+8)&"-"&2} -> 2025-2 | BK11: {=INDIRECT(BK$5&$AR11+8)&"-"&1} -> 2024-1 | BL11: {=INDIRECT(BL$5&$AR11+8)&"-"&2} -> 2024-2 | BM11: {=INDIRECT(BM$5&$AR11+8)&"-"&1} -> 2023-1 | BN11: {=INDIRECT(BN$5&$AR11+8)&"-"&2} -> 2023-2 | BO11: {=INDIRECT(BO$5&$AR11+8)&"-"&1} -> 2022-1 | BP11: {=INDIRECT(BP$5&$AR11+8)&"-"&2} -> 2022-2 | BQ11: {=INDIRECT(BQ$5&$AR11+8)&"-"&1} -> 2021-1 | BR11: {=INDIRECT(BR$5&$AR11+8)&"-"&2} -> 2021-2 | BS11: {=INDIRECT(BS$5&$AR11+8)&"-"&1} -> 2020-1 | BT11: {=INDIRECT(BT$5&$AR11+8)&"-"&2} -> 2020-2 | BU11: {=INDIRECT(BU$5&$AR11+8)&"-"&1} -> 2019-1 | BV11: {=INDIRECT(BV$5&$AR11+8)&"-"&2} -> 2019-2 | BW11: {=INDIRECT(BW$5&$AR11+8)&"-"&1} -> 2018-1 | BX11: {=INDIRECT(BX$5&$AR11+8)&"-"&2} -> 2018-2 | BY11: {=INDIRECT(BY$5&$AR11+8)&"-"&1} -> 2017-1 | BZ11: {=INDIRECT(BZ$5&$AR11+8)&"-"&2} -> 2017-2 | CA11: {=INDIRECT(CA$5&$AR11+8)&"-"&1} -> 1032-1 | CB11: {=INDIRECT(CB$5&$AR11+8)&"-"&2} -> 1032-2 | CC11: {=INDIRECT(CC$5&$AR11+8)&"-"&1} -> 1031-1 | CD11: {=INDIRECT(CD$5&$AR11+8)&"-"&2} -> 1031-2 | CE11: {=INDIRECT(CE$5&$AR11+8)&"-"&1} -> 1030-1 | CF11: {=INDIRECT(CF$5&$AR11+8)&"-"&2} -> 1030-2 | CG11: {=INDIRECT(CG$5&$AR11+8)&"-"&1} -> 1029-1 | CH11: {=INDIRECT(CH$5&$AR11+8)&"-"&2} -> 1029-2 | CI11: {=INDIRECT(CI$5&$AR11+8)&"-"&1} -> 1028-1 | CJ11: {=INDIRECT(CJ$5&$AR11+8)&"-"&2} -> 1028-2 | CK11: {=INDIRECT(CK$5&$AR11+8)&"-"&1} -> 1027-1 | CL11: {=INDIRECT(CL$5&$AR11+8)&"-"&2} -> 1027-2 | CM11: {=INDIRECT(CM$5&$AR11+8)&"-"&1} -> 1026-1 | CN11: {=INDIRECT(CN$5&$AR11+8)&"-"&2} -> 1026-2 | CO11: {=INDIRECT(CO$5&$AR11+8)&"-"&1} -> 1025-1 | CP11: {=INDIRECT(CP$5&$AR11+8)&"-"&2} -> 1025-2 | CQ11: {=INDIRECT(CQ$5&$AR11+8)&"-"&1} -> 1024-1 | CR11: {=INDIRECT(CR$5&$AR11+8)&"-"&2} -> 1024-2 | CS11: {=INDIRECT(CS$5&$AR11+8)&"-"&1} -> 1023-1 | CT11: {=INDIRECT(CT$5&$AR11+8)&"-"&2} -> 1023-2 | CU11: {=INDIRECT(CU$5&$AR11+8)&"-"&1} -> 1022-1 | CV11: {=INDIRECT(CV$5&$AR11+8)&"-"&2} -> 1022-2 | CW11: {=INDIRECT(CW$5&$AR11+8)&"-"&1} -> 1021-1 | CX11: {=INDIRECT(CX$5&$AR11+8)&"-"&2} -> 1021-2 | CY11: {=INDIRECT(CY$5&$AR11+8)&"-"&1} -> 1020-1 | CZ11: {=INDIRECT(CZ$5&$AR11+8)&"-"&2} -> 1020-2 | DA11: {=INDIRECT(DA$5&$AR11+8)&"-"&1} -> 1019-1 | DB11: {=INDIRECT(DB$5&$AR11+8)&"-"&2} -> 1019-2 | DC11: {=INDIRECT(DC$5&$AR11+8)&"-"&1} -> 1018-1 | DD11: {=INDIRECT(DD$5&$AR11+8)&"-"&2} -> 1018-2 | DE11: {=INDIRECT(DE$5&$AR11+8)&"-"&1} -> 1017-1 | DF11: {=INDIRECT(DF$5&$AR11+8)&"-"&2} -> 1017-2 | DG11: {=INDIRECT(DG$5&$AR11+8)} -> Border | DH11: {=INDIRECT(DH$5&$AR11+8)} -> Border
B12: 4 | C12: Border | D12: =E12+1 -> 2048 | E12: =F12+1 -> 2047 | F12: =G12+1 -> 2046 | G12: =H12+1 -> 2045 | H12: =I12+1 -> 2044 | I12: =J12+1 -> 2043 | J12: =K12+1 -> 2042 | K12: =L12+1 -> 2041 | ... R12: =S12+1 -> 2034 | S12: {=D11+1} -> 2033 | T12: =U12+1 -> 1048 | U12: =V12+1 -> 1047 | V12: =W12+1 -> 1046 | W12: =X12+1 -> 1045 | X12: =Y12+1 -> 1044 | Y12: =Z12+1 -> 1043 | Z12: =AA12+1 -> 1042 | AA12: =AB12+1 -> 1041 | ... AH12: =AI12+1 -> 1034 | AI12: =T11+1 -> 1033 | AJ12: Border | AR12: 4 | AS12: {=INDIRECT(AS$5&$AR12+8)} -> Border | AT12: {=INDIRECT(AT$5&$AR12+8)} -> Border | AU12: {=INDIRECT(AU$5&$AR12+8)&"-"&1} -> 2048-1 | AV12: {=INDIRECT(AV$5&$AR12+8)&"-"&2} -> 2048-2 | AW12: {=INDIRECT(AW$5&$AR12+8)&"-"&1} -> 2047-1 | AX12: {=INDIRECT(AX$5&$AR12+8)&"-"&2} -> 2047-2 | AY12: {=INDIRECT(AY$5&$AR12+8)&"-"&1} -> 2046-1 | AZ12: {=INDIRECT(AZ$5&$AR12+8)&"-"&2} -> 2046-2 | BA12: {=INDIRECT(BA$5&$AR12+8)&"-"&1} -> 2045-1 | BB12: {=INDIRECT(BB$5&$AR12+8)&"-"&2} -> 2045-2 | BC12: {=INDIRECT(BC$5&$AR12+8)&"-"&1} -> 2044-1 | BD12: {=INDIRECT(BD$5&$AR12+8)&"-"&2} -> 2044-2 | BE12: {=INDIRECT(BE$5&$AR12+8)&"-"&1} -> 2043-1 | BF12: {=INDIRECT(BF$5&$AR12+8)&"-"&2} -> 2043-2 | BG12: {=INDIRECT(BG$5&$AR12+8)&"-"&1} -> 2042-1 | BH12: {=INDIRECT(BH$5&$AR12+8)&"-"&2} -> 2042-2 | BI12: {=INDIRECT(BI$5&$AR12+8)&"-"&1} -> 2041-1 | BJ12: {=INDIRECT(BJ$5&$AR12+8)&"-"&2} -> 2041-2 | BK12: {=INDIRECT(BK$5&$AR12+8)&"-"&1} -> 2040-1 | BL12: {=INDIRECT(BL$5&$AR12+8)&"-"&2} -> 2040-2 | BM12: {=INDIRECT(BM$5&$AR12+8)&"-"&1} -> 2039-1 | BN12: {=INDIRECT(BN$5&$AR12+8)&"-"&2} -> 2039-2 | BO12: {=INDIRECT(BO$5&$AR12+8)&"-"&1} -> 2038-1 | BP12: {=INDIRECT(BP$5&$AR12+8)&"-"&2} -> 2038-2 | BQ12: {=INDIRECT(BQ$5&$AR12+8)&"-"&1} -> 2037-1 | BR12: {=INDIRECT(BR$5&$AR12+8)&"-"&2} -> 2037-2 | BS12: {=INDIRECT(BS$5&$AR12+8)&"-"&1} -> 2036-1 | BT12: {=INDIRECT(BT$5&$AR12+8)&"-"&2} -> 2036-2 | BU12: {=INDIRECT(BU$5&$AR12+8)&"-"&1} -> 2035-1 | BV12: {=INDIRECT(BV$5&$AR12+8)&"-"&2} -> 2035-2 | BW12: {=INDIRECT(BW$5&$AR12+8)&"-"&1} -> 2034-1 | BX12: {=INDIRECT(BX$5&$AR12+8)&"-"&2} -> 2034-2 | BY12: {=INDIRECT(BY$5&$AR12+8)&"-"&1} -> 2033-1 | BZ12: {=INDIRECT(BZ$5&$AR12+8)&"-"&2} -> 2033-2 | CA12: {=INDIRECT(CA$5&$AR12+8)&"-"&1} -> 1048-1 | CB12: {=INDIRECT(CB$5&$AR12+8)&"-"&2} -> 1048-2 | CC12: {=INDIRECT(CC$5&$AR12+8)&"-"&1} -> 1047-1 | CD12: {=INDIRECT(CD$5&$AR12+8)&"-"&2} -> 1047-2 | CE12: {=INDIRECT(CE$5&$AR12+8)&"-"&1} -> 1046-1 | CF12: {=INDIRECT(CF$5&$AR12+8)&"-"&2} -> 1046-2 | CG12: {=INDIRECT(CG$5&$AR12+8)&"-"&1} -> 1045-1 | CH12: {=INDIRECT(CH$5&$AR12+8)&"-"&2} -> 1045-2 | CI12: {=INDIRECT(CI$5&$AR12+8)&"-"&1} -> 1044-1 | CJ12: {=INDIRECT(CJ$5&$AR12+8)&"-"&2} -> 1044-2 | CK12: {=INDIRECT(CK$5&$AR12+8)&"-"&1} -> 1043-1 | CL12: {=INDIRECT(CL$5&$AR12+8)&"-"&2} -> 1043-2 | CM12: {=INDIRECT(CM$5&$AR12+8)&"-"&1} -> 1042-1 | CN12: {=INDIRECT(CN$5&$AR12+8)&"-"&2} -> 1042-2 | CO12: {=INDIRECT(CO$5&$AR12+8)&"-"&1} -> 1041-1 | CP12: {=INDIRECT(CP$5&$AR12+8)&"-"&2} -> 1041-2 | CQ12: {=INDIRECT(CQ$5&$AR12+8)&"-"&1} -> 1040-1 | CR12: {=INDIRECT(CR$5&$AR12+8)&"-"&2} -> 1040-2 | CS12: {=INDIRECT(CS$5&$AR12+8)&"-"&1} -> 1039-1 | CT12: {=INDIRECT(CT$5&$AR12+8)&"-"&2} -> 1039-2 | CU12: {=INDIRECT(CU$5&$AR12+8)&"-"&1} -> 1038-1 | CV12: {=INDIRECT(CV$5&$AR12+8)&"-"&2} -> 1038-2 | CW12: {=INDIRECT(CW$5&$AR12+8)&"-"&1} -> 1037-1 | CX12: {=INDIRECT(CX$5&$AR12+8)&"-"&2} -> 1037-2 | CY12: {=INDIRECT(CY$5&$AR12+8)&"-"&1} -> 1036-1 | CZ12: {=INDIRECT(CZ$5&$AR12+8)&"-"&2} -> 1036-2 | DA12: {=INDIRECT(DA$5&$AR12+8)&"-"&1} -> 1035-1 | DB12: {=INDIRECT(DB$5&$AR12+8)&"-"&2} -> 1035-2 | DC12: {=INDIRECT(DC$5&$AR12+8)&"-"&1} -> 1034-1 | DD12: {=INDIRECT(DD$5&$AR12+8)&"-"&2} -> 1034-2 | DE12: {=INDIRECT(DE$5&$AR12+8)&"-"&1} -> 1033-1 | DF12: {=INDIRECT(DF$5&$AR12+8)&"-"&2} -> 1033-2 | DG12: {=INDIRECT(DG$5&$AR12+8)} -> Border | DH12: {=INDIRECT(DH$5&$AR12+8)} -> Border
B13: 5 | C13: Border | D13: =E13+1 -> 2064 | E13: =F13+1 -> 2063 | F13: =G13+1 -> 2062 | G13: =H13+1 -> 2061 | H13: =I13+1 -> 2060 | I13: =J13+1 -> 2059 | J13: =K13+1 -> 2058 | K13: =L13+1 -> 2057 | ... R13: =S13+1 -> 2050 | S13: {=D12+1} -> 2049 | T13: =U13+1 -> 1064 | U13: =V13+1 -> 1063 | V13: =W13+1 -> 1062 | W13: =X13+1 -> 1061 | X13: =Y13+1 -> 1060 | Y13: =Z13+1 -> 1059 | Z13: =AA13+1 -> 1058 | AA13: =AB13+1 -> 1057 | ... AH13: =AI13+1 -> 1050 | AI13: =T12+1 -> 1049 | AJ13: Border | AR13: 5 | AS13: {=INDIRECT(AS$5&$AR13+8)} -> Border | AT13: {=INDIRECT(AT$5&$AR13+8)} -> Border | AU13: {=INDIRECT(AU$5&$AR13+8)&"-"&1} -> 2064-1 | AV13: {=INDIRECT(AV$5&$AR13+8)&"-"&2} -> 2064-2 | AW13: {=INDIRECT(AW$5&$AR13+8)&"-"&1} -> 2063-1 | AX13: {=INDIRECT(AX$5&$AR13+8)&"-"&2} -> 2063-2 | AY13: {=INDIRECT(AY$5&$AR13+8)&"-"&1} -> 2062-1 | AZ13: {=INDIRECT(AZ$5&$AR13+8)&"-"&2} -> 2062-2 | BA13: {=INDIRECT(BA$5&$AR13+8)&"-"&1} -> 2061-1 | BB13: {=INDIRECT(BB$5&$AR13+8)&"-"&2} -> 2061-2 | BC13: {=INDIRECT(BC$5&$AR13+8)&"-"&1} -> 2060-1 | BD13: {=INDIRECT(BD$5&$AR13+8)&"-"&2} -> 2060-2 | BE13: {=INDIRECT(BE$5&$AR13+8)&"-"&1} -> 2059-1 | BF13: {=INDIRECT(BF$5&$AR13+8)&"-"&2} -> 2059-2 | BG13: {=INDIRECT(BG$5&$AR13+8)&"-"&1} -> 2058-1 | BH13: {=INDIRECT(BH$5&$AR13+8)&"-"&2} -> 2058-2 | BI13: {=INDIRECT(BI$5&$AR13+8)&"-"&1} -> 2057-1 | BJ13: {=INDIRECT(BJ$5&$AR13+8)&"-"&2} -> 2057-2 | BK13: {=INDIRECT(BK$5&$AR13+8)&"-"&1} -> 2056-1 | BL13: {=INDIRECT(BL$5&$AR13+8)&"-"&2} -> 2056-2 | BM13: {=INDIRECT(BM$5&$AR13+8)&"-"&1} -> 2055-1 | BN13: {=INDIRECT(BN$5&$AR13+8)&"-"&2} -> 2055-2 | BO13: {=INDIRECT(BO$5&$AR13+8)&"-"&1} -> 2054-1 | BP13: {=INDIRECT(BP$5&$AR13+8)&"-"&2} -> 2054-2 | BQ13: {=INDIRECT(BQ$5&$AR13+8)&"-"&1} -> 2053-1 | BR13: {=INDIRECT(BR$5&$AR13+8)&"-"&2} -> 2053-2 | BS13: {=INDIRECT(BS$5&$AR13+8)&"-"&1} -> 2052-1 | BT13: {=INDIRECT(BT$5&$AR13+8)&"-"&2} -> 2052-2 | BU13: {=INDIRECT(BU$5&$AR13+8)&"-"&1} -> 2051-1 | BV13: {=INDIRECT(BV$5&$AR13+8)&"-"&2} -> 2051-2 | BW13: {=INDIRECT(BW$5&$AR13+8)&"-"&1} -> 2050-1 | BX13: {=INDIRECT(BX$5&$AR13+8)&"-"&2} -> 2050-2 | BY13: {=INDIRECT(BY$5&$AR13+8)&"-"&1} -> 2049-1 | BZ13: {=INDIRECT(BZ$5&$AR13+8)&"-"&2} -> 2049-2 | CA13: {=INDIRECT(CA$5&$AR13+8)&"-"&1} -> 1064-1 | CB13: {=INDIRECT(CB$5&$AR13+8)&"-"&2} -> 1064-2 | CC13: {=INDIRECT(CC$5&$AR13+8)&"-"&1} -> 1063-1 | CD13: {=INDIRECT(CD$5&$AR13+8)&"-"&2} -> 1063-2 | CE13: {=INDIRECT(CE$5&$AR13+8)&"-"&1} -> 1062-1 | CF13: {=INDIRECT(CF$5&$AR13+8)&"-"&2} -> 1062-2 | CG13: {=INDIRECT(CG$5&$AR13+8)&"-"&1} -> 1061-1 | CH13: {=INDIRECT(CH$5&$AR13+8)&"-"&2} -> 1061-2 | CI13: {=INDIRECT(CI$5&$AR13+8)&"-"&1} -> 1060-1 | CJ13: {=INDIRECT(CJ$5&$AR13+8)&"-"&2} -> 1060-2 | CK13: {=INDIRECT(CK$5&$AR13+8)&"-"&1} -> 1059-1 | CL13: {=INDIRECT(CL$5&$AR13+8)&"-"&2} -> 1059-2 | CM13: {=INDIRECT(CM$5&$AR13+8)&"-"&1} -> 1058-1 | CN13: {=INDIRECT(CN$5&$AR13+8)&"-"&2} -> 1058-2 | CO13: {=INDIRECT(CO$5&$AR13+8)&"-"&1} -> 1057-1 | CP13: {=INDIRECT(CP$5&$AR13+8)&"-"&2} -> 1057-2 | CQ13: {=INDIRECT(CQ$5&$AR13+8)&"-"&1} -> 1056-1 | CR13: {=INDIRECT(CR$5&$AR13+8)&"-"&2} -> 1056-2 | CS13: {=INDIRECT(CS$5&$AR13+8)&"-"&1} -> 1055-1 | CT13: {=INDIRECT(CT$5&$AR13+8)&"-"&2} -> 1055-2 | CU13: {=INDIRECT(CU$5&$AR13+8)&"-"&1} -> 1054-1 | CV13: {=INDIRECT(CV$5&$AR13+8)&"-"&2} -> 1054-2 | CW13: {=INDIRECT(CW$5&$AR13+8)&"-"&1} -> 1053-1 | CX13: {=INDIRECT(CX$5&$AR13+8)&"-"&2} -> 1053-2 | CY13: {=INDIRECT(CY$5&$AR13+8)&"-"&1} -> 1052-1 | CZ13: {=INDIRECT(CZ$5&$AR13+8)&"-"&2} -> 1052-2 | DA13: {=INDIRECT(DA$5&$AR13+8)&"-"&1} -> 1051-1 | DB13: {=INDIRECT(DB$5&$AR13+8)&"-"&2} -> 1051-2 | DC13: {=INDIRECT(DC$5&$AR13+8)&"-"&1} -> 1050-1 | DD13: {=INDIRECT(DD$5&$AR13+8)&"-"&2} -> 1050-2 | DE13: {=INDIRECT(DE$5&$AR13+8)&"-"&1} -> 1049-1 | DF13: {=INDIRECT(DF$5&$AR13+8)&"-"&2} -> 1049-2 | DG13: {=INDIRECT(DG$5&$AR13+8)} -> Border | DH13: {=INDIRECT(DH$5&$AR13+8)} -> Border
B14: 6 | C14: Border | D14: =E14+1 -> 2080 | E14: =F14+1 -> 2079 | F14: =G14+1 -> 2078 | G14: =H14+1 -> 2077 | H14: =I14+1 -> 2076 | I14: =J14+1 -> 2075 | J14: =K14+1 -> 2074 | K14: =L14+1 -> 2073 | ... R14: =S14+1 -> 2066 | S14: {=D13+1} -> 2065 | T14: =U14+1 -> 1080 | U14: =V14+1 -> 1079 | V14: =W14+1 -> 1078 | W14: =X14+1 -> 1077 | X14: =Y14+1 -> 1076 | Y14: =Z14+1 -> 1075 | Z14: =AA14+1 -> 1074 | AA14: =AB14+1 -> 1073 | ... AH14: =AI14+1 -> 1066 | AI14: =T13+1 -> 1065 | AJ14: Border | AR14: 6 | AS14: {=INDIRECT(AS$5&$AR14+8)} -> Border | AT14: {=INDIRECT(AT$5&$AR14+8)} -> Border | AU14: {=INDIRECT(AU$5&$AR14+8)&"-"&1} -> 2080-1 | AV14: {=INDIRECT(AV$5&$AR14+8)&"-"&2} -> 2080-2 | AW14: {=INDIRECT(AW$5&$AR14+8)&"-"&1} -> 2079-1 | AX14: {=INDIRECT(AX$5&$AR14+8)&"-"&2} -> 2079-2 | AY14: {=INDIRECT(AY$5&$AR14+8)&"-"&1} -> 2078-1 | AZ14: {=INDIRECT(AZ$5&$AR14+8)&"-"&2} -> 2078-2 | BA14: {=INDIRECT(BA$5&$AR14+8)&"-"&1} -> 2077-1 | BB14: {=INDIRECT(BB$5&$AR14+8)&"-"&2} -> 2077-2 | BC14: {=INDIRECT(BC$5&$AR14+8)&"-"&1} -> 2076-1 | BD14: {=INDIRECT(BD$5&$AR14+8)&"-"&2} -> 2076-2 | BE14: {=INDIRECT(BE$5&$AR14+8)&"-"&1} -> 2075-1 | BF14: {=INDIRECT(BF$5&$AR14+8)&"-"&2} -> 2075-2 | BG14: {=INDIRECT(BG$5&$AR14+8)&"-"&1} -> 2074-1 | BH14: {=INDIRECT(BH$5&$AR14+8)&"-"&2} -> 2074-2 | BI14: {=INDIRECT(BI$5&$AR14+8)&"-"&1} -> 2073-1 | BJ14: {=INDIRECT(BJ$5&$AR14+8)&"-"&2} -> 2073-2 | BK14: {=INDIRECT(BK$5&$AR14+8)&"-"&1} -> 2072-1 | BL14: {=INDIRECT(BL$5&$AR14+8)&"-"&2} -> 2072-2 | BM14: {=INDIRECT(BM$5&$AR14+8)&"-"&1} -> 2071-1 | BN14: {=INDIRECT(BN$5&$AR14+8)&"-"&2} -> 2071-2 | BO14: {=INDIRECT(BO$5&$AR14+8)&"-"&1} -> 2070-1 | BP14: {=INDIRECT(BP$5&$AR14+8)&"-"&2} -> 2070-2 | BQ14: {=INDIRECT(BQ$5&$AR14+8)&"-"&1} -> 2069-1 | BR14: {=INDIRECT(BR$5&$AR14+8)&"-"&2} -> 2069-2 | BS14: {=INDIRECT(BS$5&$AR14+8)&"-"&1} -> 2068-1 | BT14: {=INDIRECT(BT$5&$AR14+8)&"-"&2} -> 2068-2 | BU14: {=INDIRECT(BU$5&$AR14+8)&"-"&1} -> 2067-1 | BV14: {=INDIRECT(BV$5&$AR14+8)&"-"&2} -> 2067-2 | BW14: {=INDIRECT(BW$5&$AR14+8)&"-"&1} -> 2066-1 | BX14: {=INDIRECT(BX$5&$AR14+8)&"-"&2} -> 2066-2 | BY14: {=INDIRECT(BY$5&$AR14+8)&"-"&1} -> 2065-1 | BZ14: {=INDIRECT(BZ$5&$AR14+8)&"-"&2} -> 2065-2 | CA14: {=INDIRECT(CA$5&$AR14+8)&"-"&1} -> 1080-1 | CB14: {=INDIRECT(CB$5&$AR14+8)&"-"&2} -> 1080-2 | CC14: {=INDIRECT(CC$5&$AR14+8)&"-"&1} -> 1079-1 | CD14: {=INDIRECT(CD$5&$AR14+8)&"-"&2} -> 1079-2 | CE14: {=INDIRECT(CE$5&$AR14+8)&"-"&1} -> 1078-1 | CF14: {=INDIRECT(CF$5&$AR14+8)&"-"&2} -> 1078-2 | CG14: {=INDIRECT(CG$5&$AR14+8)&"-"&1} -> 1077-1 | CH14: {=INDIRECT(CH$5&$AR14+8)&"-"&2} -> 1077-2 | CI14: {=INDIRECT(CI$5&$AR14+8)&"-"&1} -> 1076-1 | CJ14: {=INDIRECT(CJ$5&$AR14+8)&"-"&2} -> 1076-2 | CK14: {=INDIRECT(CK$5&$AR14+8)&"-"&1} -> 1075-1 | CL14: {=INDIRECT(CL$5&$AR14+8)&"-"&2} -> 1075-2 | CM14: {=INDIRECT(CM$5&$AR14+8)&"-"&1} -> 1074-1 | CN14: {=INDIRECT(CN$5&$AR14+8)&"-"&2} -> 1074-2 | CO14: {=INDIRECT(CO$5&$AR14+8)&"-"&1} -> 1073-1 | CP14: {=INDIRECT(CP$5&$AR14+8)&"-"&2} -> 1073-2 | CQ14: {=INDIRECT(CQ$5&$AR14+8)&"-"&1} -> 1072-1 | CR14: {=INDIRECT(CR$5&$AR14+8)&"-"&2} -> 1072-2 | CS14: {=INDIRECT(CS$5&$AR14+8)&"-"&1} -> 1071-1 | CT14: {=INDIRECT(CT$5&$AR14+8)&"-"&2} -> 1071-2 | CU14: {=INDIRECT(CU$5&$AR14+8)&"-"&1} -> 1070-1 | CV14: {=INDIRECT(CV$5&$AR14+8)&"-"&2} -> 1070-2 | CW14: {=INDIRECT(CW$5&$AR14+8)&"-"&1} -> 1069-1 | CX14: {=INDIRECT(CX$5&$AR14+8)&"-"&2} -> 1069-2 | CY14: {=INDIRECT(CY$5&$AR14+8)&"-"&1} -> 1068-1 | CZ14: {=INDIRECT(CZ$5&$AR14+8)&"-"&2} -> 1068-2 | DA14: {=INDIRECT(DA$5&$AR14+8)&"-"&1} -> 1067-1 | DB14: {=INDIRECT(DB$5&$AR14+8)&"-"&2} -> 1067-2 | DC14: {=INDIRECT(DC$5&$AR14+8)&"-"&1} -> 1066-1 | DD14: {=INDIRECT(DD$5&$AR14+8)&"-"&2} -> 1066-2 | DE14: {=INDIRECT(DE$5&$AR14+8)&"-"&1} -> 1065-1 | DF14: {=INDIRECT(DF$5&$AR14+8)&"-"&2} -> 1065-2 | DG14: {=INDIRECT(DG$5&$AR14+8)} -> Border | DH14: {=INDIRECT(DH$5&$AR14+8)} -> Border
B15: 7 | C15: Border | D15: =E15+1 -> 2096 | E15: =F15+1 -> 2095 | F15: =G15+1 -> 2094 | G15: =H15+1 -> 2093 | H15: =I15+1 -> 2092 | I15: =J15+1 -> 2091 | J15: =K15+1 -> 2090 | K15: =L15+1 -> 2089 | ... R15: =S15+1 -> 2082 | S15: {=D14+1} -> 2081 | T15: =U15+1 -> 1096 | U15: =V15+1 -> 1095 | V15: =W15+1 -> 1094 | W15: =X15+1 -> 1093 | X15: =Y15+1 -> 1092 | Y15: =Z15+1 -> 1091 | Z15: =AA15+1 -> 1090 | AA15: =AB15+1 -> 1089 | ... AH15: =AI15+1 -> 1082 | AI15: =T14+1 -> 1081 | AJ15: Border | AR15: 7 | AS15: {=INDIRECT(AS$5&$AR15+8)} -> Border | AT15: {=INDIRECT(AT$5&$AR15+8)} -> Border | AU15: {=INDIRECT(AU$5&$AR15+8)&"-"&1} -> 2096-1 | AV15: {=INDIRECT(AV$5&$AR15+8)&"-"&2} -> 2096-2 | AW15: {=INDIRECT(AW$5&$AR15+8)&"-"&1} -> 2095-1 | AX15: {=INDIRECT(AX$5&$AR15+8)&"-"&2} -> 2095-2 | AY15: {=INDIRECT(AY$5&$AR15+8)&"-"&1} -> 2094-1 | AZ15: {=INDIRECT(AZ$5&$AR15+8)&"-"&2} -> 2094-2 | BA15: {=INDIRECT(BA$5&$AR15+8)&"-"&1} -> 2093-1 | BB15: {=INDIRECT(BB$5&$AR15+8)&"-"&2} -> 2093-2 | BC15: {=INDIRECT(BC$5&$AR15+8)&"-"&1} -> 2092-1 | BD15: {=INDIRECT(BD$5&$AR15+8)&"-"&2} -> 2092-2 | BE15: {=INDIRECT(BE$5&$AR15+8)&"-"&1} -> 2091-1 | BF15: {=INDIRECT(BF$5&$AR15+8)&"-"&2} -> 2091-2 | BG15: {=INDIRECT(BG$5&$AR15+8)&"-"&1} -> 2090-1 | BH15: {=INDIRECT(BH$5&$AR15+8)&"-"&2} -> 2090-2 | BI15: {=INDIRECT(BI$5&$AR15+8)&"-"&1} -> 2089-1 | BJ15: {=INDIRECT(BJ$5&$AR15+8)&"-"&2} -> 2089-2 | BK15: {=INDIRECT(BK$5&$AR15+8)&"-"&1} -> 2088-1 | BL15: {=INDIRECT(BL$5&$AR15+8)&"-"&2} -> 2088-2 | BM15: {=INDIRECT(BM$5&$AR15+8)&"-"&1} -> 2087-1 | BN15: {=INDIRECT(BN$5&$AR15+8)&"-"&2} -> 2087-2 | BO15: {=INDIRECT(BO$5&$AR15+8)&"-"&1} -> 2086-1 | BP15: {=INDIRECT(BP$5&$AR15+8)&"-"&2} -> 2086-2 | BQ15: {=INDIRECT(BQ$5&$AR15+8)&"-"&1} -> 2085-1 | BR15: {=INDIRECT(BR$5&$AR15+8)&"-"&2} -> 2085-2 | BS15: {=INDIRECT(BS$5&$AR15+8)&"-"&1} -> 2084-1 | BT15: {=INDIRECT(BT$5&$AR15+8)&"-"&2} -> 2084-2 | BU15: {=INDIRECT(BU$5&$AR15+8)&"-"&1} -> 2083-1 | BV15: {=INDIRECT(BV$5&$AR15+8)&"-"&2} -> 2083-2 | BW15: {=INDIRECT(BW$5&$AR15+8)&"-"&1} -> 2082-1 | BX15: {=INDIRECT(BX$5&$AR15+8)&"-"&2} -> 2082-2 | BY15: {=INDIRECT(BY$5&$AR15+8)&"-"&1} -> 2081-1 | BZ15: {=INDIRECT(BZ$5&$AR15+8)&"-"&2} -> 2081-2 | CA15: {=INDIRECT(CA$5&$AR15+8)&"-"&1} -> 1096-1 | CB15: {=INDIRECT(CB$5&$AR15+8)&"-"&2} -> 1096-2 | CC15: {=INDIRECT(CC$5&$AR15+8)&"-"&1} -> 1095-1 | CD15: {=INDIRECT(CD$5&$AR15+8)&"-"&2} -> 1095-2 | CE15: {=INDIRECT(CE$5&$AR15+8)&"-"&1} -> 1094-1 | CF15: {=INDIRECT(CF$5&$AR15+8)&"-"&2} -> 1094-2 | CG15: {=INDIRECT(CG$5&$AR15+8)&"-"&1} -> 1093-1 | CH15: {=INDIRECT(CH$5&$AR15+8)&"-"&2} -> 1093-2 | CI15: {=INDIRECT(CI$5&$AR15+8)&"-"&1} -> 1092-1 | CJ15: {=INDIRECT(CJ$5&$AR15+8)&"-"&2} -> 1092-2 | CK15: {=INDIRECT(CK$5&$AR15+8)&"-"&1} -> 1091-1 | CL15: {=INDIRECT(CL$5&$AR15+8)&"-"&2} -> 1091-2 | CM15: {=INDIRECT(CM$5&$AR15+8)&"-"&1} -> 1090-1 | CN15: {=INDIRECT(CN$5&$AR15+8)&"-"&2} -> 1090-2 | CO15: {=INDIRECT(CO$5&$AR15+8)&"-"&1} -> 1089-1 | CP15: {=INDIRECT(CP$5&$AR15+8)&"-"&2} -> 1089-2 | CQ15: {=INDIRECT(CQ$5&$AR15+8)&"-"&1} -> 1088-1 | CR15: {=INDIRECT(CR$5&$AR15+8)&"-"&2} -> 1088-2 | CS15: {=INDIRECT(CS$5&$AR15+8)&"-"&1} -> 1087-1 | CT15: {=INDIRECT(CT$5&$AR15+8)&"-"&2} -> 1087-2 | CU15: {=INDIRECT(CU$5&$AR15+8)&"-"&1} -> 1086-1 | CV15: {=INDIRECT(CV$5&$AR15+8)&"-"&2} -> 1086-2 | CW15: {=INDIRECT(CW$5&$AR15+8)&"-"&1} -> 1085-1 | CX15: {=INDIRECT(CX$5&$AR15+8)&"-"&2} -> 1085-2 | CY15: {=INDIRECT(CY$5&$AR15+8)&"-"&1} -> 1084-1 | CZ15: {=INDIRECT(CZ$5&$AR15+8)&"-"&2} -> 1084-2 | DA15: {=INDIRECT(DA$5&$AR15+8)&"-"&1} -> 1083-1 | DB15: {=INDIRECT(DB$5&$AR15+8)&"-"&2} -> 1083-2 | DC15: {=INDIRECT(DC$5&$AR15+8)&"-"&1} -> 1082-1 | DD15: {=INDIRECT(DD$5&$AR15+8)&"-"&2} -> 1082-2 | DE15: {=INDIRECT(DE$5&$AR15+8)&"-"&1} -> 1081-1 | DF15: {=INDIRECT(DF$5&$AR15+8)&"-"&2} -> 1081-2 | DG15: {=INDIRECT(DG$5&$AR15+8)} -> Border | DH15: {=INDIRECT(DH$5&$AR15+8)} -> Border
B16: 8 | C16: Border | D16: =E16+1 -> 2112 | E16: =F16+1 -> 2111 | F16: =G16+1 -> 2110 | G16: =H16+1 -> 2109 | H16: =I16+1 -> 2108 | I16: =J16+1 -> 2107 | J16: =K16+1 -> 2106 | K16: =L16+1 -> 2105 | ... R16: =S16+1 -> 2098 | S16: {=D15+1} -> 2097 | T16: =U16+1 -> 1112 | U16: =V16+1 -> 1111 | V16: =W16+1 -> 1110 | W16: =X16+1 -> 1109 | X16: =Y16+1 -> 1108 | Y16: =Z16+1 -> 1107 | Z16: =AA16+1 -> 1106 | AA16: =AB16+1 -> 1105 | ... AH16: =AI16+1 -> 1098 | AI16: =T15+1 -> 1097 | AJ16: Border | AR16: 8 | AS16: {=INDIRECT(AS$5&$AR16+8)} -> Border | AT16: {=INDIRECT(AT$5&$AR16+8)} -> Border | AU16: {=INDIRECT(AU$5&$AR16+8)&"-"&1} -> 2112-1 | AV16: {=INDIRECT(AV$5&$AR16+8)&"-"&2} -> 2112-2 | AW16: {=INDIRECT(AW$5&$AR16+8)&"-"&1} -> 2111-1 | AX16: {=INDIRECT(AX$5&$AR16+8)&"-"&2} -> 2111-2 | AY16: {=INDIRECT(AY$5&$AR16+8)&"-"&1} -> 2110-1 | AZ16: {=INDIRECT(AZ$5&$AR16+8)&"-"&2} -> 2110-2 | BA16: {=INDIRECT(BA$5&$AR16+8)&"-"&1} -> 2109-1 | BB16: {=INDIRECT(BB$5&$AR16+8)&"-"&2} -> 2109-2 | BC16: {=INDIRECT(BC$5&$AR16+8)&"-"&1} -> 2108-1 | BD16: {=INDIRECT(BD$5&$AR16+8)&"-"&2} -> 2108-2 | BE16: {=INDIRECT(BE$5&$AR16+8)&"-"&1} -> 2107-1 | BF16: {=INDIRECT(BF$5&$AR16+8)&"-"&2} -> 2107-2 | BG16: {=INDIRECT(BG$5&$AR16+8)&"-"&1} -> 2106-1 | BH16: {=INDIRECT(BH$5&$AR16+8)&"-"&2} -> 2106-2 | BI16: {=INDIRECT(BI$5&$AR16+8)&"-"&1} -> 2105-1 | BJ16: {=INDIRECT(BJ$5&$AR16+8)&"-"&2} -> 2105-2 | BK16: {=INDIRECT(BK$5&$AR16+8)&"-"&1} -> 2104-1 | BL16: {=INDIRECT(BL$5&$AR16+8)&"-"&2} -> 2104-2 | BM16: {=INDIRECT(BM$5&$AR16+8)&"-"&1} -> 2103-1 | BN16: {=INDIRECT(BN$5&$AR16+8)&"-"&2} -> 2103-2 | BO16: {=INDIRECT(BO$5&$AR16+8)&"-"&1} -> 2102-1 | BP16: {=INDIRECT(BP$5&$AR16+8)&"-"&2} -> 2102-2 | BQ16: {=INDIRECT(BQ$5&$AR16+8)&"-"&1} -> 2101-1 | BR16: {=INDIRECT(BR$5&$AR16+8)&"-"&2} -> 2101-2 | BS16: {=INDIRECT(BS$5&$AR16+8)&"-"&1} -> 2100-1 | BT16: {=INDIRECT(BT$5&$AR16+8)&"-"&2} -> 2100-2 | BU16: {=INDIRECT(BU$5&$AR16+8)&"-"&1} -> 2099-1 | BV16: {=INDIRECT(BV$5&$AR16+8)&"-"&2} -> 2099-2 | BW16: {=INDIRECT(BW$5&$AR16+8)&"-"&1} -> 2098-1 | BX16: {=INDIRECT(BX$5&$AR16+8)&"-"&2} -> 2098-2 | BY16: {=INDIRECT(BY$5&$AR16+8)&"-"&1} -> 2097-1 | BZ16: {=INDIRECT(BZ$5&$AR16+8)&"-"&2} -> 2097-2 | CA16: {=INDIRECT(CA$5&$AR16+8)&"-"&1} -> 1112-1 | CB16: {=INDIRECT(CB$5&$AR16+8)&"-"&2} -> 1112-2 | CC16: {=INDIRECT(CC$5&$AR16+8)&"-"&1} -> 1111-1 | CD16: {=INDIRECT(CD$5&$AR16+8)&"-"&2} -> 1111-2 | CE16: {=INDIRECT(CE$5&$AR16+8)&"-"&1} -> 1110-1 | CF16: {=INDIRECT(CF$5&$AR16+8)&"-"&2} -> 1110-2 | CG16: {=INDIRECT(CG$5&$AR16+8)&"-"&1} -> 1109-1 | CH16: {=INDIRECT(CH$5&$AR16+8)&"-"&2} -> 1109-2 | CI16: {=INDIRECT(CI$5&$AR16+8)&"-"&1} -> 1108-1 | CJ16: {=INDIRECT(CJ$5&$AR16+8)&"-"&2} -> 1108-2 | CK16: {=INDIRECT(CK$5&$AR16+8)&"-"&1} -> 1107-1 | CL16: {=INDIRECT(CL$5&$AR16+8)&"-"&2} -> 1107-2 | CM16: {=INDIRECT(CM$5&$AR16+8)&"-"&1} -> 1106-1 | CN16: {=INDIRECT(CN$5&$AR16+8)&"-"&2} -> 1106-2 | CO16: {=INDIRECT(CO$5&$AR16+8)&"-"&1} -> 1105-1 | CP16: {=INDIRECT(CP$5&$AR16+8)&"-"&2} -> 1105-2 | CQ16: {=INDIRECT(CQ$5&$AR16+8)&"-"&1} -> 1104-1 | CR16: {=INDIRECT(CR$5&$AR16+8)&"-"&2} -> 1104-2 | CS16: {=INDIRECT(CS$5&$AR16+8)&"-"&1} -> 1103-1 | CT16: {=INDIRECT(CT$5&$AR16+8)&"-"&2} -> 1103-2 | CU16: {=INDIRECT(CU$5&$AR16+8)&"-"&1} -> 1102-1 | CV16: {=INDIRECT(CV$5&$AR16+8)&"-"&2} -> 1102-2 | CW16: {=INDIRECT(CW$5&$AR16+8)&"-"&1} -> 1101-1 | CX16: {=INDIRECT(CX$5&$AR16+8)&"-"&2} -> 1101-2 | CY16: {=INDIRECT(CY$5&$AR16+8)&"-"&1} -> 1100-1 | CZ16: {=INDIRECT(CZ$5&$AR16+8)&"-"&2} -> 1100-2 | DA16: {=INDIRECT(DA$5&$AR16+8)&"-"&1} -> 1099-1 | DB16: {=INDIRECT(DB$5&$AR16+8)&"-"&2} -> 1099-2 | DC16: {=INDIRECT(DC$5&$AR16+8)&"-"&1} -> 1098-1 | DD16: {=INDIRECT(DD$5&$AR16+8)&"-"&2} -> 1098-2 | DE16: {=INDIRECT(DE$5&$AR16+8)&"-"&1} -> 1097-1 | DF16: {=INDIRECT(DF$5&$AR16+8)&"-"&2} -> 1097-2 | DG16: {=INDIRECT(DG$5&$AR16+8)} -> Border | DH16: {=INDIRECT(DH$5&$AR16+8)} -> Border
B17: 9 | C17: Border | D17: =E17+1 -> 2128 | E17: =F17+1 -> 2127 | F17: =G17+1 -> 2126 | G17: =H17+1 -> 2125 | H17: =I17+1 -> 2124 | I17: =J17+1 -> 2123 | J17: =K17+1 -> 2122 | K17: =L17+1 -> 2121 | ... R17: =S17+1 -> 2114 | S17: {=D16+1} -> 2113 | T17: =U17+1 -> 1128 | U17: =V17+1 -> 1127 | V17: =W17+1 -> 1126 | W17: =X17+1 -> 1125 | X17: =Y17+1 -> 1124 | Y17: =Z17+1 -> 1123 | Z17: =AA17+1 -> 1122 | AA17: =AB17+1 -> 1121 | ... AH17: =AI17+1 -> 1114 | AI17: =T16+1 -> 1113 | AJ17: Border | AR17: 9 | AS17: {=INDIRECT(AS$5&$AR17+8)} -> Border | AT17: {=INDIRECT(AT$5&$AR17+8)} -> Border | AU17: {=INDIRECT(AU$5&$AR17+8)&"-"&1} -> 2128-1 | AV17: {=INDIRECT(AV$5&$AR17+8)&"-"&2} -> 2128-2 | AW17: {=INDIRECT(AW$5&$AR17+8)&"-"&1} -> 2127-1 | AX17: {=INDIRECT(AX$5&$AR17+8)&"-"&2} -> 2127-2 | AY17: {=INDIRECT(AY$5&$AR17+8)&"-"&1} -> 2126-1 | AZ17: {=INDIRECT(AZ$5&$AR17+8)&"-"&2} -> 2126-2 | BA17: {=INDIRECT(BA$5&$AR17+8)&"-"&1} -> 2125-1 | BB17: {=INDIRECT(BB$5&$AR17+8)&"-"&2} -> 2125-2 | BC17: {=INDIRECT(BC$5&$AR17+8)&"-"&1} -> 2124-1 | BD17: {=INDIRECT(BD$5&$AR17+8)&"-"&2} -> 2124-2 | BE17: {=INDIRECT(BE$5&$AR17+8)&"-"&1} -> 2123-1 | BF17: {=INDIRECT(BF$5&$AR17+8)&"-"&2} -> 2123-2 | BG17: {=INDIRECT(BG$5&$AR17+8)&"-"&1} -> 2122-1 | BH17: {=INDIRECT(BH$5&$AR17+8)&"-"&2} -> 2122-2 | BI17: {=INDIRECT(BI$5&$AR17+8)&"-"&1} -> 2121-1 | BJ17: {=INDIRECT(BJ$5&$AR17+8)&"-"&2} -> 2121-2 | BK17: {=INDIRECT(BK$5&$AR17+8)&"-"&1} -> 2120-1 | BL17: {=INDIRECT(BL$5&$AR17+8)&"-"&2} -> 2120-2 | BM17: {=INDIRECT(BM$5&$AR17+8)&"-"&1} -> 2119-1 | BN17: {=INDIRECT(BN$5&$AR17+8)&"-"&2} -> 2119-2 | BO17: {=INDIRECT(BO$5&$AR17+8)&"-"&1} -> 2118-1 | BP17: {=INDIRECT(BP$5&$AR17+8)&"-"&2} -> 2118-2 | BQ17: {=INDIRECT(BQ$5&$AR17+8)&"-"&1} -> 2117-1 | BR17: {=INDIRECT(BR$5&$AR17+8)&"-"&2} -> 2117-2 | BS17: {=INDIRECT(BS$5&$AR17+8)&"-"&1} -> 2116-1 | BT17: {=INDIRECT(BT$5&$AR17+8)&"-"&2} -> 2116-2 | BU17: {=INDIRECT(BU$5&$AR17+8)&"-"&1} -> 2115-1 | BV17: {=INDIRECT(BV$5&$AR17+8)&"-"&2} -> 2115-2 | BW17: {=INDIRECT(BW$5&$AR17+8)&"-"&1} -> 2114-1 | BX17: {=INDIRECT(BX$5&$AR17+8)&"-"&2} -> 2114-2 | BY17: {=INDIRECT(BY$5&$AR17+8)&"-"&1} -> 2113-1 | BZ17: {=INDIRECT(BZ$5&$AR17+8)&"-"&2} -> 2113-2 | CA17: {=INDIRECT(CA$5&$AR17+8)&"-"&1} -> 1128-1 | CB17: {=INDIRECT(CB$5&$AR17+8)&"-"&2} -> 1128-2 | CC17: {=INDIRECT(CC$5&$AR17+8)&"-"&1} -> 1127-1 | CD17: {=INDIRECT(CD$5&$AR17+8)&"-"&2} -> 1127-2 | CE17: {=INDIRECT(CE$5&$AR17+8)&"-"&1} -> 1126-1 | CF17: {=INDIRECT(CF$5&$AR17+8)&"-"&2} -> 1126-2 | CG17: {=INDIRECT(CG$5&$AR17+8)&"-"&1} -> 1125-1 | CH17: {=INDIRECT(CH$5&$AR17+8)&"-"&2} -> 1125-2 | CI17: {=INDIRECT(CI$5&$AR17+8)&"-"&1} -> 1124-1 | CJ17: {=INDIRECT(CJ$5&$AR17+8)&"-"&2} -> 1124-2 | CK17: {=INDIRECT(CK$5&$AR17+8)&"-"&1} -> 1123-1 | CL17: {=INDIRECT(CL$5&$AR17+8)&"-"&2} -> 1123-2 | CM17: {=INDIRECT(CM$5&$AR17+8)&"-"&1} -> 1122-1 | CN17: {=INDIRECT(CN$5&$AR17+8)&"-"&2} -> 1122-2 | CO17: {=INDIRECT(CO$5&$AR17+8)&"-"&1} -> 1121-1 | CP17: {=INDIRECT(CP$5&$AR17+8)&"-"&2} -> 1121-2 | CQ17: {=INDIRECT(CQ$5&$AR17+8)&"-"&1} -> 1120-1 | CR17: {=INDIRECT(CR$5&$AR17+8)&"-"&2} -> 1120-2 | CS17: {=INDIRECT(CS$5&$AR17+8)&"-"&1} -> 1119-1 | CT17: {=INDIRECT(CT$5&$AR17+8)&"-"&2} -> 1119-2 | CU17: {=INDIRECT(CU$5&$AR17+8)&"-"&1} -> 1118-1 | CV17: {=INDIRECT(CV$5&$AR17+8)&"-"&2} -> 1118-2 | CW17: {=INDIRECT(CW$5&$AR17+8)&"-"&1} -> 1117-1 | CX17: {=INDIRECT(CX$5&$AR17+8)&"-"&2} -> 1117-2 | CY17: {=INDIRECT(CY$5&$AR17+8)&"-"&1} -> 1116-1 | CZ17: {=INDIRECT(CZ$5&$AR17+8)&"-"&2} -> 1116-2 | DA17: {=INDIRECT(DA$5&$AR17+8)&"-"&1} -> 1115-1 | DB17: {=INDIRECT(DB$5&$AR17+8)&"-"&2} -> 1115-2 | DC17: {=INDIRECT(DC$5&$AR17+8)&"-"&1} -> 1114-1 | DD17: {=INDIRECT(DD$5&$AR17+8)&"-"&2} -> 1114-2 | DE17: {=INDIRECT(DE$5&$AR17+8)&"-"&1} -> 1113-1 | DF17: {=INDIRECT(DF$5&$AR17+8)&"-"&2} -> 1113-2 | DG17: {=INDIRECT(DG$5&$AR17+8)} -> Border | DH17: {=INDIRECT(DH$5&$AR17+8)} -> Border
B18: 10 | C18: Border | D18: =E18+1 -> 2144 | E18: =F18+1 -> 2143 | F18: =G18+1 -> 2142 | G18: =H18+1 -> 2141 | H18: =I18+1 -> 2140 | I18: =J18+1 -> 2139 | J18: =K18+1 -> 2138 | K18: =L18+1 -> 2137 | ... R18: =S18+1 -> 2130 | S18: {=D17+1} -> 2129 | T18: =U18+1 -> 1144 | U18: =V18+1 -> 1143 | V18: =W18+1 -> 1142 | W18: =X18+1 -> 1141 | X18: =Y18+1 -> 1140 | Y18: =Z18+1 -> 1139 | Z18: =AA18+1 -> 1138 | AA18: =AB18+1 -> 1137 | ... AH18: =AI18+1 -> 1130 | AI18: =T17+1 -> 1129 | AJ18: Border | AR18: 10 | AS18: {=INDIRECT(AS$5&$AR18+8)} -> Border | AT18: {=INDIRECT(AT$5&$AR18+8)} -> Border | AU18: {=INDIRECT(AU$5&$AR18+8)&"-"&1} -> 2144-1 | AV18: {=INDIRECT(AV$5&$AR18+8)&"-"&2} -> 2144-2 | AW18: {=INDIRECT(AW$5&$AR18+8)&"-"&1} -> 2143-1 | AX18: {=INDIRECT(AX$5&$AR18+8)&"-"&2} -> 2143-2 | AY18: {=INDIRECT(AY$5&$AR18+8)&"-"&1} -> 2142-1 | AZ18: {=INDIRECT(AZ$5&$AR18+8)&"-"&2} -> 2142-2 | BA18: {=INDIRECT(BA$5&$AR18+8)&"-"&1} -> 2141-1 | BB18: {=INDIRECT(BB$5&$AR18+8)&"-"&2} -> 2141-2 | BC18: {=INDIRECT(BC$5&$AR18+8)&"-"&1} -> 2140-1 | BD18: {=INDIRECT(BD$5&$AR18+8)&"-"&2} -> 2140-2 | BE18: {=INDIRECT(BE$5&$AR18+8)&"-"&1} -> 2139-1 | BF18: {=INDIRECT(BF$5&$AR18+8)&"-"&2} -> 2139-2 | BG18: {=INDIRECT(BG$5&$AR18+8)&"-"&1} -> 2138-1 | BH18: {=INDIRECT(BH$5&$AR18+8)&"-"&2} -> 2138-2 | BI18: {=INDIRECT(BI$5&$AR18+8)&"-"&1} -> 2137-1 | BJ18: {=INDIRECT(BJ$5&$AR18+8)&"-"&2} -> 2137-2 | BK18: {=INDIRECT(BK$5&$AR18+8)&"-"&1} -> 2136-1 | BL18: {=INDIRECT(BL$5&$AR18+8)&"-"&2} -> 2136-2 | BM18: {=INDIRECT(BM$5&$AR18+8)&"-"&1} -> 2135-1 | BN18: {=INDIRECT(BN$5&$AR18+8)&"-"&2} -> 2135-2 | BO18: {=INDIRECT(BO$5&$AR18+8)&"-"&1} -> 2134-1 | BP18: {=INDIRECT(BP$5&$AR18+8)&"-"&2} -> 2134-2 | BQ18: {=INDIRECT(BQ$5&$AR18+8)&"-"&1} -> 2133-1 | BR18: {=INDIRECT(BR$5&$AR18+8)&"-"&2} -> 2133-2 | BS18: {=INDIRECT(BS$5&$AR18+8)&"-"&1} -> 2132-1 | BT18: {=INDIRECT(BT$5&$AR18+8)&"-"&2} -> 2132-2 | BU18: {=INDIRECT(BU$5&$AR18+8)&"-"&1} -> 2131-1 | BV18: {=INDIRECT(BV$5&$AR18+8)&"-"&2} -> 2131-2 | BW18: {=INDIRECT(BW$5&$AR18+8)&"-"&1} -> 2130-1 | BX18: {=INDIRECT(BX$5&$AR18+8)&"-"&2} -> 2130-2 | BY18: {=INDIRECT(BY$5&$AR18+8)&"-"&1} -> 2129-1 | BZ18: {=INDIRECT(BZ$5&$AR18+8)&"-"&2} -> 2129-2 | CA18: {=INDIRECT(CA$5&$AR18+8)&"-"&1} -> 1144-1 | CB18: {=INDIRECT(CB$5&$AR18+8)&"-"&2} -> 1144-2 | CC18: {=INDIRECT(CC$5&$AR18+8)&"-"&1} -> 1143-1 | CD18: {=INDIRECT(CD$5&$AR18+8)&"-"&2} -> 1143-2 | CE18: {=INDIRECT(CE$5&$AR18+8)&"-"&1} -> 1142-1 | CF18: {=INDIRECT(CF$5&$AR18+8)&"-"&2} -> 1142-2 | CG18: {=INDIRECT(CG$5&$AR18+8)&"-"&1} -> 1141-1 | CH18: {=INDIRECT(CH$5&$AR18+8)&"-"&2} -> 1141-2 | CI18: {=INDIRECT(CI$5&$AR18+8)&"-"&1} -> 1140-1 | CJ18: {=INDIRECT(CJ$5&$AR18+8)&"-"&2} -> 1140-2 | CK18: {=INDIRECT(CK$5&$AR18+8)&"-"&1} -> 1139-1 | CL18: {=INDIRECT(CL$5&$AR18+8)&"-"&2} -> 1139-2 | CM18: {=INDIRECT(CM$5&$AR18+8)&"-"&1} -> 1138-1 | CN18: {=INDIRECT(CN$5&$AR18+8)&"-"&2} -> 1138-2 | CO18: {=INDIRECT(CO$5&$AR18+8)&"-"&1} -> 1137-1 | CP18: {=INDIRECT(CP$5&$AR18+8)&"-"&2} -> 1137-2 | CQ18: {=INDIRECT(CQ$5&$AR18+8)&"-"&1} -> 1136-1 | CR18: {=INDIRECT(CR$5&$AR18+8)&"-"&2} -> 1136-2 | CS18: {=INDIRECT(CS$5&$AR18+8)&"-"&1} -> 1135-1 | CT18: {=INDIRECT(CT$5&$AR18+8)&"-"&2} -> 1135-2 | CU18: {=INDIRECT(CU$5&$AR18+8)&"-"&1} -> 1134-1 | CV18: {=INDIRECT(CV$5&$AR18+8)&"-"&2} -> 1134-2 | CW18: {=INDIRECT(CW$5&$AR18+8)&"-"&1} -> 1133-1 | CX18: {=INDIRECT(CX$5&$AR18+8)&"-"&2} -> 1133-2 | CY18: {=INDIRECT(CY$5&$AR18+8)&"-"&1} -> 1132-1 | CZ18: {=INDIRECT(CZ$5&$AR18+8)&"-"&2} -> 1132-2 | DA18: {=INDIRECT(DA$5&$AR18+8)&"-"&1} -> 1131-1 | DB18: {=INDIRECT(DB$5&$AR18+8)&"-"&2} -> 1131-2 | DC18: {=INDIRECT(DC$5&$AR18+8)&"-"&1} -> 1130-1 | DD18: {=INDIRECT(DD$5&$AR18+8)&"-"&2} -> 1130-2 | DE18: {=INDIRECT(DE$5&$AR18+8)&"-"&1} -> 1129-1 | DF18: {=INDIRECT(DF$5&$AR18+8)&"-"&2} -> 1129-2 | DG18: {=INDIRECT(DG$5&$AR18+8)} -> Border | DH18: {=INDIRECT(DH$5&$AR18+8)} -> Border
B19: 11 | C19: Border | D19: =E19+1 -> 2160 | E19: =F19+1 -> 2159 | F19: =G19+1 -> 2158 | G19: =H19+1 -> 2157 | H19: =I19+1 -> 2156 | I19: =J19+1 -> 2155 | J19: =K19+1 -> 2154 | K19: =L19+1 -> 2153 | ... R19: =S19+1 -> 2146 | S19: {=D18+1} -> 2145 | T19: =U19+1 -> 1160 | U19: =V19+1 -> 1159 | V19: =W19+1 -> 1158 | W19: =X19+1 -> 1157 | X19: =Y19+1 -> 1156 | Y19: =Z19+1 -> 1155 | Z19: =AA19+1 -> 1154 | AA19: =AB19+1 -> 1153 | ... AH19: =AI19+1 -> 1146 | AI19: =T18+1 -> 1145 | AJ19: Border | AR19: 11 | AS19: {=INDIRECT(AS$5&$AR19+8)} -> Border | AT19: {=INDIRECT(AT$5&$AR19+8)} -> Border | AU19: {=INDIRECT(AU$5&$AR19+8)&"-"&1} -> 2160-1 | AV19: {=INDIRECT(AV$5&$AR19+8)&"-"&2} -> 2160-2 | AW19: {=INDIRECT(AW$5&$AR19+8)&"-"&1} -> 2159-1 | AX19: {=INDIRECT(AX$5&$AR19+8)&"-"&2} -> 2159-2 | AY19: {=INDIRECT(AY$5&$AR19+8)&"-"&1} -> 2158-1 | AZ19: {=INDIRECT(AZ$5&$AR19+8)&"-"&2} -> 2158-2 | BA19: {=INDIRECT(BA$5&$AR19+8)&"-"&1} -> 2157-1 | BB19: {=INDIRECT(BB$5&$AR19+8)&"-"&2} -> 2157-2 | BC19: {=INDIRECT(BC$5&$AR19+8)&"-"&1} -> 2156-1 | BD19: {=INDIRECT(BD$5&$AR19+8)&"-"&2} -> 2156-2 | BE19: {=INDIRECT(BE$5&$AR19+8)&"-"&1} -> 2155-1 | BF19: {=INDIRECT(BF$5&$AR19+8)&"-"&2} -> 2155-2 | BG19: {=INDIRECT(BG$5&$AR19+8)&"-"&1} -> 2154-1 | BH19: {=INDIRECT(BH$5&$AR19+8)&"-"&2} -> 2154-2 | BI19: {=INDIRECT(BI$5&$AR19+8)&"-"&1} -> 2153-1 | BJ19: {=INDIRECT(BJ$5&$AR19+8)&"-"&2} -> 2153-2 | BK19: {=INDIRECT(BK$5&$AR19+8)&"-"&1} -> 2152-1 | BL19: {=INDIRECT(BL$5&$AR19+8)&"-"&2} -> 2152-2 | BM19: {=INDIRECT(BM$5&$AR19+8)&"-"&1} -> 2151-1 | BN19: {=INDIRECT(BN$5&$AR19+8)&"-"&2} -> 2151-2 | BO19: {=INDIRECT(BO$5&$AR19+8)&"-"&1} -> 2150-1 | BP19: {=INDIRECT(BP$5&$AR19+8)&"-"&2} -> 2150-2 | BQ19: {=INDIRECT(BQ$5&$AR19+8)&"-"&1} -> 2149-1 | BR19: {=INDIRECT(BR$5&$AR19+8)&"-"&2} -> 2149-2 | BS19: {=INDIRECT(BS$5&$AR19+8)&"-"&1} -> 2148-1 | BT19: {=INDIRECT(BT$5&$AR19+8)&"-"&2} -> 2148-2 | BU19: {=INDIRECT(BU$5&$AR19+8)&"-"&1} -> 2147-1 | BV19: {=INDIRECT(BV$5&$AR19+8)&"-"&2} -> 2147-2 | BW19: {=INDIRECT(BW$5&$AR19+8)&"-"&1} -> 2146-1 | BX19: {=INDIRECT(BX$5&$AR19+8)&"-"&2} -> 2146-2 | BY19: {=INDIRECT(BY$5&$AR19+8)&"-"&1} -> 2145-1 | BZ19: {=INDIRECT(BZ$5&$AR19+8)&"-"&2} -> 2145-2 | CA19: {=INDIRECT(CA$5&$AR19+8)&"-"&1} -> 1160-1 | CB19: {=INDIRECT(CB$5&$AR19+8)&"-"&2} -> 1160-2 | CC19: {=INDIRECT(CC$5&$AR19+8)&"-"&1} -> 1159-1 | CD19: {=INDIRECT(CD$5&$AR19+8)&"-"&2} -> 1159-2 | CE19: {=INDIRECT(CE$5&$AR19+8)&"-"&1} -> 1158-1 | CF19: {=INDIRECT(CF$5&$AR19+8)&"-"&2} -> 1158-2 | CG19: {=INDIRECT(CG$5&$AR19+8)&"-"&1} -> 1157-1 | CH19: {=INDIRECT(CH$5&$AR19+8)&"-"&2} -> 1157-2 | CI19: {=INDIRECT(CI$5&$AR19+8)&"-"&1} -> 1156-1 | CJ19: {=INDIRECT(CJ$5&$AR19+8)&"-"&2} -> 1156-2 | CK19: {=INDIRECT(CK$5&$AR19+8)&"-"&1} -> 1155-1 | CL19: {=INDIRECT(CL$5&$AR19+8)&"-"&2} -> 1155-2 | CM19: {=INDIRECT(CM$5&$AR19+8)&"-"&1} -> 1154-1 | CN19: {=INDIRECT(CN$5&$AR19+8)&"-"&2} -> 1154-2 | CO19: {=INDIRECT(CO$5&$AR19+8)&"-"&1} -> 1153-1 | CP19: {=INDIRECT(CP$5&$AR19+8)&"-"&2} -> 1153-2 | CQ19: {=INDIRECT(CQ$5&$AR19+8)&"-"&1} -> 1152-1 | CR19: {=INDIRECT(CR$5&$AR19+8)&"-"&2} -> 1152-2 | CS19: {=INDIRECT(CS$5&$AR19+8)&"-"&1} -> 1151-1 | CT19: {=INDIRECT(CT$5&$AR19+8)&"-"&2} -> 1151-2 | CU19: {=INDIRECT(CU$5&$AR19+8)&"-"&1} -> 1150-1 | CV19: {=INDIRECT(CV$5&$AR19+8)&"-"&2} -> 1150-2 | CW19: {=INDIRECT(CW$5&$AR19+8)&"-"&1} -> 1149-1 | CX19: {=INDIRECT(CX$5&$AR19+8)&"-"&2} -> 1149-2 | CY19: {=INDIRECT(CY$5&$AR19+8)&"-"&1} -> 1148-1 | CZ19: {=INDIRECT(CZ$5&$AR19+8)&"-"&2} -> 1148-2 | DA19: {=INDIRECT(DA$5&$AR19+8)&"-"&1} -> 1147-1 | DB19: {=INDIRECT(DB$5&$AR19+8)&"-"&2} -> 1147-2 | DC19: {=INDIRECT(DC$5&$AR19+8)&"-"&1} -> 1146-1 | DD19: {=INDIRECT(DD$5&$AR19+8)&"-"&2} -> 1146-2 | DE19: {=INDIRECT(DE$5&$AR19+8)&"-"&1} -> 1145-1 | DF19: {=INDIRECT(DF$5&$AR19+8)&"-"&2} -> 1145-2 | DG19: {=INDIRECT(DG$5&$AR19+8)} -> Border | DH19: {=INDIRECT(DH$5&$AR19+8)} -> Border
B20: 12 | C20: Border | D20: =E20+1 -> 2176 | E20: =F20+1 -> 2175 | F20: =G20+1 -> 2174 | G20: =H20+1 -> 2173 | H20: =I20+1 -> 2172 | I20: =J20+1 -> 2171 | J20: =K20+1 -> 2170 | K20: =L20+1 -> 2169 | ... R20: =S20+1 -> 2162 | S20: {=D19+1} -> 2161 | T20: =U20+1 -> 1176 | U20: =V20+1 -> 1175 | V20: =W20+1 -> 1174 | W20: =X20+1 -> 1173 | X20: =Y20+1 -> 1172 | Y20: =Z20+1 -> 1171 | Z20: =AA20+1 -> 1170 | AA20: =AB20+1 -> 1169 | ... AH20: =AI20+1 -> 1162 | AI20: =T19+1 -> 1161 | AJ20: Border | AR20: 12 | AS20: {=INDIRECT(AS$5&$AR20+8)} -> Border | AT20: {=INDIRECT(AT$5&$AR20+8)} -> Border | AU20: {=INDIRECT(AU$5&$AR20+8)&"-"&1} -> 2176-1 | AV20: {=INDIRECT(AV$5&$AR20+8)&"-"&2} -> 2176-2 | AW20: {=INDIRECT(AW$5&$AR20+8)&"-"&1} -> 2175-1 | AX20: {=INDIRECT(AX$5&$AR20+8)&"-"&2} -> 2175-2 | AY20: {=INDIRECT(AY$5&$AR20+8)&"-"&1} -> 2174-1 | AZ20: {=INDIRECT(AZ$5&$AR20+8)&"-"&2} -> 2174-2 | BA20: {=INDIRECT(BA$5&$AR20+8)&"-"&1} -> 2173-1 | BB20: {=INDIRECT(BB$5&$AR20+8)&"-"&2} -> 2173-2 | BC20: {=INDIRECT(BC$5&$AR20+8)&"-"&1} -> 2172-1 | BD20: {=INDIRECT(BD$5&$AR20+8)&"-"&2} -> 2172-2 | BE20: {=INDIRECT(BE$5&$AR20+8)&"-"&1} -> 2171-1 | BF20: {=INDIRECT(BF$5&$AR20+8)&"-"&2} -> 2171-2 | BG20: {=INDIRECT(BG$5&$AR20+8)&"-"&1} -> 2170-1 | BH20: {=INDIRECT(BH$5&$AR20+8)&"-"&2} -> 2170-2 | BI20: {=INDIRECT(BI$5&$AR20+8)&"-"&1} -> 2169-1 | BJ20: {=INDIRECT(BJ$5&$AR20+8)&"-"&2} -> 2169-2 | BK20: {=INDIRECT(BK$5&$AR20+8)&"-"&1} -> 2168-1 | BL20: {=INDIRECT(BL$5&$AR20+8)&"-"&2} -> 2168-2 | BM20: {=INDIRECT(BM$5&$AR20+8)&"-"&1} -> 2167-1 | BN20: {=INDIRECT(BN$5&$AR20+8)&"-"&2} -> 2167-2 | BO20: {=INDIRECT(BO$5&$AR20+8)&"-"&1} -> 2166-1 | BP20: {=INDIRECT(BP$5&$AR20+8)&"-"&2} -> 2166-2 | BQ20: {=INDIRECT(BQ$5&$AR20+8)&"-"&1} -> 2165-1 | BR20: {=INDIRECT(BR$5&$AR20+8)&"-"&2} -> 2165-2 | BS20: {=INDIRECT(BS$5&$AR20+8)&"-"&1} -> 2164-1 | BT20: {=INDIRECT(BT$5&$AR20+8)&"-"&2} -> 2164-2 | BU20: {=INDIRECT(BU$5&$AR20+8)&"-"&1} -> 2163-1 | BV20: {=INDIRECT(BV$5&$AR20+8)&"-"&2} -> 2163-2 | BW20: {=INDIRECT(BW$5&$AR20+8)&"-"&1} -> 2162-1 | BX20: {=INDIRECT(BX$5&$AR20+8)&"-"&2} -> 2162-2 | BY20: {=INDIRECT(BY$5&$AR20+8)&"-"&1} -> 2161-1 | BZ20: {=INDIRECT(BZ$5&$AR20+8)&"-"&2} -> 2161-2 | CA20: {=INDIRECT(CA$5&$AR20+8)&"-"&1} -> 1176-1 | CB20: {=INDIRECT(CB$5&$AR20+8)&"-"&2} -> 1176-2 | CC20: {=INDIRECT(CC$5&$AR20+8)&"-"&1} -> 1175-1 | CD20: {=INDIRECT(CD$5&$AR20+8)&"-"&2} -> 1175-2 | CE20: {=INDIRECT(CE$5&$AR20+8)&"-"&1} -> 1174-1 | CF20: {=INDIRECT(CF$5&$AR20+8)&"-"&2} -> 1174-2 | CG20: {=INDIRECT(CG$5&$AR20+8)&"-"&1} -> 1173-1 | CH20: {=INDIRECT(CH$5&$AR20+8)&"-"&2} -> 1173-2 | CI20: {=INDIRECT(CI$5&$AR20+8)&"-"&1} -> 1172-1 | CJ20: {=INDIRECT(CJ$5&$AR20+8)&"-"&2} -> 1172-2 | CK20: {=INDIRECT(CK$5&$AR20+8)&"-"&1} -> 1171-1 | CL20: {=INDIRECT(CL$5&$AR20+8)&"-"&2} -> 1171-2 | CM20: {=INDIRECT(CM$5&$AR20+8)&"-"&1} -> 1170-1 | CN20: {=INDIRECT(CN$5&$AR20+8)&"-"&2} -> 1170-2 | CO20: {=INDIRECT(CO$5&$AR20+8)&"-"&1} -> 1169-1 | CP20: {=INDIRECT(CP$5&$AR20+8)&"-"&2} -> 1169-2 | CQ20: {=INDIRECT(CQ$5&$AR20+8)&"-"&1} -> 1168-1 | CR20: {=INDIRECT(CR$5&$AR20+8)&"-"&2} -> 1168-2 | CS20: {=INDIRECT(CS$5&$AR20+8)&"-"&1} -> 1167-1 | CT20: {=INDIRECT(CT$5&$AR20+8)&"-"&2} -> 1167-2 | CU20: {=INDIRECT(CU$5&$AR20+8)&"-"&1} -> 1166-1 | CV20: {=INDIRECT(CV$5&$AR20+8)&"-"&2} -> 1166-2 | CW20: {=INDIRECT(CW$5&$AR20+8)&"-"&1} -> 1165-1 | CX20: {=INDIRECT(CX$5&$AR20+8)&"-"&2} -> 1165-2 | CY20: {=INDIRECT(CY$5&$AR20+8)&"-"&1} -> 1164-1 | CZ20: {=INDIRECT(CZ$5&$AR20+8)&"-"&2} -> 1164-2 | DA20: {=INDIRECT(DA$5&$AR20+8)&"-"&1} -> 1163-1 | DB20: {=INDIRECT(DB$5&$AR20+8)&"-"&2} -> 1163-2 | DC20: {=INDIRECT(DC$5&$AR20+8)&"-"&1} -> 1162-1 | DD20: {=INDIRECT(DD$5&$AR20+8)&"-"&2} -> 1162-2 | DE20: {=INDIRECT(DE$5&$AR20+8)&"-"&1} -> 1161-1 | DF20: {=INDIRECT(DF$5&$AR20+8)&"-"&2} -> 1161-2 | DG20: {=INDIRECT(DG$5&$AR20+8)} -> Border | DH20: {=INDIRECT(DH$5&$AR20+8)} -> Border
B21: 13 | C21: Border | D21: =E21+1 -> 2192 | E21: =F21+1 -> 2191 | F21: =G21+1 -> 2190 | G21: =H21+1 -> 2189 | H21: =I21+1 -> 2188 | I21: =J21+1 -> 2187 | J21: =K21+1 -> 2186 | K21: =L21+1 -> 2185 | ... R21: =S21+1 -> 2178 | S21: {=D20+1} -> 2177 | T21: =U21+1 -> 1192 | U21: =V21+1 -> 1191 | V21: =W21+1 -> 1190 | W21: =X21+1 -> 1189 | X21: =Y21+1 -> 1188 | Y21: =Z21+1 -> 1187 | Z21: =AA21+1 -> 1186 | AA21: =AB21+1 -> 1185 | ... AH21: =AI21+1 -> 1178 | AI21: =T20+1 -> 1177 | AJ21: Border | AR21: 13 | AS21: {=INDIRECT(AS$5&$AR21+8)} -> Border | AT21: {=INDIRECT(AT$5&$AR21+8)} -> Border | AU21: {=INDIRECT(AU$5&$AR21+8)&"-"&1} -> 2192-1 | AV21: {=INDIRECT(AV$5&$AR21+8)&"-"&2} -> 2192-2 | AW21: {=INDIRECT(AW$5&$AR21+8)&"-"&1} -> 2191-1 | AX21: {=INDIRECT(AX$5&$AR21+8)&"-"&2} -> 2191-2 | AY21: {=INDIRECT(AY$5&$AR21+8)&"-"&1} -> 2190-1 | AZ21: {=INDIRECT(AZ$5&$AR21+8)&"-"&2} -> 2190-2 | BA21: {=INDIRECT(BA$5&$AR21+8)&"-"&1} -> 2189-1 | BB21: {=INDIRECT(BB$5&$AR21+8)&"-"&2} -> 2189-2 | BC21: {=INDIRECT(BC$5&$AR21+8)&"-"&1} -> 2188-1 | BD21: {=INDIRECT(BD$5&$AR21+8)&"-"&2} -> 2188-2 | BE21: {=INDIRECT(BE$5&$AR21+8)&"-"&1} -> 2187-1 | BF21: {=INDIRECT(BF$5&$AR21+8)&"-"&2} -> 2187-2 | BG21: {=INDIRECT(BG$5&$AR21+8)&"-"&1} -> 2186-1 | BH21: {=INDIRECT(BH$5&$AR21+8)&"-"&2} -> 2186-2 | BI21: {=INDIRECT(BI$5&$AR21+8)&"-"&1} -> 2185-1 | BJ21: {=INDIRECT(BJ$5&$AR21+8)&"-"&2} -> 2185-2 | BK21: {=INDIRECT(BK$5&$AR21+8)&"-"&1} -> 2184-1 | BL21: {=INDIRECT(BL$5&$AR21+8)&"-"&2} -> 2184-2 | BM21: {=INDIRECT(BM$5&$AR21+8)&"-"&1} -> 2183-1 | BN21: {=INDIRECT(BN$5&$AR21+8)&"-"&2} -> 2183-2 | BO21: {=INDIRECT(BO$5&$AR21+8)&"-"&1} -> 2182-1 | BP21: {=INDIRECT(BP$5&$AR21+8)&"-"&2} -> 2182-2 | BQ21: {=INDIRECT(BQ$5&$AR21+8)&"-"&1} -> 2181-1 | BR21: {=INDIRECT(BR$5&$AR21+8)&"-"&2} -> 2181-2 | BS21: {=INDIRECT(BS$5&$AR21+8)&"-"&1} -> 2180-1 | BT21: {=INDIRECT(BT$5&$AR21+8)&"-"&2} -> 2180-2 | BU21: {=INDIRECT(BU$5&$AR21+8)&"-"&1} -> 2179-1 | BV21: {=INDIRECT(BV$5&$AR21+8)&"-"&2} -> 2179-2 | BW21: {=INDIRECT(BW$5&$AR21+8)&"-"&1} -> 2178-1 | BX21: {=INDIRECT(BX$5&$AR21+8)&"-"&2} -> 2178-2 | BY21: {=INDIRECT(BY$5&$AR21+8)&"-"&1} -> 2177-1 | BZ21: {=INDIRECT(BZ$5&$AR21+8)&"-"&2} -> 2177-2 | CA21: {=INDIRECT(CA$5&$AR21+8)&"-"&1} -> 1192-1 | CB21: {=INDIRECT(CB$5&$AR21+8)&"-"&2} -> 1192-2 | CC21: {=INDIRECT(CC$5&$AR21+8)&"-"&1} -> 1191-1 | CD21: {=INDIRECT(CD$5&$AR21+8)&"-"&2} -> 1191-2 | CE21: {=INDIRECT(CE$5&$AR21+8)&"-"&1} -> 1190-1 | CF21: {=INDIRECT(CF$5&$AR21+8)&"-"&2} -> 1190-2 | CG21: {=INDIRECT(CG$5&$AR21+8)&"-"&1} -> 1189-1 | CH21: {=INDIRECT(CH$5&$AR21+8)&"-"&2} -> 1189-2 | CI21: {=INDIRECT(CI$5&$AR21+8)&"-"&1} -> 1188-1 | CJ21: {=INDIRECT(CJ$5&$AR21+8)&"-"&2} -> 1188-2 | CK21: {=INDIRECT(CK$5&$AR21+8)&"-"&1} -> 1187-1 | CL21: {=INDIRECT(CL$5&$AR21+8)&"-"&2} -> 1187-2 | CM21: {=INDIRECT(CM$5&$AR21+8)&"-"&1} -> 1186-1 | CN21: {=INDIRECT(CN$5&$AR21+8)&"-"&2} -> 1186-2 | CO21: {=INDIRECT(CO$5&$AR21+8)&"-"&1} -> 1185-1 | CP21: {=INDIRECT(CP$5&$AR21+8)&"-"&2} -> 1185-2 | CQ21: {=INDIRECT(CQ$5&$AR21+8)&"-"&1} -> 1184-1 | CR21: {=INDIRECT(CR$5&$AR21+8)&"-"&2} -> 1184-2 | CS21: {=INDIRECT(CS$5&$AR21+8)&"-"&1} -> 1183-1 | CT21: {=INDIRECT(CT$5&$AR21+8)&"-"&2} -> 1183-2 | CU21: {=INDIRECT(CU$5&$AR21+8)&"-"&1} -> 1182-1 | CV21: {=INDIRECT(CV$5&$AR21+8)&"-"&2} -> 1182-2 | CW21: {=INDIRECT(CW$5&$AR21+8)&"-"&1} -> 1181-1 | CX21: {=INDIRECT(CX$5&$AR21+8)&"-"&2} -> 1181-2 | CY21: {=INDIRECT(CY$5&$AR21+8)&"-"&1} -> 1180-1 | CZ21: {=INDIRECT(CZ$5&$AR21+8)&"-"&2} -> 1180-2 | DA21: {=INDIRECT(DA$5&$AR21+8)&"-"&1} -> 1179-1 | DB21: {=INDIRECT(DB$5&$AR21+8)&"-"&2} -> 1179-2 | DC21: {=INDIRECT(DC$5&$AR21+8)&"-"&1} -> 1178-1 | DD21: {=INDIRECT(DD$5&$AR21+8)&"-"&2} -> 1178-2 | DE21: {=INDIRECT(DE$5&$AR21+8)&"-"&1} -> 1177-1 | DF21: {=INDIRECT(DF$5&$AR21+8)&"-"&2} -> 1177-2 | DG21: {=INDIRECT(DG$5&$AR21+8)} -> Border | DH21: {=INDIRECT(DH$5&$AR21+8)} -> Border
B22: 14 | C22: Border | D22: =E22+1 -> 2208 | E22: =F22+1 -> 2207 | F22: =G22+1 -> 2206 | G22: =H22+1 -> 2205 | H22: =I22+1 -> 2204 | I22: =J22+1 -> 2203 | J22: =K22+1 -> 2202 | K22: =L22+1 -> 2201 | ... R22: =S22+1 -> 2194 | S22: {=D21+1} -> 2193 | T22: =U22+1 -> 1208 | U22: =V22+1 -> 1207 | V22: =W22+1 -> 1206 | W22: =X22+1 -> 1205 | X22: =Y22+1 -> 1204 | Y22: =Z22+1 -> 1203 | Z22: =AA22+1 -> 1202 | AA22: =AB22+1 -> 1201 | ... AH22: =AI22+1 -> 1194 | AI22: =T21+1 -> 1193 | AJ22: Border | AR22: 14 | AS22: {=INDIRECT(AS$5&$AR22+8)} -> Border | AT22: {=INDIRECT(AT$5&$AR22+8)} -> Border | AU22: {=INDIRECT(AU$5&$AR22+8)&"-"&1} -> 2208-1 | AV22: {=INDIRECT(AV$5&$AR22+8)&"-"&2} -> 2208-2 | AW22: {=INDIRECT(AW$5&$AR22+8)&"-"&1} -> 2207-1 | AX22: {=INDIRECT(AX$5&$AR22+8)&"-"&2} -> 2207-2 | AY22: {=INDIRECT(AY$5&$AR22+8)&"-"&1} -> 2206-1 | AZ22: {=INDIRECT(AZ$5&$AR22+8)&"-"&2} -> 2206-2 | BA22: {=INDIRECT(BA$5&$AR22+8)&"-"&1} -> 2205-1 | BB22: {=INDIRECT(BB$5&$AR22+8)&"-"&2} -> 2205-2 | BC22: {=INDIRECT(BC$5&$AR22+8)&"-"&1} -> 2204-1 | BD22: {=INDIRECT(BD$5&$AR22+8)&"-"&2} -> 2204-2 | BE22: {=INDIRECT(BE$5&$AR22+8)&"-"&1} -> 2203-1 | BF22: {=INDIRECT(BF$5&$AR22+8)&"-"&2} -> 2203-2 | BG22: {=INDIRECT(BG$5&$AR22+8)&"-"&1} -> 2202-1 | BH22: {=INDIRECT(BH$5&$AR22+8)&"-"&2} -> 2202-2 | BI22: {=INDIRECT(BI$5&$AR22+8)&"-"&1} -> 2201-1 | BJ22: {=INDIRECT(BJ$5&$AR22+8)&"-"&2} -> 2201-2 | BK22: {=INDIRECT(BK$5&$AR22+8)&"-"&1} -> 2200-1 | BL22: {=INDIRECT(BL$5&$AR22+8)&"-"&2} -> 2200-2 | BM22: {=INDIRECT(BM$5&$AR22+8)&"-"&1} -> 2199-1 | BN22: {=INDIRECT(BN$5&$AR22+8)&"-"&2} -> 2199-2 | BO22: {=INDIRECT(BO$5&$AR22+8)&"-"&1} -> 2198-1 | BP22: {=INDIRECT(BP$5&$AR22+8)&"-"&2} -> 2198-2 | BQ22: {=INDIRECT(BQ$5&$AR22+8)&"-"&1} -> 2197-1 | BR22: {=INDIRECT(BR$5&$AR22+8)&"-"&2} -> 2197-2 | BS22: {=INDIRECT(BS$5&$AR22+8)&"-"&1} -> 2196-1 | BT22: {=INDIRECT(BT$5&$AR22+8)&"-"&2} -> 2196-2 | BU22: {=INDIRECT(BU$5&$AR22+8)&"-"&1} -> 2195-1 | BV22: {=INDIRECT(BV$5&$AR22+8)&"-"&2} -> 2195-2 | BW22: {=INDIRECT(BW$5&$AR22+8)&"-"&1} -> 2194-1 | BX22: {=INDIRECT(BX$5&$AR22+8)&"-"&2} -> 2194-2 | BY22: {=INDIRECT(BY$5&$AR22+8)&"-"&1} -> 2193-1 | BZ22: {=INDIRECT(BZ$5&$AR22+8)&"-"&2} -> 2193-2 | CA22: {=INDIRECT(CA$5&$AR22+8)&"-"&1} -> 1208-1 | CB22: {=INDIRECT(CB$5&$AR22+8)&"-"&2} -> 1208-2 | CC22: {=INDIRECT(CC$5&$AR22+8)&"-"&1} -> 1207-1 | CD22: {=INDIRECT(CD$5&$AR22+8)&"-"&2} -> 1207-2 | CE22: {=INDIRECT(CE$5&$AR22+8)&"-"&1} -> 1206-1 | CF22: {=INDIRECT(CF$5&$AR22+8)&"-"&2} -> 1206-2 | CG22: {=INDIRECT(CG$5&$AR22+8)&"-"&1} -> 1205-1 | CH22: {=INDIRECT(CH$5&$AR22+8)&"-"&2} -> 1205-2 | CI22: {=INDIRECT(CI$5&$AR22+8)&"-"&1} -> 1204-1 | CJ22: {=INDIRECT(CJ$5&$AR22+8)&"-"&2} -> 1204-2 | CK22: {=INDIRECT(CK$5&$AR22+8)&"-"&1} -> 1203-1 | CL22: {=INDIRECT(CL$5&$AR22+8)&"-"&2} -> 1203-2 | CM22: {=INDIRECT(CM$5&$AR22+8)&"-"&1} -> 1202-1 | CN22: {=INDIRECT(CN$5&$AR22+8)&"-"&2} -> 1202-2 | CO22: {=INDIRECT(CO$5&$AR22+8)&"-"&1} -> 1201-1 | CP22: {=INDIRECT(CP$5&$AR22+8)&"-"&2} -> 1201-2 | CQ22: {=INDIRECT(CQ$5&$AR22+8)&"-"&1} -> 1200-1 | CR22: {=INDIRECT(CR$5&$AR22+8)&"-"&2} -> 1200-2 | CS22: {=INDIRECT(CS$5&$AR22+8)&"-"&1} -> 1199-1 | CT22: {=INDIRECT(CT$5&$AR22+8)&"-"&2} -> 1199-2 | CU22: {=INDIRECT(CU$5&$AR22+8)&"-"&1} -> 1198-1 | CV22: {=INDIRECT(CV$5&$AR22+8)&"-"&2} -> 1198-2 | CW22: {=INDIRECT(CW$5&$AR22+8)&"-"&1} -> 1197-1 | CX22: {=INDIRECT(CX$5&$AR22+8)&"-"&2} -> 1197-2 | CY22: {=INDIRECT(CY$5&$AR22+8)&"-"&1} -> 1196-1 | CZ22: {=INDIRECT(CZ$5&$AR22+8)&"-"&2} -> 1196-2 | DA22: {=INDIRECT(DA$5&$AR22+8)&"-"&1} -> 1195-1 | DB22: {=INDIRECT(DB$5&$AR22+8)&"-"&2} -> 1195-2 | DC22: {=INDIRECT(DC$5&$AR22+8)&"-"&1} -> 1194-1 | DD22: {=INDIRECT(DD$5&$AR22+8)&"-"&2} -> 1194-2 | DE22: {=INDIRECT(DE$5&$AR22+8)&"-"&1} -> 1193-1 | DF22: {=INDIRECT(DF$5&$AR22+8)&"-"&2} -> 1193-2 | DG22: {=INDIRECT(DG$5&$AR22+8)} -> Border | DH22: {=INDIRECT(DH$5&$AR22+8)} -> Border
... B34: 26 | C34: Border | D34: =E34+1 -> 2400 | E34: =F34+1 -> 2399 | F34: =G34+1 -> 2398 | G34: =H34+1 -> 2397 | H34: =I34+1 -> 2396 | I34: =J34+1 -> 2395 | J34: =K34+1 -> 2394 | K34: =L34+1 -> 2393 | ... R34: =S34+1 -> 2386 | S34: {=D33+1} -> 2385 | T34: =U34+1 -> 1400 | U34: =V34+1 -> 1399 | V34: =W34+1 -> 1398 | W34: =X34+1 -> 1397 | X34: =Y34+1 -> 1396 | Y34: =Z34+1 -> 1395 | Z34: =AA34+1 -> 1394 | AA34: =AB34+1 -> 1393 | ... AH34: =AI34+1 -> 1386 | AI34: =T33+1 -> 1385 | AJ34: Border | AR34: 26 | AS34: {=INDIRECT(AS$5&$AR34+8)} -> Border | AT34: {=INDIRECT(AT$5&$AR34+8)} -> Border | AU34: {=INDIRECT(AU$5&$AR34+8)&"-"&1} -> 2400-1 | AV34: {=INDIRECT(AV$5&$AR34+8)&"-"&2} -> 2400-2 | AW34: {=INDIRECT(AW$5&$AR34+8)&"-"&1} -> 2399-1 | AX34: {=INDIRECT(AX$5&$AR34+8)&"-"&2} -> 2399-2 | AY34: {=INDIRECT(AY$5&$AR34+8)&"-"&1} -> 2398-1 | AZ34: {=INDIRECT(AZ$5&$AR34+8)&"-"&2} -> 2398-2 | BA34: {=INDIRECT(BA$5&$AR34+8)&"-"&1} -> 2397-1 | BB34: {=INDIRECT(BB$5&$AR34+8)&"-"&2} -> 2397-2 | BC34: {=INDIRECT(BC$5&$AR34+8)&"-"&1} -> 2396-1 | BD34: {=INDIRECT(BD$5&$AR34+8)&"-"&2} -> 2396-2 | BE34: {=INDIRECT(BE$5&$AR34+8)&"-"&1} -> 2395-1 | BF34: {=INDIRECT(BF$5&$AR34+8)&"-"&2} -> 2395-2 | BG34: {=INDIRECT(BG$5&$AR34+8)&"-"&1} -> 2394-1 | BH34: {=INDIRECT(BH$5&$AR34+8)&"-"&2} -> 2394-2 | BI34: {=INDIRECT(BI$5&$AR34+8)&"-"&1} -> 2393-1 | BJ34: {=INDIRECT(BJ$5&$AR34+8)&"-"&2} -> 2393-2 | BK34: {=INDIRECT(BK$5&$AR34+8)&"-"&1} -> 2392-1 | BL34: {=INDIRECT(BL$5&$AR34+8)&"-"&2} -> 2392-2 | BM34: {=INDIRECT(BM$5&$AR34+8)&"-"&1} -> 2391-1 | BN34: {=INDIRECT(BN$5&$AR34+8)&"-"&2} -> 2391-2 | BO34: {=INDIRECT(BO$5&$AR34+8)&"-"&1} -> 2390-1 | BP34: {=INDIRECT(BP$5&$AR34+8)&"-"&2} -> 2390-2 | BQ34: {=INDIRECT(BQ$5&$AR34+8)&"-"&1} -> 2389-1 | BR34: {=INDIRECT(BR$5&$AR34+8)&"-"&2} -> 2389-2 | BS34: {=INDIRECT(BS$5&$AR34+8)&"-"&1} -> 2388-1 | BT34: {=INDIRECT(BT$5&$AR34+8)&"-"&2} -> 2388-2 | BU34: {=INDIRECT(BU$5&$AR34+8)&"-"&1} -> 2387-1 | BV34: {=INDIRECT(BV$5&$AR34+8)&"-"&2} -> 2387-2 | BW34: {=INDIRECT(BW$5&$AR34+8)&"-"&1} -> 2386-1 | BX34: {=INDIRECT(BX$5&$AR34+8)&"-"&2} -> 2386-2 | BY34: {=INDIRECT(BY$5&$AR34+8)&"-"&1} -> 2385-1 | BZ34: {=INDIRECT(BZ$5&$AR34+8)&"-"&2} -> 2385-2 | CA34: {=INDIRECT(CA$5&$AR34+8)&"-"&1} -> 1400-1 | CB34: {=INDIRECT(CB$5&$AR34+8)&"-"&2} -> 1400-2 | CC34: {=INDIRECT(CC$5&$AR34+8)&"-"&1} -> 1399-1 | CD34: {=INDIRECT(CD$5&$AR34+8)&"-"&2} -> 1399-2 | CE34: {=INDIRECT(CE$5&$AR34+8)&"-"&1} -> 1398-1 | CF34: {=INDIRECT(CF$5&$AR34+8)&"-"&2} -> 1398-2 | CG34: {=INDIRECT(CG$5&$AR34+8)&"-"&1} -> 1397-1 | CH34: {=INDIRECT(CH$5&$AR34+8)&"-"&2} -> 1397-2 | CI34: {=INDIRECT(CI$5&$AR34+8)&"-"&1} -> 1396-1 | CJ34: {=INDIRECT(CJ$5&$AR34+8)&"-"&2} -> 1396-2 | CK34: {=INDIRECT(CK$5&$AR34+8)&"-"&1} -> 1395-1 | CL34: {=INDIRECT(CL$5&$AR34+8)&"-"&2} -> 1395-2 | CM34: {=INDIRECT(CM$5&$AR34+8)&"-"&1} -> 1394-1 | CN34: {=INDIRECT(CN$5&$AR34+8)&"-"&2} -> 1394-2 | CO34: {=INDIRECT(CO$5&$AR34+8)&"-"&1} -> 1393-1 | CP34: {=INDIRECT(CP$5&$AR34+8)&"-"&2} -> 1393-2 | CQ34: {=INDIRECT(CQ$5&$AR34+8)&"-"&1} -> 1392-1 | CR34: {=INDIRECT(CR$5&$AR34+8)&"-"&2} -> 1392-2 | CS34: {=INDIRECT(CS$5&$AR34+8)&"-"&1} -> 1391-1 | CT34: {=INDIRECT(CT$5&$AR34+8)&"-"&2} -> 1391-2 | CU34: {=INDIRECT(CU$5&$AR34+8)&"-"&1} -> 1390-1 | CV34: {=INDIRECT(CV$5&$AR34+8)&"-"&2} -> 1390-2 | CW34: {=INDIRECT(CW$5&$AR34+8)&"-"&1} -> 1389-1 | CX34: {=INDIRECT(CX$5&$AR34+8)&"-"&2} -> 1389-2 | CY34: {=INDIRECT(CY$5&$AR34+8)&"-"&1} -> 1388-1 | CZ34: {=INDIRECT(CZ$5&$AR34+8)&"-"&2} -> 1388-2 | DA34: {=INDIRECT(DA$5&$AR34+8)&"-"&1} -> 1387-1 | DB34: {=INDIRECT(DB$5&$AR34+8)&"-"&2} -> 1387-2 | DC34: {=INDIRECT(DC$5&$AR34+8)&"-"&1} -> 1386-1 | DD34: {=INDIRECT(DD$5&$AR34+8)&"-"&2} -> 1386-2 | DE34: {=INDIRECT(DE$5&$AR34+8)&"-"&1} -> 1385-1 | DF34: {=INDIRECT(DF$5&$AR34+8)&"-"&2} -> 1385-2 | DG34: {=INDIRECT(DG$5&$AR34+8)} -> Border | DH34: {=INDIRECT(DH$5&$AR34+8)} -> Border
